{
  "uid" : "3d65f199f46823ed",
  "name" : "test_main[cases50]",
  "fullName" : "test.test_api#test_main",
  "historyId" : "652aab4b830e31052e91be4fd150459f",
  "time" : {
    "start" : 1641450341375,
    "stop" : 1641450341375,
    "duration" : 0
  },
  "status" : "broken",
  "statusMessage" : "FileNotFoundError: [Errno 2] No such file or directory: '/home/chenlei/backup_sqls/apiautotest_2022-01-06T14_21_46.sql'",
  "statusTrace" : "@pytest.fixture(scope=\"session\")\n    def data_clearing():\n        \"\"\"数据清洗\"\"\"\n        DataClearing.server_init()\n        # 1. 备份数据库\n>       DataClearing.backup_mysql()\n\ntest\\conftest.py:24: \n_ _ _ _ _ _ _ _ _ _ _ _ _ _ _ _ _ _ _ _ _ _ _ _ _ _ _ _ _ _ _ _ _ _ _ _ _ _ _ _\ntools\\data_clearing.py:119: in backup_mysql\n    cls.server.files_action(0,\ntools\\data_clearing.py:77: in files_action\n    self.ftp_client.get(remotepath=remote_path, localpath=file_path)\n_ _ _ _ _ _ _ _ _ _ _ _ _ _ _ _ _ _ _ _ _ _ _ _ _ _ _ _ _ _ _ _ _ _ _ _ _ _ _ _\n\nself = <paramiko.sftp_client.SFTPClient object at 0x0000017F68F53670>\nremotepath = '/root/backup_sql/apiautotest_2022-01-06T14_21_46.sql'\nlocalpath = '/home/chenlei/backup_sqls/apiautotest_2022-01-06T14_21_46.sql'\ncallback = None\n\n    def get(self, remotepath, localpath, callback=None):\n        \"\"\"\n        Copy a remote file (``remotepath``) from the SFTP server to the local\n        host as ``localpath``.  Any exception raised by operations will be\n        passed through.  This method is primarily provided as a convenience.\n    \n        :param str remotepath: the remote file to copy\n        :param str localpath: the destination path on the local host\n        :param callable callback:\n            optional callback function (form: ``func(int, int)``) that accepts\n            the bytes transferred so far and the total bytes to be transferred\n    \n        .. versionadded:: 1.4\n        .. versionchanged:: 1.7.4\n            Added the ``callback`` param\n        \"\"\"\n>       with open(localpath, \"wb\") as fl:\nE       FileNotFoundError: [Errno 2] No such file or directory: '/home/chenlei/backup_sqls/apiautotest_2022-01-06T14_21_46.sql'\n\nD:\\PythonCode\\apiAutoTest\\lib\\site-packages\\paramiko\\sftp_client.py:801: FileNotFoundError",
  "flaky" : false,
  "newFailed" : false,
  "newBroken" : false,
  "newPassed" : false,
  "retriesCount" : 2,
  "retriesStatusChange" : false,
  "beforeStages" : [ {
    "name" : "data_clearing",
    "time" : {
      "start" : 1641450107419,
      "stop" : 1641450108813,
      "duration" : 1394
    },
    "status" : "broken",
    "statusMessage" : "FileNotFoundError: [Errno 2] No such file or directory: '/home/chenlei/backup_sqls/apiautotest_2022-01-06T14_21_46.sql'\n",
    "statusTrace" : "  File \"D:\\PythonCode\\apiAutoTest\\lib\\site-packages\\pluggy\\callers.py\", line 187, in _multicall\n    res = hook_impl.function(*args)\n  File \"D:\\PythonCode\\apiAutoTest\\lib\\site-packages\\_pytest\\fixtures.py\", line 1117, in pytest_fixture_setup\n    result = call_fixture_func(fixturefunc, request, kwargs)\n  File \"D:\\PythonCode\\apiAutoTest\\lib\\site-packages\\_pytest\\fixtures.py\", line 915, in call_fixture_func\n    fixture_result = next(generator)\n  File \"F:\\CODE\\python-test\\apiAutoTest\\test\\conftest.py\", line 24, in data_clearing\n    DataClearing.backup_mysql()\n  File \"F:\\CODE\\python-test\\apiAutoTest\\tools\\data_clearing.py\", line 119, in backup_mysql\n    cls.server.files_action(0,\n  File \"F:\\CODE\\python-test\\apiAutoTest\\tools\\data_clearing.py\", line 77, in files_action\n    self.ftp_client.get(remotepath=remote_path, localpath=file_path)\n  File \"D:\\PythonCode\\apiAutoTest\\lib\\site-packages\\paramiko\\sftp_client.py\", line 801, in get\n    with open(localpath, \"wb\") as fl:\n",
    "steps" : [ ],
    "attachments" : [ ],
    "parameters" : [ ],
    "hasContent" : true,
    "stepsCount" : 0,
    "attachmentsCount" : 0,
    "shouldDisplayMessage" : true
  }, {
    "name" : "data_clearing",
    "time" : {
      "start" : 1641450109969,
      "stop" : 1641450111546,
      "duration" : 1577
    },
    "status" : "broken",
    "statusMessage" : "FileNotFoundError: [Errno 2] No such file or directory: '/home/chenlei/backup_sqls/apiautotest_2022-01-06T14_21_46.sql'\n",
    "statusTrace" : "  File \"D:\\PythonCode\\apiAutoTest\\lib\\site-packages\\pluggy\\callers.py\", line 187, in _multicall\n    res = hook_impl.function(*args)\n  File \"D:\\PythonCode\\apiAutoTest\\lib\\site-packages\\_pytest\\fixtures.py\", line 1117, in pytest_fixture_setup\n    result = call_fixture_func(fixturefunc, request, kwargs)\n  File \"D:\\PythonCode\\apiAutoTest\\lib\\site-packages\\_pytest\\fixtures.py\", line 915, in call_fixture_func\n    fixture_result = next(generator)\n  File \"F:\\CODE\\python-test\\apiAutoTest\\test\\conftest.py\", line 24, in data_clearing\n    DataClearing.backup_mysql()\n  File \"F:\\CODE\\python-test\\apiAutoTest\\tools\\data_clearing.py\", line 119, in backup_mysql\n    cls.server.files_action(0,\n  File \"F:\\CODE\\python-test\\apiAutoTest\\tools\\data_clearing.py\", line 77, in files_action\n    self.ftp_client.get(remotepath=remote_path, localpath=file_path)\n  File \"D:\\PythonCode\\apiAutoTest\\lib\\site-packages\\paramiko\\sftp_client.py\", line 801, in get\n    with open(localpath, \"wb\") as fl:\n",
    "steps" : [ ],
    "attachments" : [ ],
    "parameters" : [ ],
    "hasContent" : true,
    "stepsCount" : 0,
    "attachmentsCount" : 0,
    "shouldDisplayMessage" : true
  }, {
    "name" : "data_clearing",
    "time" : {
      "start" : 1641450112576,
      "stop" : 1641450113897,
      "duration" : 1321
    },
    "status" : "broken",
    "statusMessage" : "FileNotFoundError: [Errno 2] No such file or directory: '/home/chenlei/backup_sqls/apiautotest_2022-01-06T14_21_46.sql'\n",
    "statusTrace" : "  File \"D:\\PythonCode\\apiAutoTest\\lib\\site-packages\\pluggy\\callers.py\", line 187, in _multicall\n    res = hook_impl.function(*args)\n  File \"D:\\PythonCode\\apiAutoTest\\lib\\site-packages\\_pytest\\fixtures.py\", line 1117, in pytest_fixture_setup\n    result = call_fixture_func(fixturefunc, request, kwargs)\n  File \"D:\\PythonCode\\apiAutoTest\\lib\\site-packages\\_pytest\\fixtures.py\", line 915, in call_fixture_func\n    fixture_result = next(generator)\n  File \"F:\\CODE\\python-test\\apiAutoTest\\test\\conftest.py\", line 24, in data_clearing\n    DataClearing.backup_mysql()\n  File \"F:\\CODE\\python-test\\apiAutoTest\\tools\\data_clearing.py\", line 119, in backup_mysql\n    cls.server.files_action(0,\n  File \"F:\\CODE\\python-test\\apiAutoTest\\tools\\data_clearing.py\", line 77, in files_action\n    self.ftp_client.get(remotepath=remote_path, localpath=file_path)\n  File \"D:\\PythonCode\\apiAutoTest\\lib\\site-packages\\paramiko\\sftp_client.py\", line 801, in get\n    with open(localpath, \"wb\") as fl:\n",
    "steps" : [ ],
    "attachments" : [ ],
    "parameters" : [ ],
    "hasContent" : true,
    "stepsCount" : 0,
    "attachmentsCount" : 0,
    "shouldDisplayMessage" : true
  }, {
    "name" : "data_clearing",
    "time" : {
      "start" : 1641450114931,
      "stop" : 1641450116080,
      "duration" : 1149
    },
    "status" : "broken",
    "statusMessage" : "FileNotFoundError: [Errno 2] No such file or directory: '/home/chenlei/backup_sqls/apiautotest_2022-01-06T14_21_46.sql'\n",
    "statusTrace" : "  File \"D:\\PythonCode\\apiAutoTest\\lib\\site-packages\\pluggy\\callers.py\", line 187, in _multicall\n    res = hook_impl.function(*args)\n  File \"D:\\PythonCode\\apiAutoTest\\lib\\site-packages\\_pytest\\fixtures.py\", line 1117, in pytest_fixture_setup\n    result = call_fixture_func(fixturefunc, request, kwargs)\n  File \"D:\\PythonCode\\apiAutoTest\\lib\\site-packages\\_pytest\\fixtures.py\", line 915, in call_fixture_func\n    fixture_result = next(generator)\n  File \"F:\\CODE\\python-test\\apiAutoTest\\test\\conftest.py\", line 24, in data_clearing\n    DataClearing.backup_mysql()\n  File \"F:\\CODE\\python-test\\apiAutoTest\\tools\\data_clearing.py\", line 119, in backup_mysql\n    cls.server.files_action(0,\n  File \"F:\\CODE\\python-test\\apiAutoTest\\tools\\data_clearing.py\", line 77, in files_action\n    self.ftp_client.get(remotepath=remote_path, localpath=file_path)\n  File \"D:\\PythonCode\\apiAutoTest\\lib\\site-packages\\paramiko\\sftp_client.py\", line 801, in get\n    with open(localpath, \"wb\") as fl:\n",
    "steps" : [ ],
    "attachments" : [ ],
    "parameters" : [ ],
    "hasContent" : true,
    "stepsCount" : 0,
    "attachmentsCount" : 0,
    "shouldDisplayMessage" : true
  }, {
    "name" : "data_clearing",
    "time" : {
      "start" : 1641450117103,
      "stop" : 1641450118359,
      "duration" : 1256
    },
    "status" : "broken",
    "statusMessage" : "FileNotFoundError: [Errno 2] No such file or directory: '/home/chenlei/backup_sqls/apiautotest_2022-01-06T14_21_46.sql'\n",
    "statusTrace" : "  File \"D:\\PythonCode\\apiAutoTest\\lib\\site-packages\\pluggy\\callers.py\", line 187, in _multicall\n    res = hook_impl.function(*args)\n  File \"D:\\PythonCode\\apiAutoTest\\lib\\site-packages\\_pytest\\fixtures.py\", line 1117, in pytest_fixture_setup\n    result = call_fixture_func(fixturefunc, request, kwargs)\n  File \"D:\\PythonCode\\apiAutoTest\\lib\\site-packages\\_pytest\\fixtures.py\", line 915, in call_fixture_func\n    fixture_result = next(generator)\n  File \"F:\\CODE\\python-test\\apiAutoTest\\test\\conftest.py\", line 24, in data_clearing\n    DataClearing.backup_mysql()\n  File \"F:\\CODE\\python-test\\apiAutoTest\\tools\\data_clearing.py\", line 119, in backup_mysql\n    cls.server.files_action(0,\n  File \"F:\\CODE\\python-test\\apiAutoTest\\tools\\data_clearing.py\", line 77, in files_action\n    self.ftp_client.get(remotepath=remote_path, localpath=file_path)\n  File \"D:\\PythonCode\\apiAutoTest\\lib\\site-packages\\paramiko\\sftp_client.py\", line 801, in get\n    with open(localpath, \"wb\") as fl:\n",
    "steps" : [ ],
    "attachments" : [ ],
    "parameters" : [ ],
    "hasContent" : true,
    "stepsCount" : 0,
    "attachmentsCount" : 0,
    "shouldDisplayMessage" : true
  }, {
    "name" : "data_clearing",
    "time" : {
      "start" : 1641450119435,
      "stop" : 1641450120502,
      "duration" : 1067
    },
    "status" : "broken",
    "statusMessage" : "FileNotFoundError: [Errno 2] No such file or directory: '/home/chenlei/backup_sqls/apiautotest_2022-01-06T14_21_46.sql'\n",
    "statusTrace" : "  File \"D:\\PythonCode\\apiAutoTest\\lib\\site-packages\\pluggy\\callers.py\", line 187, in _multicall\n    res = hook_impl.function(*args)\n  File \"D:\\PythonCode\\apiAutoTest\\lib\\site-packages\\_pytest\\fixtures.py\", line 1117, in pytest_fixture_setup\n    result = call_fixture_func(fixturefunc, request, kwargs)\n  File \"D:\\PythonCode\\apiAutoTest\\lib\\site-packages\\_pytest\\fixtures.py\", line 915, in call_fixture_func\n    fixture_result = next(generator)\n  File \"F:\\CODE\\python-test\\apiAutoTest\\test\\conftest.py\", line 24, in data_clearing\n    DataClearing.backup_mysql()\n  File \"F:\\CODE\\python-test\\apiAutoTest\\tools\\data_clearing.py\", line 119, in backup_mysql\n    cls.server.files_action(0,\n  File \"F:\\CODE\\python-test\\apiAutoTest\\tools\\data_clearing.py\", line 77, in files_action\n    self.ftp_client.get(remotepath=remote_path, localpath=file_path)\n  File \"D:\\PythonCode\\apiAutoTest\\lib\\site-packages\\paramiko\\sftp_client.py\", line 801, in get\n    with open(localpath, \"wb\") as fl:\n",
    "steps" : [ ],
    "attachments" : [ ],
    "parameters" : [ ],
    "hasContent" : true,
    "stepsCount" : 0,
    "attachmentsCount" : 0,
    "shouldDisplayMessage" : true
  }, {
    "name" : "data_clearing",
    "time" : {
      "start" : 1641450121527,
      "stop" : 1641450122874,
      "duration" : 1347
    },
    "status" : "broken",
    "statusMessage" : "FileNotFoundError: [Errno 2] No such file or directory: '/home/chenlei/backup_sqls/apiautotest_2022-01-06T14_21_46.sql'\n",
    "statusTrace" : "  File \"D:\\PythonCode\\apiAutoTest\\lib\\site-packages\\pluggy\\callers.py\", line 187, in _multicall\n    res = hook_impl.function(*args)\n  File \"D:\\PythonCode\\apiAutoTest\\lib\\site-packages\\_pytest\\fixtures.py\", line 1117, in pytest_fixture_setup\n    result = call_fixture_func(fixturefunc, request, kwargs)\n  File \"D:\\PythonCode\\apiAutoTest\\lib\\site-packages\\_pytest\\fixtures.py\", line 915, in call_fixture_func\n    fixture_result = next(generator)\n  File \"F:\\CODE\\python-test\\apiAutoTest\\test\\conftest.py\", line 24, in data_clearing\n    DataClearing.backup_mysql()\n  File \"F:\\CODE\\python-test\\apiAutoTest\\tools\\data_clearing.py\", line 119, in backup_mysql\n    cls.server.files_action(0,\n  File \"F:\\CODE\\python-test\\apiAutoTest\\tools\\data_clearing.py\", line 77, in files_action\n    self.ftp_client.get(remotepath=remote_path, localpath=file_path)\n  File \"D:\\PythonCode\\apiAutoTest\\lib\\site-packages\\paramiko\\sftp_client.py\", line 801, in get\n    with open(localpath, \"wb\") as fl:\n",
    "steps" : [ ],
    "attachments" : [ ],
    "parameters" : [ ],
    "hasContent" : true,
    "stepsCount" : 0,
    "attachmentsCount" : 0,
    "shouldDisplayMessage" : true
  }, {
    "name" : "data_clearing",
    "time" : {
      "start" : 1641450123910,
      "stop" : 1641450125574,
      "duration" : 1664
    },
    "status" : "broken",
    "statusMessage" : "FileNotFoundError: [Errno 2] No such file or directory: '/home/chenlei/backup_sqls/apiautotest_2022-01-06T14_21_46.sql'\n",
    "statusTrace" : "  File \"D:\\PythonCode\\apiAutoTest\\lib\\site-packages\\pluggy\\callers.py\", line 187, in _multicall\n    res = hook_impl.function(*args)\n  File \"D:\\PythonCode\\apiAutoTest\\lib\\site-packages\\_pytest\\fixtures.py\", line 1117, in pytest_fixture_setup\n    result = call_fixture_func(fixturefunc, request, kwargs)\n  File \"D:\\PythonCode\\apiAutoTest\\lib\\site-packages\\_pytest\\fixtures.py\", line 915, in call_fixture_func\n    fixture_result = next(generator)\n  File \"F:\\CODE\\python-test\\apiAutoTest\\test\\conftest.py\", line 24, in data_clearing\n    DataClearing.backup_mysql()\n  File \"F:\\CODE\\python-test\\apiAutoTest\\tools\\data_clearing.py\", line 119, in backup_mysql\n    cls.server.files_action(0,\n  File \"F:\\CODE\\python-test\\apiAutoTest\\tools\\data_clearing.py\", line 77, in files_action\n    self.ftp_client.get(remotepath=remote_path, localpath=file_path)\n  File \"D:\\PythonCode\\apiAutoTest\\lib\\site-packages\\paramiko\\sftp_client.py\", line 801, in get\n    with open(localpath, \"wb\") as fl:\n",
    "steps" : [ ],
    "attachments" : [ ],
    "parameters" : [ ],
    "hasContent" : true,
    "stepsCount" : 0,
    "attachmentsCount" : 0,
    "shouldDisplayMessage" : true
  }, {
    "name" : "data_clearing",
    "time" : {
      "start" : 1641450126611,
      "stop" : 1641450127781,
      "duration" : 1170
    },
    "status" : "broken",
    "statusMessage" : "FileNotFoundError: [Errno 2] No such file or directory: '/home/chenlei/backup_sqls/apiautotest_2022-01-06T14_21_46.sql'\n",
    "statusTrace" : "  File \"D:\\PythonCode\\apiAutoTest\\lib\\site-packages\\pluggy\\callers.py\", line 187, in _multicall\n    res = hook_impl.function(*args)\n  File \"D:\\PythonCode\\apiAutoTest\\lib\\site-packages\\_pytest\\fixtures.py\", line 1117, in pytest_fixture_setup\n    result = call_fixture_func(fixturefunc, request, kwargs)\n  File \"D:\\PythonCode\\apiAutoTest\\lib\\site-packages\\_pytest\\fixtures.py\", line 915, in call_fixture_func\n    fixture_result = next(generator)\n  File \"F:\\CODE\\python-test\\apiAutoTest\\test\\conftest.py\", line 24, in data_clearing\n    DataClearing.backup_mysql()\n  File \"F:\\CODE\\python-test\\apiAutoTest\\tools\\data_clearing.py\", line 119, in backup_mysql\n    cls.server.files_action(0,\n  File \"F:\\CODE\\python-test\\apiAutoTest\\tools\\data_clearing.py\", line 77, in files_action\n    self.ftp_client.get(remotepath=remote_path, localpath=file_path)\n  File \"D:\\PythonCode\\apiAutoTest\\lib\\site-packages\\paramiko\\sftp_client.py\", line 801, in get\n    with open(localpath, \"wb\") as fl:\n",
    "steps" : [ ],
    "attachments" : [ ],
    "parameters" : [ ],
    "hasContent" : true,
    "stepsCount" : 0,
    "attachmentsCount" : 0,
    "shouldDisplayMessage" : true
  }, {
    "name" : "data_clearing",
    "time" : {
      "start" : 1641450128813,
      "stop" : 1641450130016,
      "duration" : 1203
    },
    "status" : "broken",
    "statusMessage" : "FileNotFoundError: [Errno 2] No such file or directory: '/home/chenlei/backup_sqls/apiautotest_2022-01-06T14_21_46.sql'\n",
    "statusTrace" : "  File \"D:\\PythonCode\\apiAutoTest\\lib\\site-packages\\pluggy\\callers.py\", line 187, in _multicall\n    res = hook_impl.function(*args)\n  File \"D:\\PythonCode\\apiAutoTest\\lib\\site-packages\\_pytest\\fixtures.py\", line 1117, in pytest_fixture_setup\n    result = call_fixture_func(fixturefunc, request, kwargs)\n  File \"D:\\PythonCode\\apiAutoTest\\lib\\site-packages\\_pytest\\fixtures.py\", line 915, in call_fixture_func\n    fixture_result = next(generator)\n  File \"F:\\CODE\\python-test\\apiAutoTest\\test\\conftest.py\", line 24, in data_clearing\n    DataClearing.backup_mysql()\n  File \"F:\\CODE\\python-test\\apiAutoTest\\tools\\data_clearing.py\", line 119, in backup_mysql\n    cls.server.files_action(0,\n  File \"F:\\CODE\\python-test\\apiAutoTest\\tools\\data_clearing.py\", line 77, in files_action\n    self.ftp_client.get(remotepath=remote_path, localpath=file_path)\n  File \"D:\\PythonCode\\apiAutoTest\\lib\\site-packages\\paramiko\\sftp_client.py\", line 801, in get\n    with open(localpath, \"wb\") as fl:\n",
    "steps" : [ ],
    "attachments" : [ ],
    "parameters" : [ ],
    "hasContent" : true,
    "stepsCount" : 0,
    "attachmentsCount" : 0,
    "shouldDisplayMessage" : true
  }, {
    "name" : "data_clearing",
    "time" : {
      "start" : 1641450131040,
      "stop" : 1641450132799,
      "duration" : 1759
    },
    "status" : "broken",
    "statusMessage" : "FileNotFoundError: [Errno 2] No such file or directory: '/home/chenlei/backup_sqls/apiautotest_2022-01-06T14_21_46.sql'\n",
    "statusTrace" : "  File \"D:\\PythonCode\\apiAutoTest\\lib\\site-packages\\pluggy\\callers.py\", line 187, in _multicall\n    res = hook_impl.function(*args)\n  File \"D:\\PythonCode\\apiAutoTest\\lib\\site-packages\\_pytest\\fixtures.py\", line 1117, in pytest_fixture_setup\n    result = call_fixture_func(fixturefunc, request, kwargs)\n  File \"D:\\PythonCode\\apiAutoTest\\lib\\site-packages\\_pytest\\fixtures.py\", line 915, in call_fixture_func\n    fixture_result = next(generator)\n  File \"F:\\CODE\\python-test\\apiAutoTest\\test\\conftest.py\", line 24, in data_clearing\n    DataClearing.backup_mysql()\n  File \"F:\\CODE\\python-test\\apiAutoTest\\tools\\data_clearing.py\", line 119, in backup_mysql\n    cls.server.files_action(0,\n  File \"F:\\CODE\\python-test\\apiAutoTest\\tools\\data_clearing.py\", line 77, in files_action\n    self.ftp_client.get(remotepath=remote_path, localpath=file_path)\n  File \"D:\\PythonCode\\apiAutoTest\\lib\\site-packages\\paramiko\\sftp_client.py\", line 801, in get\n    with open(localpath, \"wb\") as fl:\n",
    "steps" : [ ],
    "attachments" : [ ],
    "parameters" : [ ],
    "hasContent" : true,
    "stepsCount" : 0,
    "attachmentsCount" : 0,
    "shouldDisplayMessage" : true
  }, {
    "name" : "data_clearing",
    "time" : {
      "start" : 1641450133835,
      "stop" : 1641450135079,
      "duration" : 1244
    },
    "status" : "broken",
    "statusMessage" : "FileNotFoundError: [Errno 2] No such file or directory: '/home/chenlei/backup_sqls/apiautotest_2022-01-06T14_21_46.sql'\n",
    "statusTrace" : "  File \"D:\\PythonCode\\apiAutoTest\\lib\\site-packages\\pluggy\\callers.py\", line 187, in _multicall\n    res = hook_impl.function(*args)\n  File \"D:\\PythonCode\\apiAutoTest\\lib\\site-packages\\_pytest\\fixtures.py\", line 1117, in pytest_fixture_setup\n    result = call_fixture_func(fixturefunc, request, kwargs)\n  File \"D:\\PythonCode\\apiAutoTest\\lib\\site-packages\\_pytest\\fixtures.py\", line 915, in call_fixture_func\n    fixture_result = next(generator)\n  File \"F:\\CODE\\python-test\\apiAutoTest\\test\\conftest.py\", line 24, in data_clearing\n    DataClearing.backup_mysql()\n  File \"F:\\CODE\\python-test\\apiAutoTest\\tools\\data_clearing.py\", line 119, in backup_mysql\n    cls.server.files_action(0,\n  File \"F:\\CODE\\python-test\\apiAutoTest\\tools\\data_clearing.py\", line 77, in files_action\n    self.ftp_client.get(remotepath=remote_path, localpath=file_path)\n  File \"D:\\PythonCode\\apiAutoTest\\lib\\site-packages\\paramiko\\sftp_client.py\", line 801, in get\n    with open(localpath, \"wb\") as fl:\n",
    "steps" : [ ],
    "attachments" : [ ],
    "parameters" : [ ],
    "hasContent" : true,
    "stepsCount" : 0,
    "attachmentsCount" : 0,
    "shouldDisplayMessage" : true
  }, {
    "name" : "data_clearing",
    "time" : {
      "start" : 1641450136110,
      "stop" : 1641450137282,
      "duration" : 1172
    },
    "status" : "broken",
    "statusMessage" : "FileNotFoundError: [Errno 2] No such file or directory: '/home/chenlei/backup_sqls/apiautotest_2022-01-06T14_21_46.sql'\n",
    "statusTrace" : "  File \"D:\\PythonCode\\apiAutoTest\\lib\\site-packages\\pluggy\\callers.py\", line 187, in _multicall\n    res = hook_impl.function(*args)\n  File \"D:\\PythonCode\\apiAutoTest\\lib\\site-packages\\_pytest\\fixtures.py\", line 1117, in pytest_fixture_setup\n    result = call_fixture_func(fixturefunc, request, kwargs)\n  File \"D:\\PythonCode\\apiAutoTest\\lib\\site-packages\\_pytest\\fixtures.py\", line 915, in call_fixture_func\n    fixture_result = next(generator)\n  File \"F:\\CODE\\python-test\\apiAutoTest\\test\\conftest.py\", line 24, in data_clearing\n    DataClearing.backup_mysql()\n  File \"F:\\CODE\\python-test\\apiAutoTest\\tools\\data_clearing.py\", line 119, in backup_mysql\n    cls.server.files_action(0,\n  File \"F:\\CODE\\python-test\\apiAutoTest\\tools\\data_clearing.py\", line 77, in files_action\n    self.ftp_client.get(remotepath=remote_path, localpath=file_path)\n  File \"D:\\PythonCode\\apiAutoTest\\lib\\site-packages\\paramiko\\sftp_client.py\", line 801, in get\n    with open(localpath, \"wb\") as fl:\n",
    "steps" : [ ],
    "attachments" : [ ],
    "parameters" : [ ],
    "hasContent" : true,
    "stepsCount" : 0,
    "attachmentsCount" : 0,
    "shouldDisplayMessage" : true
  }, {
    "name" : "data_clearing",
    "time" : {
      "start" : 1641450138321,
      "stop" : 1641450139590,
      "duration" : 1269
    },
    "status" : "broken",
    "statusMessage" : "FileNotFoundError: [Errno 2] No such file or directory: '/home/chenlei/backup_sqls/apiautotest_2022-01-06T14_21_46.sql'\n",
    "statusTrace" : "  File \"D:\\PythonCode\\apiAutoTest\\lib\\site-packages\\pluggy\\callers.py\", line 187, in _multicall\n    res = hook_impl.function(*args)\n  File \"D:\\PythonCode\\apiAutoTest\\lib\\site-packages\\_pytest\\fixtures.py\", line 1117, in pytest_fixture_setup\n    result = call_fixture_func(fixturefunc, request, kwargs)\n  File \"D:\\PythonCode\\apiAutoTest\\lib\\site-packages\\_pytest\\fixtures.py\", line 915, in call_fixture_func\n    fixture_result = next(generator)\n  File \"F:\\CODE\\python-test\\apiAutoTest\\test\\conftest.py\", line 24, in data_clearing\n    DataClearing.backup_mysql()\n  File \"F:\\CODE\\python-test\\apiAutoTest\\tools\\data_clearing.py\", line 119, in backup_mysql\n    cls.server.files_action(0,\n  File \"F:\\CODE\\python-test\\apiAutoTest\\tools\\data_clearing.py\", line 77, in files_action\n    self.ftp_client.get(remotepath=remote_path, localpath=file_path)\n  File \"D:\\PythonCode\\apiAutoTest\\lib\\site-packages\\paramiko\\sftp_client.py\", line 801, in get\n    with open(localpath, \"wb\") as fl:\n",
    "steps" : [ ],
    "attachments" : [ ],
    "parameters" : [ ],
    "hasContent" : true,
    "stepsCount" : 0,
    "attachmentsCount" : 0,
    "shouldDisplayMessage" : true
  }, {
    "name" : "data_clearing",
    "time" : {
      "start" : 1641450140614,
      "stop" : 1641450141947,
      "duration" : 1333
    },
    "status" : "broken",
    "statusMessage" : "FileNotFoundError: [Errno 2] No such file or directory: '/home/chenlei/backup_sqls/apiautotest_2022-01-06T14_21_46.sql'\n",
    "statusTrace" : "  File \"D:\\PythonCode\\apiAutoTest\\lib\\site-packages\\pluggy\\callers.py\", line 187, in _multicall\n    res = hook_impl.function(*args)\n  File \"D:\\PythonCode\\apiAutoTest\\lib\\site-packages\\_pytest\\fixtures.py\", line 1117, in pytest_fixture_setup\n    result = call_fixture_func(fixturefunc, request, kwargs)\n  File \"D:\\PythonCode\\apiAutoTest\\lib\\site-packages\\_pytest\\fixtures.py\", line 915, in call_fixture_func\n    fixture_result = next(generator)\n  File \"F:\\CODE\\python-test\\apiAutoTest\\test\\conftest.py\", line 24, in data_clearing\n    DataClearing.backup_mysql()\n  File \"F:\\CODE\\python-test\\apiAutoTest\\tools\\data_clearing.py\", line 119, in backup_mysql\n    cls.server.files_action(0,\n  File \"F:\\CODE\\python-test\\apiAutoTest\\tools\\data_clearing.py\", line 77, in files_action\n    self.ftp_client.get(remotepath=remote_path, localpath=file_path)\n  File \"D:\\PythonCode\\apiAutoTest\\lib\\site-packages\\paramiko\\sftp_client.py\", line 801, in get\n    with open(localpath, \"wb\") as fl:\n",
    "steps" : [ ],
    "attachments" : [ ],
    "parameters" : [ ],
    "hasContent" : true,
    "stepsCount" : 0,
    "attachmentsCount" : 0,
    "shouldDisplayMessage" : true
  }, {
    "name" : "data_clearing",
    "time" : {
      "start" : 1641450142991,
      "stop" : 1641450144142,
      "duration" : 1151
    },
    "status" : "broken",
    "statusMessage" : "FileNotFoundError: [Errno 2] No such file or directory: '/home/chenlei/backup_sqls/apiautotest_2022-01-06T14_21_46.sql'\n",
    "statusTrace" : "  File \"D:\\PythonCode\\apiAutoTest\\lib\\site-packages\\pluggy\\callers.py\", line 187, in _multicall\n    res = hook_impl.function(*args)\n  File \"D:\\PythonCode\\apiAutoTest\\lib\\site-packages\\_pytest\\fixtures.py\", line 1117, in pytest_fixture_setup\n    result = call_fixture_func(fixturefunc, request, kwargs)\n  File \"D:\\PythonCode\\apiAutoTest\\lib\\site-packages\\_pytest\\fixtures.py\", line 915, in call_fixture_func\n    fixture_result = next(generator)\n  File \"F:\\CODE\\python-test\\apiAutoTest\\test\\conftest.py\", line 24, in data_clearing\n    DataClearing.backup_mysql()\n  File \"F:\\CODE\\python-test\\apiAutoTest\\tools\\data_clearing.py\", line 119, in backup_mysql\n    cls.server.files_action(0,\n  File \"F:\\CODE\\python-test\\apiAutoTest\\tools\\data_clearing.py\", line 77, in files_action\n    self.ftp_client.get(remotepath=remote_path, localpath=file_path)\n  File \"D:\\PythonCode\\apiAutoTest\\lib\\site-packages\\paramiko\\sftp_client.py\", line 801, in get\n    with open(localpath, \"wb\") as fl:\n",
    "steps" : [ ],
    "attachments" : [ ],
    "parameters" : [ ],
    "hasContent" : true,
    "stepsCount" : 0,
    "attachmentsCount" : 0,
    "shouldDisplayMessage" : true
  }, {
    "name" : "data_clearing",
    "time" : {
      "start" : 1641450145165,
      "stop" : 1641450146218,
      "duration" : 1053
    },
    "status" : "broken",
    "statusMessage" : "FileNotFoundError: [Errno 2] No such file or directory: '/home/chenlei/backup_sqls/apiautotest_2022-01-06T14_21_46.sql'\n",
    "statusTrace" : "  File \"D:\\PythonCode\\apiAutoTest\\lib\\site-packages\\pluggy\\callers.py\", line 187, in _multicall\n    res = hook_impl.function(*args)\n  File \"D:\\PythonCode\\apiAutoTest\\lib\\site-packages\\_pytest\\fixtures.py\", line 1117, in pytest_fixture_setup\n    result = call_fixture_func(fixturefunc, request, kwargs)\n  File \"D:\\PythonCode\\apiAutoTest\\lib\\site-packages\\_pytest\\fixtures.py\", line 915, in call_fixture_func\n    fixture_result = next(generator)\n  File \"F:\\CODE\\python-test\\apiAutoTest\\test\\conftest.py\", line 24, in data_clearing\n    DataClearing.backup_mysql()\n  File \"F:\\CODE\\python-test\\apiAutoTest\\tools\\data_clearing.py\", line 119, in backup_mysql\n    cls.server.files_action(0,\n  File \"F:\\CODE\\python-test\\apiAutoTest\\tools\\data_clearing.py\", line 77, in files_action\n    self.ftp_client.get(remotepath=remote_path, localpath=file_path)\n  File \"D:\\PythonCode\\apiAutoTest\\lib\\site-packages\\paramiko\\sftp_client.py\", line 801, in get\n    with open(localpath, \"wb\") as fl:\n",
    "steps" : [ ],
    "attachments" : [ ],
    "parameters" : [ ],
    "hasContent" : true,
    "stepsCount" : 0,
    "attachmentsCount" : 0,
    "shouldDisplayMessage" : true
  }, {
    "name" : "data_clearing",
    "time" : {
      "start" : 1641450147252,
      "stop" : 1641450148412,
      "duration" : 1160
    },
    "status" : "broken",
    "statusMessage" : "FileNotFoundError: [Errno 2] No such file or directory: '/home/chenlei/backup_sqls/apiautotest_2022-01-06T14_21_46.sql'\n",
    "statusTrace" : "  File \"D:\\PythonCode\\apiAutoTest\\lib\\site-packages\\pluggy\\callers.py\", line 187, in _multicall\n    res = hook_impl.function(*args)\n  File \"D:\\PythonCode\\apiAutoTest\\lib\\site-packages\\_pytest\\fixtures.py\", line 1117, in pytest_fixture_setup\n    result = call_fixture_func(fixturefunc, request, kwargs)\n  File \"D:\\PythonCode\\apiAutoTest\\lib\\site-packages\\_pytest\\fixtures.py\", line 915, in call_fixture_func\n    fixture_result = next(generator)\n  File \"F:\\CODE\\python-test\\apiAutoTest\\test\\conftest.py\", line 24, in data_clearing\n    DataClearing.backup_mysql()\n  File \"F:\\CODE\\python-test\\apiAutoTest\\tools\\data_clearing.py\", line 119, in backup_mysql\n    cls.server.files_action(0,\n  File \"F:\\CODE\\python-test\\apiAutoTest\\tools\\data_clearing.py\", line 77, in files_action\n    self.ftp_client.get(remotepath=remote_path, localpath=file_path)\n  File \"D:\\PythonCode\\apiAutoTest\\lib\\site-packages\\paramiko\\sftp_client.py\", line 801, in get\n    with open(localpath, \"wb\") as fl:\n",
    "steps" : [ ],
    "attachments" : [ ],
    "parameters" : [ ],
    "hasContent" : true,
    "stepsCount" : 0,
    "attachmentsCount" : 0,
    "shouldDisplayMessage" : true
  }, {
    "name" : "data_clearing",
    "time" : {
      "start" : 1641450149446,
      "stop" : 1641450150471,
      "duration" : 1025
    },
    "status" : "broken",
    "statusMessage" : "FileNotFoundError: [Errno 2] No such file or directory: '/home/chenlei/backup_sqls/apiautotest_2022-01-06T14_21_46.sql'\n",
    "statusTrace" : "  File \"D:\\PythonCode\\apiAutoTest\\lib\\site-packages\\pluggy\\callers.py\", line 187, in _multicall\n    res = hook_impl.function(*args)\n  File \"D:\\PythonCode\\apiAutoTest\\lib\\site-packages\\_pytest\\fixtures.py\", line 1117, in pytest_fixture_setup\n    result = call_fixture_func(fixturefunc, request, kwargs)\n  File \"D:\\PythonCode\\apiAutoTest\\lib\\site-packages\\_pytest\\fixtures.py\", line 915, in call_fixture_func\n    fixture_result = next(generator)\n  File \"F:\\CODE\\python-test\\apiAutoTest\\test\\conftest.py\", line 24, in data_clearing\n    DataClearing.backup_mysql()\n  File \"F:\\CODE\\python-test\\apiAutoTest\\tools\\data_clearing.py\", line 119, in backup_mysql\n    cls.server.files_action(0,\n  File \"F:\\CODE\\python-test\\apiAutoTest\\tools\\data_clearing.py\", line 77, in files_action\n    self.ftp_client.get(remotepath=remote_path, localpath=file_path)\n  File \"D:\\PythonCode\\apiAutoTest\\lib\\site-packages\\paramiko\\sftp_client.py\", line 801, in get\n    with open(localpath, \"wb\") as fl:\n",
    "steps" : [ ],
    "attachments" : [ ],
    "parameters" : [ ],
    "hasContent" : true,
    "stepsCount" : 0,
    "attachmentsCount" : 0,
    "shouldDisplayMessage" : true
  }, {
    "name" : "data_clearing",
    "time" : {
      "start" : 1641450151505,
      "stop" : 1641450152945,
      "duration" : 1440
    },
    "status" : "broken",
    "statusMessage" : "FileNotFoundError: [Errno 2] No such file or directory: '/home/chenlei/backup_sqls/apiautotest_2022-01-06T14_21_46.sql'\n",
    "statusTrace" : "  File \"D:\\PythonCode\\apiAutoTest\\lib\\site-packages\\pluggy\\callers.py\", line 187, in _multicall\n    res = hook_impl.function(*args)\n  File \"D:\\PythonCode\\apiAutoTest\\lib\\site-packages\\_pytest\\fixtures.py\", line 1117, in pytest_fixture_setup\n    result = call_fixture_func(fixturefunc, request, kwargs)\n  File \"D:\\PythonCode\\apiAutoTest\\lib\\site-packages\\_pytest\\fixtures.py\", line 915, in call_fixture_func\n    fixture_result = next(generator)\n  File \"F:\\CODE\\python-test\\apiAutoTest\\test\\conftest.py\", line 24, in data_clearing\n    DataClearing.backup_mysql()\n  File \"F:\\CODE\\python-test\\apiAutoTest\\tools\\data_clearing.py\", line 119, in backup_mysql\n    cls.server.files_action(0,\n  File \"F:\\CODE\\python-test\\apiAutoTest\\tools\\data_clearing.py\", line 77, in files_action\n    self.ftp_client.get(remotepath=remote_path, localpath=file_path)\n  File \"D:\\PythonCode\\apiAutoTest\\lib\\site-packages\\paramiko\\sftp_client.py\", line 801, in get\n    with open(localpath, \"wb\") as fl:\n",
    "steps" : [ ],
    "attachments" : [ ],
    "parameters" : [ ],
    "hasContent" : true,
    "stepsCount" : 0,
    "attachmentsCount" : 0,
    "shouldDisplayMessage" : true
  }, {
    "name" : "data_clearing",
    "time" : {
      "start" : 1641450153963,
      "stop" : 1641450155182,
      "duration" : 1219
    },
    "status" : "broken",
    "statusMessage" : "FileNotFoundError: [Errno 2] No such file or directory: '/home/chenlei/backup_sqls/apiautotest_2022-01-06T14_21_46.sql'\n",
    "statusTrace" : "  File \"D:\\PythonCode\\apiAutoTest\\lib\\site-packages\\pluggy\\callers.py\", line 187, in _multicall\n    res = hook_impl.function(*args)\n  File \"D:\\PythonCode\\apiAutoTest\\lib\\site-packages\\_pytest\\fixtures.py\", line 1117, in pytest_fixture_setup\n    result = call_fixture_func(fixturefunc, request, kwargs)\n  File \"D:\\PythonCode\\apiAutoTest\\lib\\site-packages\\_pytest\\fixtures.py\", line 915, in call_fixture_func\n    fixture_result = next(generator)\n  File \"F:\\CODE\\python-test\\apiAutoTest\\test\\conftest.py\", line 24, in data_clearing\n    DataClearing.backup_mysql()\n  File \"F:\\CODE\\python-test\\apiAutoTest\\tools\\data_clearing.py\", line 119, in backup_mysql\n    cls.server.files_action(0,\n  File \"F:\\CODE\\python-test\\apiAutoTest\\tools\\data_clearing.py\", line 77, in files_action\n    self.ftp_client.get(remotepath=remote_path, localpath=file_path)\n  File \"D:\\PythonCode\\apiAutoTest\\lib\\site-packages\\paramiko\\sftp_client.py\", line 801, in get\n    with open(localpath, \"wb\") as fl:\n",
    "steps" : [ ],
    "attachments" : [ ],
    "parameters" : [ ],
    "hasContent" : true,
    "stepsCount" : 0,
    "attachmentsCount" : 0,
    "shouldDisplayMessage" : true
  }, {
    "name" : "data_clearing",
    "time" : {
      "start" : 1641450156219,
      "stop" : 1641450157501,
      "duration" : 1282
    },
    "status" : "broken",
    "statusMessage" : "FileNotFoundError: [Errno 2] No such file or directory: '/home/chenlei/backup_sqls/apiautotest_2022-01-06T14_21_46.sql'\n",
    "statusTrace" : "  File \"D:\\PythonCode\\apiAutoTest\\lib\\site-packages\\pluggy\\callers.py\", line 187, in _multicall\n    res = hook_impl.function(*args)\n  File \"D:\\PythonCode\\apiAutoTest\\lib\\site-packages\\_pytest\\fixtures.py\", line 1117, in pytest_fixture_setup\n    result = call_fixture_func(fixturefunc, request, kwargs)\n  File \"D:\\PythonCode\\apiAutoTest\\lib\\site-packages\\_pytest\\fixtures.py\", line 915, in call_fixture_func\n    fixture_result = next(generator)\n  File \"F:\\CODE\\python-test\\apiAutoTest\\test\\conftest.py\", line 24, in data_clearing\n    DataClearing.backup_mysql()\n  File \"F:\\CODE\\python-test\\apiAutoTest\\tools\\data_clearing.py\", line 119, in backup_mysql\n    cls.server.files_action(0,\n  File \"F:\\CODE\\python-test\\apiAutoTest\\tools\\data_clearing.py\", line 77, in files_action\n    self.ftp_client.get(remotepath=remote_path, localpath=file_path)\n  File \"D:\\PythonCode\\apiAutoTest\\lib\\site-packages\\paramiko\\sftp_client.py\", line 801, in get\n    with open(localpath, \"wb\") as fl:\n",
    "steps" : [ ],
    "attachments" : [ ],
    "parameters" : [ ],
    "hasContent" : true,
    "stepsCount" : 0,
    "attachmentsCount" : 0,
    "shouldDisplayMessage" : true
  }, {
    "name" : "data_clearing",
    "time" : {
      "start" : 1641450158525,
      "stop" : 1641450159578,
      "duration" : 1053
    },
    "status" : "broken",
    "statusMessage" : "FileNotFoundError: [Errno 2] No such file or directory: '/home/chenlei/backup_sqls/apiautotest_2022-01-06T14_21_46.sql'\n",
    "statusTrace" : "  File \"D:\\PythonCode\\apiAutoTest\\lib\\site-packages\\pluggy\\callers.py\", line 187, in _multicall\n    res = hook_impl.function(*args)\n  File \"D:\\PythonCode\\apiAutoTest\\lib\\site-packages\\_pytest\\fixtures.py\", line 1117, in pytest_fixture_setup\n    result = call_fixture_func(fixturefunc, request, kwargs)\n  File \"D:\\PythonCode\\apiAutoTest\\lib\\site-packages\\_pytest\\fixtures.py\", line 915, in call_fixture_func\n    fixture_result = next(generator)\n  File \"F:\\CODE\\python-test\\apiAutoTest\\test\\conftest.py\", line 24, in data_clearing\n    DataClearing.backup_mysql()\n  File \"F:\\CODE\\python-test\\apiAutoTest\\tools\\data_clearing.py\", line 119, in backup_mysql\n    cls.server.files_action(0,\n  File \"F:\\CODE\\python-test\\apiAutoTest\\tools\\data_clearing.py\", line 77, in files_action\n    self.ftp_client.get(remotepath=remote_path, localpath=file_path)\n  File \"D:\\PythonCode\\apiAutoTest\\lib\\site-packages\\paramiko\\sftp_client.py\", line 801, in get\n    with open(localpath, \"wb\") as fl:\n",
    "steps" : [ ],
    "attachments" : [ ],
    "parameters" : [ ],
    "hasContent" : true,
    "stepsCount" : 0,
    "attachmentsCount" : 0,
    "shouldDisplayMessage" : true
  }, {
    "name" : "data_clearing",
    "time" : {
      "start" : 1641450160612,
      "stop" : 1641450161975,
      "duration" : 1363
    },
    "status" : "broken",
    "statusMessage" : "FileNotFoundError: [Errno 2] No such file or directory: '/home/chenlei/backup_sqls/apiautotest_2022-01-06T14_21_46.sql'\n",
    "statusTrace" : "  File \"D:\\PythonCode\\apiAutoTest\\lib\\site-packages\\pluggy\\callers.py\", line 187, in _multicall\n    res = hook_impl.function(*args)\n  File \"D:\\PythonCode\\apiAutoTest\\lib\\site-packages\\_pytest\\fixtures.py\", line 1117, in pytest_fixture_setup\n    result = call_fixture_func(fixturefunc, request, kwargs)\n  File \"D:\\PythonCode\\apiAutoTest\\lib\\site-packages\\_pytest\\fixtures.py\", line 915, in call_fixture_func\n    fixture_result = next(generator)\n  File \"F:\\CODE\\python-test\\apiAutoTest\\test\\conftest.py\", line 24, in data_clearing\n    DataClearing.backup_mysql()\n  File \"F:\\CODE\\python-test\\apiAutoTest\\tools\\data_clearing.py\", line 119, in backup_mysql\n    cls.server.files_action(0,\n  File \"F:\\CODE\\python-test\\apiAutoTest\\tools\\data_clearing.py\", line 77, in files_action\n    self.ftp_client.get(remotepath=remote_path, localpath=file_path)\n  File \"D:\\PythonCode\\apiAutoTest\\lib\\site-packages\\paramiko\\sftp_client.py\", line 801, in get\n    with open(localpath, \"wb\") as fl:\n",
    "steps" : [ ],
    "attachments" : [ ],
    "parameters" : [ ],
    "hasContent" : true,
    "stepsCount" : 0,
    "attachmentsCount" : 0,
    "shouldDisplayMessage" : true
  }, {
    "name" : "data_clearing",
    "time" : {
      "start" : 1641450163003,
      "stop" : 1641450164425,
      "duration" : 1422
    },
    "status" : "broken",
    "statusMessage" : "FileNotFoundError: [Errno 2] No such file or directory: '/home/chenlei/backup_sqls/apiautotest_2022-01-06T14_21_46.sql'\n",
    "statusTrace" : "  File \"D:\\PythonCode\\apiAutoTest\\lib\\site-packages\\pluggy\\callers.py\", line 187, in _multicall\n    res = hook_impl.function(*args)\n  File \"D:\\PythonCode\\apiAutoTest\\lib\\site-packages\\_pytest\\fixtures.py\", line 1117, in pytest_fixture_setup\n    result = call_fixture_func(fixturefunc, request, kwargs)\n  File \"D:\\PythonCode\\apiAutoTest\\lib\\site-packages\\_pytest\\fixtures.py\", line 915, in call_fixture_func\n    fixture_result = next(generator)\n  File \"F:\\CODE\\python-test\\apiAutoTest\\test\\conftest.py\", line 24, in data_clearing\n    DataClearing.backup_mysql()\n  File \"F:\\CODE\\python-test\\apiAutoTest\\tools\\data_clearing.py\", line 119, in backup_mysql\n    cls.server.files_action(0,\n  File \"F:\\CODE\\python-test\\apiAutoTest\\tools\\data_clearing.py\", line 77, in files_action\n    self.ftp_client.get(remotepath=remote_path, localpath=file_path)\n  File \"D:\\PythonCode\\apiAutoTest\\lib\\site-packages\\paramiko\\sftp_client.py\", line 801, in get\n    with open(localpath, \"wb\") as fl:\n",
    "steps" : [ ],
    "attachments" : [ ],
    "parameters" : [ ],
    "hasContent" : true,
    "stepsCount" : 0,
    "attachmentsCount" : 0,
    "shouldDisplayMessage" : true
  }, {
    "name" : "data_clearing",
    "time" : {
      "start" : 1641450165460,
      "stop" : 1641450166940,
      "duration" : 1480
    },
    "status" : "broken",
    "statusMessage" : "FileNotFoundError: [Errno 2] No such file or directory: '/home/chenlei/backup_sqls/apiautotest_2022-01-06T14_21_46.sql'\n",
    "statusTrace" : "  File \"D:\\PythonCode\\apiAutoTest\\lib\\site-packages\\pluggy\\callers.py\", line 187, in _multicall\n    res = hook_impl.function(*args)\n  File \"D:\\PythonCode\\apiAutoTest\\lib\\site-packages\\_pytest\\fixtures.py\", line 1117, in pytest_fixture_setup\n    result = call_fixture_func(fixturefunc, request, kwargs)\n  File \"D:\\PythonCode\\apiAutoTest\\lib\\site-packages\\_pytest\\fixtures.py\", line 915, in call_fixture_func\n    fixture_result = next(generator)\n  File \"F:\\CODE\\python-test\\apiAutoTest\\test\\conftest.py\", line 24, in data_clearing\n    DataClearing.backup_mysql()\n  File \"F:\\CODE\\python-test\\apiAutoTest\\tools\\data_clearing.py\", line 119, in backup_mysql\n    cls.server.files_action(0,\n  File \"F:\\CODE\\python-test\\apiAutoTest\\tools\\data_clearing.py\", line 77, in files_action\n    self.ftp_client.get(remotepath=remote_path, localpath=file_path)\n  File \"D:\\PythonCode\\apiAutoTest\\lib\\site-packages\\paramiko\\sftp_client.py\", line 801, in get\n    with open(localpath, \"wb\") as fl:\n",
    "steps" : [ ],
    "attachments" : [ ],
    "parameters" : [ ],
    "hasContent" : true,
    "stepsCount" : 0,
    "attachmentsCount" : 0,
    "shouldDisplayMessage" : true
  }, {
    "name" : "data_clearing",
    "time" : {
      "start" : 1641450167970,
      "stop" : 1641450169161,
      "duration" : 1191
    },
    "status" : "broken",
    "statusMessage" : "FileNotFoundError: [Errno 2] No such file or directory: '/home/chenlei/backup_sqls/apiautotest_2022-01-06T14_21_46.sql'\n",
    "statusTrace" : "  File \"D:\\PythonCode\\apiAutoTest\\lib\\site-packages\\pluggy\\callers.py\", line 187, in _multicall\n    res = hook_impl.function(*args)\n  File \"D:\\PythonCode\\apiAutoTest\\lib\\site-packages\\_pytest\\fixtures.py\", line 1117, in pytest_fixture_setup\n    result = call_fixture_func(fixturefunc, request, kwargs)\n  File \"D:\\PythonCode\\apiAutoTest\\lib\\site-packages\\_pytest\\fixtures.py\", line 915, in call_fixture_func\n    fixture_result = next(generator)\n  File \"F:\\CODE\\python-test\\apiAutoTest\\test\\conftest.py\", line 24, in data_clearing\n    DataClearing.backup_mysql()\n  File \"F:\\CODE\\python-test\\apiAutoTest\\tools\\data_clearing.py\", line 119, in backup_mysql\n    cls.server.files_action(0,\n  File \"F:\\CODE\\python-test\\apiAutoTest\\tools\\data_clearing.py\", line 77, in files_action\n    self.ftp_client.get(remotepath=remote_path, localpath=file_path)\n  File \"D:\\PythonCode\\apiAutoTest\\lib\\site-packages\\paramiko\\sftp_client.py\", line 801, in get\n    with open(localpath, \"wb\") as fl:\n",
    "steps" : [ ],
    "attachments" : [ ],
    "parameters" : [ ],
    "hasContent" : true,
    "stepsCount" : 0,
    "attachmentsCount" : 0,
    "shouldDisplayMessage" : true
  }, {
    "name" : "data_clearing",
    "time" : {
      "start" : 1641450170202,
      "stop" : 1641450171644,
      "duration" : 1442
    },
    "status" : "broken",
    "statusMessage" : "FileNotFoundError: [Errno 2] No such file or directory: '/home/chenlei/backup_sqls/apiautotest_2022-01-06T14_21_46.sql'\n",
    "statusTrace" : "  File \"D:\\PythonCode\\apiAutoTest\\lib\\site-packages\\pluggy\\callers.py\", line 187, in _multicall\n    res = hook_impl.function(*args)\n  File \"D:\\PythonCode\\apiAutoTest\\lib\\site-packages\\_pytest\\fixtures.py\", line 1117, in pytest_fixture_setup\n    result = call_fixture_func(fixturefunc, request, kwargs)\n  File \"D:\\PythonCode\\apiAutoTest\\lib\\site-packages\\_pytest\\fixtures.py\", line 915, in call_fixture_func\n    fixture_result = next(generator)\n  File \"F:\\CODE\\python-test\\apiAutoTest\\test\\conftest.py\", line 24, in data_clearing\n    DataClearing.backup_mysql()\n  File \"F:\\CODE\\python-test\\apiAutoTest\\tools\\data_clearing.py\", line 119, in backup_mysql\n    cls.server.files_action(0,\n  File \"F:\\CODE\\python-test\\apiAutoTest\\tools\\data_clearing.py\", line 77, in files_action\n    self.ftp_client.get(remotepath=remote_path, localpath=file_path)\n  File \"D:\\PythonCode\\apiAutoTest\\lib\\site-packages\\paramiko\\sftp_client.py\", line 801, in get\n    with open(localpath, \"wb\") as fl:\n",
    "steps" : [ ],
    "attachments" : [ ],
    "parameters" : [ ],
    "hasContent" : true,
    "stepsCount" : 0,
    "attachmentsCount" : 0,
    "shouldDisplayMessage" : true
  }, {
    "name" : "data_clearing",
    "time" : {
      "start" : 1641450172681,
      "stop" : 1641450173962,
      "duration" : 1281
    },
    "status" : "broken",
    "statusMessage" : "FileNotFoundError: [Errno 2] No such file or directory: '/home/chenlei/backup_sqls/apiautotest_2022-01-06T14_21_46.sql'\n",
    "statusTrace" : "  File \"D:\\PythonCode\\apiAutoTest\\lib\\site-packages\\pluggy\\callers.py\", line 187, in _multicall\n    res = hook_impl.function(*args)\n  File \"D:\\PythonCode\\apiAutoTest\\lib\\site-packages\\_pytest\\fixtures.py\", line 1117, in pytest_fixture_setup\n    result = call_fixture_func(fixturefunc, request, kwargs)\n  File \"D:\\PythonCode\\apiAutoTest\\lib\\site-packages\\_pytest\\fixtures.py\", line 915, in call_fixture_func\n    fixture_result = next(generator)\n  File \"F:\\CODE\\python-test\\apiAutoTest\\test\\conftest.py\", line 24, in data_clearing\n    DataClearing.backup_mysql()\n  File \"F:\\CODE\\python-test\\apiAutoTest\\tools\\data_clearing.py\", line 119, in backup_mysql\n    cls.server.files_action(0,\n  File \"F:\\CODE\\python-test\\apiAutoTest\\tools\\data_clearing.py\", line 77, in files_action\n    self.ftp_client.get(remotepath=remote_path, localpath=file_path)\n  File \"D:\\PythonCode\\apiAutoTest\\lib\\site-packages\\paramiko\\sftp_client.py\", line 801, in get\n    with open(localpath, \"wb\") as fl:\n",
    "steps" : [ ],
    "attachments" : [ ],
    "parameters" : [ ],
    "hasContent" : true,
    "stepsCount" : 0,
    "attachmentsCount" : 0,
    "shouldDisplayMessage" : true
  }, {
    "name" : "data_clearing",
    "time" : {
      "start" : 1641450175002,
      "stop" : 1641450176103,
      "duration" : 1101
    },
    "status" : "broken",
    "statusMessage" : "FileNotFoundError: [Errno 2] No such file or directory: '/home/chenlei/backup_sqls/apiautotest_2022-01-06T14_21_46.sql'\n",
    "statusTrace" : "  File \"D:\\PythonCode\\apiAutoTest\\lib\\site-packages\\pluggy\\callers.py\", line 187, in _multicall\n    res = hook_impl.function(*args)\n  File \"D:\\PythonCode\\apiAutoTest\\lib\\site-packages\\_pytest\\fixtures.py\", line 1117, in pytest_fixture_setup\n    result = call_fixture_func(fixturefunc, request, kwargs)\n  File \"D:\\PythonCode\\apiAutoTest\\lib\\site-packages\\_pytest\\fixtures.py\", line 915, in call_fixture_func\n    fixture_result = next(generator)\n  File \"F:\\CODE\\python-test\\apiAutoTest\\test\\conftest.py\", line 24, in data_clearing\n    DataClearing.backup_mysql()\n  File \"F:\\CODE\\python-test\\apiAutoTest\\tools\\data_clearing.py\", line 119, in backup_mysql\n    cls.server.files_action(0,\n  File \"F:\\CODE\\python-test\\apiAutoTest\\tools\\data_clearing.py\", line 77, in files_action\n    self.ftp_client.get(remotepath=remote_path, localpath=file_path)\n  File \"D:\\PythonCode\\apiAutoTest\\lib\\site-packages\\paramiko\\sftp_client.py\", line 801, in get\n    with open(localpath, \"wb\") as fl:\n",
    "steps" : [ ],
    "attachments" : [ ],
    "parameters" : [ ],
    "hasContent" : true,
    "stepsCount" : 0,
    "attachmentsCount" : 0,
    "shouldDisplayMessage" : true
  }, {
    "name" : "data_clearing",
    "time" : {
      "start" : 1641450177123,
      "stop" : 1641450178354,
      "duration" : 1231
    },
    "status" : "broken",
    "statusMessage" : "FileNotFoundError: [Errno 2] No such file or directory: '/home/chenlei/backup_sqls/apiautotest_2022-01-06T14_21_46.sql'\n",
    "statusTrace" : "  File \"D:\\PythonCode\\apiAutoTest\\lib\\site-packages\\pluggy\\callers.py\", line 187, in _multicall\n    res = hook_impl.function(*args)\n  File \"D:\\PythonCode\\apiAutoTest\\lib\\site-packages\\_pytest\\fixtures.py\", line 1117, in pytest_fixture_setup\n    result = call_fixture_func(fixturefunc, request, kwargs)\n  File \"D:\\PythonCode\\apiAutoTest\\lib\\site-packages\\_pytest\\fixtures.py\", line 915, in call_fixture_func\n    fixture_result = next(generator)\n  File \"F:\\CODE\\python-test\\apiAutoTest\\test\\conftest.py\", line 24, in data_clearing\n    DataClearing.backup_mysql()\n  File \"F:\\CODE\\python-test\\apiAutoTest\\tools\\data_clearing.py\", line 119, in backup_mysql\n    cls.server.files_action(0,\n  File \"F:\\CODE\\python-test\\apiAutoTest\\tools\\data_clearing.py\", line 77, in files_action\n    self.ftp_client.get(remotepath=remote_path, localpath=file_path)\n  File \"D:\\PythonCode\\apiAutoTest\\lib\\site-packages\\paramiko\\sftp_client.py\", line 801, in get\n    with open(localpath, \"wb\") as fl:\n",
    "steps" : [ ],
    "attachments" : [ ],
    "parameters" : [ ],
    "hasContent" : true,
    "stepsCount" : 0,
    "attachmentsCount" : 0,
    "shouldDisplayMessage" : true
  }, {
    "name" : "data_clearing",
    "time" : {
      "start" : 1641450179390,
      "stop" : 1641450180951,
      "duration" : 1561
    },
    "status" : "broken",
    "statusMessage" : "FileNotFoundError: [Errno 2] No such file or directory: '/home/chenlei/backup_sqls/apiautotest_2022-01-06T14_21_46.sql'\n",
    "statusTrace" : "  File \"D:\\PythonCode\\apiAutoTest\\lib\\site-packages\\pluggy\\callers.py\", line 187, in _multicall\n    res = hook_impl.function(*args)\n  File \"D:\\PythonCode\\apiAutoTest\\lib\\site-packages\\_pytest\\fixtures.py\", line 1117, in pytest_fixture_setup\n    result = call_fixture_func(fixturefunc, request, kwargs)\n  File \"D:\\PythonCode\\apiAutoTest\\lib\\site-packages\\_pytest\\fixtures.py\", line 915, in call_fixture_func\n    fixture_result = next(generator)\n  File \"F:\\CODE\\python-test\\apiAutoTest\\test\\conftest.py\", line 24, in data_clearing\n    DataClearing.backup_mysql()\n  File \"F:\\CODE\\python-test\\apiAutoTest\\tools\\data_clearing.py\", line 119, in backup_mysql\n    cls.server.files_action(0,\n  File \"F:\\CODE\\python-test\\apiAutoTest\\tools\\data_clearing.py\", line 77, in files_action\n    self.ftp_client.get(remotepath=remote_path, localpath=file_path)\n  File \"D:\\PythonCode\\apiAutoTest\\lib\\site-packages\\paramiko\\sftp_client.py\", line 801, in get\n    with open(localpath, \"wb\") as fl:\n",
    "steps" : [ ],
    "attachments" : [ ],
    "parameters" : [ ],
    "hasContent" : true,
    "stepsCount" : 0,
    "attachmentsCount" : 0,
    "shouldDisplayMessage" : true
  }, {
    "name" : "data_clearing",
    "time" : {
      "start" : 1641450181982,
      "stop" : 1641450183196,
      "duration" : 1214
    },
    "status" : "broken",
    "statusMessage" : "FileNotFoundError: [Errno 2] No such file or directory: '/home/chenlei/backup_sqls/apiautotest_2022-01-06T14_21_46.sql'\n",
    "statusTrace" : "  File \"D:\\PythonCode\\apiAutoTest\\lib\\site-packages\\pluggy\\callers.py\", line 187, in _multicall\n    res = hook_impl.function(*args)\n  File \"D:\\PythonCode\\apiAutoTest\\lib\\site-packages\\_pytest\\fixtures.py\", line 1117, in pytest_fixture_setup\n    result = call_fixture_func(fixturefunc, request, kwargs)\n  File \"D:\\PythonCode\\apiAutoTest\\lib\\site-packages\\_pytest\\fixtures.py\", line 915, in call_fixture_func\n    fixture_result = next(generator)\n  File \"F:\\CODE\\python-test\\apiAutoTest\\test\\conftest.py\", line 24, in data_clearing\n    DataClearing.backup_mysql()\n  File \"F:\\CODE\\python-test\\apiAutoTest\\tools\\data_clearing.py\", line 119, in backup_mysql\n    cls.server.files_action(0,\n  File \"F:\\CODE\\python-test\\apiAutoTest\\tools\\data_clearing.py\", line 77, in files_action\n    self.ftp_client.get(remotepath=remote_path, localpath=file_path)\n  File \"D:\\PythonCode\\apiAutoTest\\lib\\site-packages\\paramiko\\sftp_client.py\", line 801, in get\n    with open(localpath, \"wb\") as fl:\n",
    "steps" : [ ],
    "attachments" : [ ],
    "parameters" : [ ],
    "hasContent" : true,
    "stepsCount" : 0,
    "attachmentsCount" : 0,
    "shouldDisplayMessage" : true
  }, {
    "name" : "data_clearing",
    "time" : {
      "start" : 1641450184239,
      "stop" : 1641450185506,
      "duration" : 1267
    },
    "status" : "broken",
    "statusMessage" : "FileNotFoundError: [Errno 2] No such file or directory: '/home/chenlei/backup_sqls/apiautotest_2022-01-06T14_21_46.sql'\n",
    "statusTrace" : "  File \"D:\\PythonCode\\apiAutoTest\\lib\\site-packages\\pluggy\\callers.py\", line 187, in _multicall\n    res = hook_impl.function(*args)\n  File \"D:\\PythonCode\\apiAutoTest\\lib\\site-packages\\_pytest\\fixtures.py\", line 1117, in pytest_fixture_setup\n    result = call_fixture_func(fixturefunc, request, kwargs)\n  File \"D:\\PythonCode\\apiAutoTest\\lib\\site-packages\\_pytest\\fixtures.py\", line 915, in call_fixture_func\n    fixture_result = next(generator)\n  File \"F:\\CODE\\python-test\\apiAutoTest\\test\\conftest.py\", line 24, in data_clearing\n    DataClearing.backup_mysql()\n  File \"F:\\CODE\\python-test\\apiAutoTest\\tools\\data_clearing.py\", line 119, in backup_mysql\n    cls.server.files_action(0,\n  File \"F:\\CODE\\python-test\\apiAutoTest\\tools\\data_clearing.py\", line 77, in files_action\n    self.ftp_client.get(remotepath=remote_path, localpath=file_path)\n  File \"D:\\PythonCode\\apiAutoTest\\lib\\site-packages\\paramiko\\sftp_client.py\", line 801, in get\n    with open(localpath, \"wb\") as fl:\n",
    "steps" : [ ],
    "attachments" : [ ],
    "parameters" : [ ],
    "hasContent" : true,
    "stepsCount" : 0,
    "attachmentsCount" : 0,
    "shouldDisplayMessage" : true
  }, {
    "name" : "data_clearing",
    "time" : {
      "start" : 1641450186532,
      "stop" : 1641450187662,
      "duration" : 1130
    },
    "status" : "broken",
    "statusMessage" : "FileNotFoundError: [Errno 2] No such file or directory: '/home/chenlei/backup_sqls/apiautotest_2022-01-06T14_21_46.sql'\n",
    "statusTrace" : "  File \"D:\\PythonCode\\apiAutoTest\\lib\\site-packages\\pluggy\\callers.py\", line 187, in _multicall\n    res = hook_impl.function(*args)\n  File \"D:\\PythonCode\\apiAutoTest\\lib\\site-packages\\_pytest\\fixtures.py\", line 1117, in pytest_fixture_setup\n    result = call_fixture_func(fixturefunc, request, kwargs)\n  File \"D:\\PythonCode\\apiAutoTest\\lib\\site-packages\\_pytest\\fixtures.py\", line 915, in call_fixture_func\n    fixture_result = next(generator)\n  File \"F:\\CODE\\python-test\\apiAutoTest\\test\\conftest.py\", line 24, in data_clearing\n    DataClearing.backup_mysql()\n  File \"F:\\CODE\\python-test\\apiAutoTest\\tools\\data_clearing.py\", line 119, in backup_mysql\n    cls.server.files_action(0,\n  File \"F:\\CODE\\python-test\\apiAutoTest\\tools\\data_clearing.py\", line 77, in files_action\n    self.ftp_client.get(remotepath=remote_path, localpath=file_path)\n  File \"D:\\PythonCode\\apiAutoTest\\lib\\site-packages\\paramiko\\sftp_client.py\", line 801, in get\n    with open(localpath, \"wb\") as fl:\n",
    "steps" : [ ],
    "attachments" : [ ],
    "parameters" : [ ],
    "hasContent" : true,
    "stepsCount" : 0,
    "attachmentsCount" : 0,
    "shouldDisplayMessage" : true
  }, {
    "name" : "data_clearing",
    "time" : {
      "start" : 1641450188697,
      "stop" : 1641450190113,
      "duration" : 1416
    },
    "status" : "broken",
    "statusMessage" : "FileNotFoundError: [Errno 2] No such file or directory: '/home/chenlei/backup_sqls/apiautotest_2022-01-06T14_21_46.sql'\n",
    "statusTrace" : "  File \"D:\\PythonCode\\apiAutoTest\\lib\\site-packages\\pluggy\\callers.py\", line 187, in _multicall\n    res = hook_impl.function(*args)\n  File \"D:\\PythonCode\\apiAutoTest\\lib\\site-packages\\_pytest\\fixtures.py\", line 1117, in pytest_fixture_setup\n    result = call_fixture_func(fixturefunc, request, kwargs)\n  File \"D:\\PythonCode\\apiAutoTest\\lib\\site-packages\\_pytest\\fixtures.py\", line 915, in call_fixture_func\n    fixture_result = next(generator)\n  File \"F:\\CODE\\python-test\\apiAutoTest\\test\\conftest.py\", line 24, in data_clearing\n    DataClearing.backup_mysql()\n  File \"F:\\CODE\\python-test\\apiAutoTest\\tools\\data_clearing.py\", line 119, in backup_mysql\n    cls.server.files_action(0,\n  File \"F:\\CODE\\python-test\\apiAutoTest\\tools\\data_clearing.py\", line 77, in files_action\n    self.ftp_client.get(remotepath=remote_path, localpath=file_path)\n  File \"D:\\PythonCode\\apiAutoTest\\lib\\site-packages\\paramiko\\sftp_client.py\", line 801, in get\n    with open(localpath, \"wb\") as fl:\n",
    "steps" : [ ],
    "attachments" : [ ],
    "parameters" : [ ],
    "hasContent" : true,
    "stepsCount" : 0,
    "attachmentsCount" : 0,
    "shouldDisplayMessage" : true
  }, {
    "name" : "data_clearing",
    "time" : {
      "start" : 1641450191143,
      "stop" : 1641450192779,
      "duration" : 1636
    },
    "status" : "broken",
    "statusMessage" : "FileNotFoundError: [Errno 2] No such file or directory: '/home/chenlei/backup_sqls/apiautotest_2022-01-06T14_21_46.sql'\n",
    "statusTrace" : "  File \"D:\\PythonCode\\apiAutoTest\\lib\\site-packages\\pluggy\\callers.py\", line 187, in _multicall\n    res = hook_impl.function(*args)\n  File \"D:\\PythonCode\\apiAutoTest\\lib\\site-packages\\_pytest\\fixtures.py\", line 1117, in pytest_fixture_setup\n    result = call_fixture_func(fixturefunc, request, kwargs)\n  File \"D:\\PythonCode\\apiAutoTest\\lib\\site-packages\\_pytest\\fixtures.py\", line 915, in call_fixture_func\n    fixture_result = next(generator)\n  File \"F:\\CODE\\python-test\\apiAutoTest\\test\\conftest.py\", line 24, in data_clearing\n    DataClearing.backup_mysql()\n  File \"F:\\CODE\\python-test\\apiAutoTest\\tools\\data_clearing.py\", line 119, in backup_mysql\n    cls.server.files_action(0,\n  File \"F:\\CODE\\python-test\\apiAutoTest\\tools\\data_clearing.py\", line 77, in files_action\n    self.ftp_client.get(remotepath=remote_path, localpath=file_path)\n  File \"D:\\PythonCode\\apiAutoTest\\lib\\site-packages\\paramiko\\sftp_client.py\", line 801, in get\n    with open(localpath, \"wb\") as fl:\n",
    "steps" : [ ],
    "attachments" : [ ],
    "parameters" : [ ],
    "hasContent" : true,
    "stepsCount" : 0,
    "attachmentsCount" : 0,
    "shouldDisplayMessage" : true
  }, {
    "name" : "data_clearing",
    "time" : {
      "start" : 1641450193814,
      "stop" : 1641450195099,
      "duration" : 1285
    },
    "status" : "broken",
    "statusMessage" : "FileNotFoundError: [Errno 2] No such file or directory: '/home/chenlei/backup_sqls/apiautotest_2022-01-06T14_21_46.sql'\n",
    "statusTrace" : "  File \"D:\\PythonCode\\apiAutoTest\\lib\\site-packages\\pluggy\\callers.py\", line 187, in _multicall\n    res = hook_impl.function(*args)\n  File \"D:\\PythonCode\\apiAutoTest\\lib\\site-packages\\_pytest\\fixtures.py\", line 1117, in pytest_fixture_setup\n    result = call_fixture_func(fixturefunc, request, kwargs)\n  File \"D:\\PythonCode\\apiAutoTest\\lib\\site-packages\\_pytest\\fixtures.py\", line 915, in call_fixture_func\n    fixture_result = next(generator)\n  File \"F:\\CODE\\python-test\\apiAutoTest\\test\\conftest.py\", line 24, in data_clearing\n    DataClearing.backup_mysql()\n  File \"F:\\CODE\\python-test\\apiAutoTest\\tools\\data_clearing.py\", line 119, in backup_mysql\n    cls.server.files_action(0,\n  File \"F:\\CODE\\python-test\\apiAutoTest\\tools\\data_clearing.py\", line 77, in files_action\n    self.ftp_client.get(remotepath=remote_path, localpath=file_path)\n  File \"D:\\PythonCode\\apiAutoTest\\lib\\site-packages\\paramiko\\sftp_client.py\", line 801, in get\n    with open(localpath, \"wb\") as fl:\n",
    "steps" : [ ],
    "attachments" : [ ],
    "parameters" : [ ],
    "hasContent" : true,
    "stepsCount" : 0,
    "attachmentsCount" : 0,
    "shouldDisplayMessage" : true
  }, {
    "name" : "data_clearing",
    "time" : {
      "start" : 1641450196137,
      "stop" : 1641450197283,
      "duration" : 1146
    },
    "status" : "broken",
    "statusMessage" : "FileNotFoundError: [Errno 2] No such file or directory: '/home/chenlei/backup_sqls/apiautotest_2022-01-06T14_21_46.sql'\n",
    "statusTrace" : "  File \"D:\\PythonCode\\apiAutoTest\\lib\\site-packages\\pluggy\\callers.py\", line 187, in _multicall\n    res = hook_impl.function(*args)\n  File \"D:\\PythonCode\\apiAutoTest\\lib\\site-packages\\_pytest\\fixtures.py\", line 1117, in pytest_fixture_setup\n    result = call_fixture_func(fixturefunc, request, kwargs)\n  File \"D:\\PythonCode\\apiAutoTest\\lib\\site-packages\\_pytest\\fixtures.py\", line 915, in call_fixture_func\n    fixture_result = next(generator)\n  File \"F:\\CODE\\python-test\\apiAutoTest\\test\\conftest.py\", line 24, in data_clearing\n    DataClearing.backup_mysql()\n  File \"F:\\CODE\\python-test\\apiAutoTest\\tools\\data_clearing.py\", line 119, in backup_mysql\n    cls.server.files_action(0,\n  File \"F:\\CODE\\python-test\\apiAutoTest\\tools\\data_clearing.py\", line 77, in files_action\n    self.ftp_client.get(remotepath=remote_path, localpath=file_path)\n  File \"D:\\PythonCode\\apiAutoTest\\lib\\site-packages\\paramiko\\sftp_client.py\", line 801, in get\n    with open(localpath, \"wb\") as fl:\n",
    "steps" : [ ],
    "attachments" : [ ],
    "parameters" : [ ],
    "hasContent" : true,
    "stepsCount" : 0,
    "attachmentsCount" : 0,
    "shouldDisplayMessage" : true
  }, {
    "name" : "data_clearing",
    "time" : {
      "start" : 1641450198320,
      "stop" : 1641450199596,
      "duration" : 1276
    },
    "status" : "broken",
    "statusMessage" : "FileNotFoundError: [Errno 2] No such file or directory: '/home/chenlei/backup_sqls/apiautotest_2022-01-06T14_21_46.sql'\n",
    "statusTrace" : "  File \"D:\\PythonCode\\apiAutoTest\\lib\\site-packages\\pluggy\\callers.py\", line 187, in _multicall\n    res = hook_impl.function(*args)\n  File \"D:\\PythonCode\\apiAutoTest\\lib\\site-packages\\_pytest\\fixtures.py\", line 1117, in pytest_fixture_setup\n    result = call_fixture_func(fixturefunc, request, kwargs)\n  File \"D:\\PythonCode\\apiAutoTest\\lib\\site-packages\\_pytest\\fixtures.py\", line 915, in call_fixture_func\n    fixture_result = next(generator)\n  File \"F:\\CODE\\python-test\\apiAutoTest\\test\\conftest.py\", line 24, in data_clearing\n    DataClearing.backup_mysql()\n  File \"F:\\CODE\\python-test\\apiAutoTest\\tools\\data_clearing.py\", line 119, in backup_mysql\n    cls.server.files_action(0,\n  File \"F:\\CODE\\python-test\\apiAutoTest\\tools\\data_clearing.py\", line 77, in files_action\n    self.ftp_client.get(remotepath=remote_path, localpath=file_path)\n  File \"D:\\PythonCode\\apiAutoTest\\lib\\site-packages\\paramiko\\sftp_client.py\", line 801, in get\n    with open(localpath, \"wb\") as fl:\n",
    "steps" : [ ],
    "attachments" : [ ],
    "parameters" : [ ],
    "hasContent" : true,
    "stepsCount" : 0,
    "attachmentsCount" : 0,
    "shouldDisplayMessage" : true
  }, {
    "name" : "data_clearing",
    "time" : {
      "start" : 1641450200615,
      "stop" : 1641450201702,
      "duration" : 1087
    },
    "status" : "broken",
    "statusMessage" : "FileNotFoundError: [Errno 2] No such file or directory: '/home/chenlei/backup_sqls/apiautotest_2022-01-06T14_21_46.sql'\n",
    "statusTrace" : "  File \"D:\\PythonCode\\apiAutoTest\\lib\\site-packages\\pluggy\\callers.py\", line 187, in _multicall\n    res = hook_impl.function(*args)\n  File \"D:\\PythonCode\\apiAutoTest\\lib\\site-packages\\_pytest\\fixtures.py\", line 1117, in pytest_fixture_setup\n    result = call_fixture_func(fixturefunc, request, kwargs)\n  File \"D:\\PythonCode\\apiAutoTest\\lib\\site-packages\\_pytest\\fixtures.py\", line 915, in call_fixture_func\n    fixture_result = next(generator)\n  File \"F:\\CODE\\python-test\\apiAutoTest\\test\\conftest.py\", line 24, in data_clearing\n    DataClearing.backup_mysql()\n  File \"F:\\CODE\\python-test\\apiAutoTest\\tools\\data_clearing.py\", line 119, in backup_mysql\n    cls.server.files_action(0,\n  File \"F:\\CODE\\python-test\\apiAutoTest\\tools\\data_clearing.py\", line 77, in files_action\n    self.ftp_client.get(remotepath=remote_path, localpath=file_path)\n  File \"D:\\PythonCode\\apiAutoTest\\lib\\site-packages\\paramiko\\sftp_client.py\", line 801, in get\n    with open(localpath, \"wb\") as fl:\n",
    "steps" : [ ],
    "attachments" : [ ],
    "parameters" : [ ],
    "hasContent" : true,
    "stepsCount" : 0,
    "attachmentsCount" : 0,
    "shouldDisplayMessage" : true
  }, {
    "name" : "data_clearing",
    "time" : {
      "start" : 1641450202736,
      "stop" : 1641450203998,
      "duration" : 1262
    },
    "status" : "broken",
    "statusMessage" : "FileNotFoundError: [Errno 2] No such file or directory: '/home/chenlei/backup_sqls/apiautotest_2022-01-06T14_21_46.sql'\n",
    "statusTrace" : "  File \"D:\\PythonCode\\apiAutoTest\\lib\\site-packages\\pluggy\\callers.py\", line 187, in _multicall\n    res = hook_impl.function(*args)\n  File \"D:\\PythonCode\\apiAutoTest\\lib\\site-packages\\_pytest\\fixtures.py\", line 1117, in pytest_fixture_setup\n    result = call_fixture_func(fixturefunc, request, kwargs)\n  File \"D:\\PythonCode\\apiAutoTest\\lib\\site-packages\\_pytest\\fixtures.py\", line 915, in call_fixture_func\n    fixture_result = next(generator)\n  File \"F:\\CODE\\python-test\\apiAutoTest\\test\\conftest.py\", line 24, in data_clearing\n    DataClearing.backup_mysql()\n  File \"F:\\CODE\\python-test\\apiAutoTest\\tools\\data_clearing.py\", line 119, in backup_mysql\n    cls.server.files_action(0,\n  File \"F:\\CODE\\python-test\\apiAutoTest\\tools\\data_clearing.py\", line 77, in files_action\n    self.ftp_client.get(remotepath=remote_path, localpath=file_path)\n  File \"D:\\PythonCode\\apiAutoTest\\lib\\site-packages\\paramiko\\sftp_client.py\", line 801, in get\n    with open(localpath, \"wb\") as fl:\n",
    "steps" : [ ],
    "attachments" : [ ],
    "parameters" : [ ],
    "hasContent" : true,
    "stepsCount" : 0,
    "attachmentsCount" : 0,
    "shouldDisplayMessage" : true
  }, {
    "name" : "data_clearing",
    "time" : {
      "start" : 1641450205024,
      "stop" : 1641450206317,
      "duration" : 1293
    },
    "status" : "broken",
    "statusMessage" : "FileNotFoundError: [Errno 2] No such file or directory: '/home/chenlei/backup_sqls/apiautotest_2022-01-06T14_21_46.sql'\n",
    "statusTrace" : "  File \"D:\\PythonCode\\apiAutoTest\\lib\\site-packages\\pluggy\\callers.py\", line 187, in _multicall\n    res = hook_impl.function(*args)\n  File \"D:\\PythonCode\\apiAutoTest\\lib\\site-packages\\_pytest\\fixtures.py\", line 1117, in pytest_fixture_setup\n    result = call_fixture_func(fixturefunc, request, kwargs)\n  File \"D:\\PythonCode\\apiAutoTest\\lib\\site-packages\\_pytest\\fixtures.py\", line 915, in call_fixture_func\n    fixture_result = next(generator)\n  File \"F:\\CODE\\python-test\\apiAutoTest\\test\\conftest.py\", line 24, in data_clearing\n    DataClearing.backup_mysql()\n  File \"F:\\CODE\\python-test\\apiAutoTest\\tools\\data_clearing.py\", line 119, in backup_mysql\n    cls.server.files_action(0,\n  File \"F:\\CODE\\python-test\\apiAutoTest\\tools\\data_clearing.py\", line 77, in files_action\n    self.ftp_client.get(remotepath=remote_path, localpath=file_path)\n  File \"D:\\PythonCode\\apiAutoTest\\lib\\site-packages\\paramiko\\sftp_client.py\", line 801, in get\n    with open(localpath, \"wb\") as fl:\n",
    "steps" : [ ],
    "attachments" : [ ],
    "parameters" : [ ],
    "hasContent" : true,
    "stepsCount" : 0,
    "attachmentsCount" : 0,
    "shouldDisplayMessage" : true
  }, {
    "name" : "data_clearing",
    "time" : {
      "start" : 1641450207359,
      "stop" : 1641450208843,
      "duration" : 1484
    },
    "status" : "broken",
    "statusMessage" : "FileNotFoundError: [Errno 2] No such file or directory: '/home/chenlei/backup_sqls/apiautotest_2022-01-06T14_21_46.sql'\n",
    "statusTrace" : "  File \"D:\\PythonCode\\apiAutoTest\\lib\\site-packages\\pluggy\\callers.py\", line 187, in _multicall\n    res = hook_impl.function(*args)\n  File \"D:\\PythonCode\\apiAutoTest\\lib\\site-packages\\_pytest\\fixtures.py\", line 1117, in pytest_fixture_setup\n    result = call_fixture_func(fixturefunc, request, kwargs)\n  File \"D:\\PythonCode\\apiAutoTest\\lib\\site-packages\\_pytest\\fixtures.py\", line 915, in call_fixture_func\n    fixture_result = next(generator)\n  File \"F:\\CODE\\python-test\\apiAutoTest\\test\\conftest.py\", line 24, in data_clearing\n    DataClearing.backup_mysql()\n  File \"F:\\CODE\\python-test\\apiAutoTest\\tools\\data_clearing.py\", line 119, in backup_mysql\n    cls.server.files_action(0,\n  File \"F:\\CODE\\python-test\\apiAutoTest\\tools\\data_clearing.py\", line 77, in files_action\n    self.ftp_client.get(remotepath=remote_path, localpath=file_path)\n  File \"D:\\PythonCode\\apiAutoTest\\lib\\site-packages\\paramiko\\sftp_client.py\", line 801, in get\n    with open(localpath, \"wb\") as fl:\n",
    "steps" : [ ],
    "attachments" : [ ],
    "parameters" : [ ],
    "hasContent" : true,
    "stepsCount" : 0,
    "attachmentsCount" : 0,
    "shouldDisplayMessage" : true
  }, {
    "name" : "data_clearing",
    "time" : {
      "start" : 1641450209872,
      "stop" : 1641450211049,
      "duration" : 1177
    },
    "status" : "broken",
    "statusMessage" : "FileNotFoundError: [Errno 2] No such file or directory: '/home/chenlei/backup_sqls/apiautotest_2022-01-06T14_21_46.sql'\n",
    "statusTrace" : "  File \"D:\\PythonCode\\apiAutoTest\\lib\\site-packages\\pluggy\\callers.py\", line 187, in _multicall\n    res = hook_impl.function(*args)\n  File \"D:\\PythonCode\\apiAutoTest\\lib\\site-packages\\_pytest\\fixtures.py\", line 1117, in pytest_fixture_setup\n    result = call_fixture_func(fixturefunc, request, kwargs)\n  File \"D:\\PythonCode\\apiAutoTest\\lib\\site-packages\\_pytest\\fixtures.py\", line 915, in call_fixture_func\n    fixture_result = next(generator)\n  File \"F:\\CODE\\python-test\\apiAutoTest\\test\\conftest.py\", line 24, in data_clearing\n    DataClearing.backup_mysql()\n  File \"F:\\CODE\\python-test\\apiAutoTest\\tools\\data_clearing.py\", line 119, in backup_mysql\n    cls.server.files_action(0,\n  File \"F:\\CODE\\python-test\\apiAutoTest\\tools\\data_clearing.py\", line 77, in files_action\n    self.ftp_client.get(remotepath=remote_path, localpath=file_path)\n  File \"D:\\PythonCode\\apiAutoTest\\lib\\site-packages\\paramiko\\sftp_client.py\", line 801, in get\n    with open(localpath, \"wb\") as fl:\n",
    "steps" : [ ],
    "attachments" : [ ],
    "parameters" : [ ],
    "hasContent" : true,
    "stepsCount" : 0,
    "attachmentsCount" : 0,
    "shouldDisplayMessage" : true
  }, {
    "name" : "data_clearing",
    "time" : {
      "start" : 1641450212089,
      "stop" : 1641450213223,
      "duration" : 1134
    },
    "status" : "broken",
    "statusMessage" : "FileNotFoundError: [Errno 2] No such file or directory: '/home/chenlei/backup_sqls/apiautotest_2022-01-06T14_21_46.sql'\n",
    "statusTrace" : "  File \"D:\\PythonCode\\apiAutoTest\\lib\\site-packages\\pluggy\\callers.py\", line 187, in _multicall\n    res = hook_impl.function(*args)\n  File \"D:\\PythonCode\\apiAutoTest\\lib\\site-packages\\_pytest\\fixtures.py\", line 1117, in pytest_fixture_setup\n    result = call_fixture_func(fixturefunc, request, kwargs)\n  File \"D:\\PythonCode\\apiAutoTest\\lib\\site-packages\\_pytest\\fixtures.py\", line 915, in call_fixture_func\n    fixture_result = next(generator)\n  File \"F:\\CODE\\python-test\\apiAutoTest\\test\\conftest.py\", line 24, in data_clearing\n    DataClearing.backup_mysql()\n  File \"F:\\CODE\\python-test\\apiAutoTest\\tools\\data_clearing.py\", line 119, in backup_mysql\n    cls.server.files_action(0,\n  File \"F:\\CODE\\python-test\\apiAutoTest\\tools\\data_clearing.py\", line 77, in files_action\n    self.ftp_client.get(remotepath=remote_path, localpath=file_path)\n  File \"D:\\PythonCode\\apiAutoTest\\lib\\site-packages\\paramiko\\sftp_client.py\", line 801, in get\n    with open(localpath, \"wb\") as fl:\n",
    "steps" : [ ],
    "attachments" : [ ],
    "parameters" : [ ],
    "hasContent" : true,
    "stepsCount" : 0,
    "attachmentsCount" : 0,
    "shouldDisplayMessage" : true
  }, {
    "name" : "data_clearing",
    "time" : {
      "start" : 1641450214253,
      "stop" : 1641450215529,
      "duration" : 1276
    },
    "status" : "broken",
    "statusMessage" : "FileNotFoundError: [Errno 2] No such file or directory: '/home/chenlei/backup_sqls/apiautotest_2022-01-06T14_21_46.sql'\n",
    "statusTrace" : "  File \"D:\\PythonCode\\apiAutoTest\\lib\\site-packages\\pluggy\\callers.py\", line 187, in _multicall\n    res = hook_impl.function(*args)\n  File \"D:\\PythonCode\\apiAutoTest\\lib\\site-packages\\_pytest\\fixtures.py\", line 1117, in pytest_fixture_setup\n    result = call_fixture_func(fixturefunc, request, kwargs)\n  File \"D:\\PythonCode\\apiAutoTest\\lib\\site-packages\\_pytest\\fixtures.py\", line 915, in call_fixture_func\n    fixture_result = next(generator)\n  File \"F:\\CODE\\python-test\\apiAutoTest\\test\\conftest.py\", line 24, in data_clearing\n    DataClearing.backup_mysql()\n  File \"F:\\CODE\\python-test\\apiAutoTest\\tools\\data_clearing.py\", line 119, in backup_mysql\n    cls.server.files_action(0,\n  File \"F:\\CODE\\python-test\\apiAutoTest\\tools\\data_clearing.py\", line 77, in files_action\n    self.ftp_client.get(remotepath=remote_path, localpath=file_path)\n  File \"D:\\PythonCode\\apiAutoTest\\lib\\site-packages\\paramiko\\sftp_client.py\", line 801, in get\n    with open(localpath, \"wb\") as fl:\n",
    "steps" : [ ],
    "attachments" : [ ],
    "parameters" : [ ],
    "hasContent" : true,
    "stepsCount" : 0,
    "attachmentsCount" : 0,
    "shouldDisplayMessage" : true
  }, {
    "name" : "data_clearing",
    "time" : {
      "start" : 1641450216593,
      "stop" : 1641450217619,
      "duration" : 1026
    },
    "status" : "broken",
    "statusMessage" : "FileNotFoundError: [Errno 2] No such file or directory: '/home/chenlei/backup_sqls/apiautotest_2022-01-06T14_21_46.sql'\n",
    "statusTrace" : "  File \"D:\\PythonCode\\apiAutoTest\\lib\\site-packages\\pluggy\\callers.py\", line 187, in _multicall\n    res = hook_impl.function(*args)\n  File \"D:\\PythonCode\\apiAutoTest\\lib\\site-packages\\_pytest\\fixtures.py\", line 1117, in pytest_fixture_setup\n    result = call_fixture_func(fixturefunc, request, kwargs)\n  File \"D:\\PythonCode\\apiAutoTest\\lib\\site-packages\\_pytest\\fixtures.py\", line 915, in call_fixture_func\n    fixture_result = next(generator)\n  File \"F:\\CODE\\python-test\\apiAutoTest\\test\\conftest.py\", line 24, in data_clearing\n    DataClearing.backup_mysql()\n  File \"F:\\CODE\\python-test\\apiAutoTest\\tools\\data_clearing.py\", line 119, in backup_mysql\n    cls.server.files_action(0,\n  File \"F:\\CODE\\python-test\\apiAutoTest\\tools\\data_clearing.py\", line 77, in files_action\n    self.ftp_client.get(remotepath=remote_path, localpath=file_path)\n  File \"D:\\PythonCode\\apiAutoTest\\lib\\site-packages\\paramiko\\sftp_client.py\", line 801, in get\n    with open(localpath, \"wb\") as fl:\n",
    "steps" : [ ],
    "attachments" : [ ],
    "parameters" : [ ],
    "hasContent" : true,
    "stepsCount" : 0,
    "attachmentsCount" : 0,
    "shouldDisplayMessage" : true
  }, {
    "name" : "data_clearing",
    "time" : {
      "start" : 1641450218650,
      "stop" : 1641450219856,
      "duration" : 1206
    },
    "status" : "broken",
    "statusMessage" : "FileNotFoundError: [Errno 2] No such file or directory: '/home/chenlei/backup_sqls/apiautotest_2022-01-06T14_21_46.sql'\n",
    "statusTrace" : "  File \"D:\\PythonCode\\apiAutoTest\\lib\\site-packages\\pluggy\\callers.py\", line 187, in _multicall\n    res = hook_impl.function(*args)\n  File \"D:\\PythonCode\\apiAutoTest\\lib\\site-packages\\_pytest\\fixtures.py\", line 1117, in pytest_fixture_setup\n    result = call_fixture_func(fixturefunc, request, kwargs)\n  File \"D:\\PythonCode\\apiAutoTest\\lib\\site-packages\\_pytest\\fixtures.py\", line 915, in call_fixture_func\n    fixture_result = next(generator)\n  File \"F:\\CODE\\python-test\\apiAutoTest\\test\\conftest.py\", line 24, in data_clearing\n    DataClearing.backup_mysql()\n  File \"F:\\CODE\\python-test\\apiAutoTest\\tools\\data_clearing.py\", line 119, in backup_mysql\n    cls.server.files_action(0,\n  File \"F:\\CODE\\python-test\\apiAutoTest\\tools\\data_clearing.py\", line 77, in files_action\n    self.ftp_client.get(remotepath=remote_path, localpath=file_path)\n  File \"D:\\PythonCode\\apiAutoTest\\lib\\site-packages\\paramiko\\sftp_client.py\", line 801, in get\n    with open(localpath, \"wb\") as fl:\n",
    "steps" : [ ],
    "attachments" : [ ],
    "parameters" : [ ],
    "hasContent" : true,
    "stepsCount" : 0,
    "attachmentsCount" : 0,
    "shouldDisplayMessage" : true
  }, {
    "name" : "data_clearing",
    "time" : {
      "start" : 1641450220891,
      "stop" : 1641450222270,
      "duration" : 1379
    },
    "status" : "broken",
    "statusMessage" : "FileNotFoundError: [Errno 2] No such file or directory: '/home/chenlei/backup_sqls/apiautotest_2022-01-06T14_21_46.sql'\n",
    "statusTrace" : "  File \"D:\\PythonCode\\apiAutoTest\\lib\\site-packages\\pluggy\\callers.py\", line 187, in _multicall\n    res = hook_impl.function(*args)\n  File \"D:\\PythonCode\\apiAutoTest\\lib\\site-packages\\_pytest\\fixtures.py\", line 1117, in pytest_fixture_setup\n    result = call_fixture_func(fixturefunc, request, kwargs)\n  File \"D:\\PythonCode\\apiAutoTest\\lib\\site-packages\\_pytest\\fixtures.py\", line 915, in call_fixture_func\n    fixture_result = next(generator)\n  File \"F:\\CODE\\python-test\\apiAutoTest\\test\\conftest.py\", line 24, in data_clearing\n    DataClearing.backup_mysql()\n  File \"F:\\CODE\\python-test\\apiAutoTest\\tools\\data_clearing.py\", line 119, in backup_mysql\n    cls.server.files_action(0,\n  File \"F:\\CODE\\python-test\\apiAutoTest\\tools\\data_clearing.py\", line 77, in files_action\n    self.ftp_client.get(remotepath=remote_path, localpath=file_path)\n  File \"D:\\PythonCode\\apiAutoTest\\lib\\site-packages\\paramiko\\sftp_client.py\", line 801, in get\n    with open(localpath, \"wb\") as fl:\n",
    "steps" : [ ],
    "attachments" : [ ],
    "parameters" : [ ],
    "hasContent" : true,
    "stepsCount" : 0,
    "attachmentsCount" : 0,
    "shouldDisplayMessage" : true
  }, {
    "name" : "data_clearing",
    "time" : {
      "start" : 1641450223295,
      "stop" : 1641450224799,
      "duration" : 1504
    },
    "status" : "broken",
    "statusMessage" : "FileNotFoundError: [Errno 2] No such file or directory: '/home/chenlei/backup_sqls/apiautotest_2022-01-06T14_21_46.sql'\n",
    "statusTrace" : "  File \"D:\\PythonCode\\apiAutoTest\\lib\\site-packages\\pluggy\\callers.py\", line 187, in _multicall\n    res = hook_impl.function(*args)\n  File \"D:\\PythonCode\\apiAutoTest\\lib\\site-packages\\_pytest\\fixtures.py\", line 1117, in pytest_fixture_setup\n    result = call_fixture_func(fixturefunc, request, kwargs)\n  File \"D:\\PythonCode\\apiAutoTest\\lib\\site-packages\\_pytest\\fixtures.py\", line 915, in call_fixture_func\n    fixture_result = next(generator)\n  File \"F:\\CODE\\python-test\\apiAutoTest\\test\\conftest.py\", line 24, in data_clearing\n    DataClearing.backup_mysql()\n  File \"F:\\CODE\\python-test\\apiAutoTest\\tools\\data_clearing.py\", line 119, in backup_mysql\n    cls.server.files_action(0,\n  File \"F:\\CODE\\python-test\\apiAutoTest\\tools\\data_clearing.py\", line 77, in files_action\n    self.ftp_client.get(remotepath=remote_path, localpath=file_path)\n  File \"D:\\PythonCode\\apiAutoTest\\lib\\site-packages\\paramiko\\sftp_client.py\", line 801, in get\n    with open(localpath, \"wb\") as fl:\n",
    "steps" : [ ],
    "attachments" : [ ],
    "parameters" : [ ],
    "hasContent" : true,
    "stepsCount" : 0,
    "attachmentsCount" : 0,
    "shouldDisplayMessage" : true
  }, {
    "name" : "data_clearing",
    "time" : {
      "start" : 1641450225839,
      "stop" : 1641450227107,
      "duration" : 1268
    },
    "status" : "broken",
    "statusMessage" : "FileNotFoundError: [Errno 2] No such file or directory: '/home/chenlei/backup_sqls/apiautotest_2022-01-06T14_21_46.sql'\n",
    "statusTrace" : "  File \"D:\\PythonCode\\apiAutoTest\\lib\\site-packages\\pluggy\\callers.py\", line 187, in _multicall\n    res = hook_impl.function(*args)\n  File \"D:\\PythonCode\\apiAutoTest\\lib\\site-packages\\_pytest\\fixtures.py\", line 1117, in pytest_fixture_setup\n    result = call_fixture_func(fixturefunc, request, kwargs)\n  File \"D:\\PythonCode\\apiAutoTest\\lib\\site-packages\\_pytest\\fixtures.py\", line 915, in call_fixture_func\n    fixture_result = next(generator)\n  File \"F:\\CODE\\python-test\\apiAutoTest\\test\\conftest.py\", line 24, in data_clearing\n    DataClearing.backup_mysql()\n  File \"F:\\CODE\\python-test\\apiAutoTest\\tools\\data_clearing.py\", line 119, in backup_mysql\n    cls.server.files_action(0,\n  File \"F:\\CODE\\python-test\\apiAutoTest\\tools\\data_clearing.py\", line 77, in files_action\n    self.ftp_client.get(remotepath=remote_path, localpath=file_path)\n  File \"D:\\PythonCode\\apiAutoTest\\lib\\site-packages\\paramiko\\sftp_client.py\", line 801, in get\n    with open(localpath, \"wb\") as fl:\n",
    "steps" : [ ],
    "attachments" : [ ],
    "parameters" : [ ],
    "hasContent" : true,
    "stepsCount" : 0,
    "attachmentsCount" : 0,
    "shouldDisplayMessage" : true
  }, {
    "name" : "data_clearing",
    "time" : {
      "start" : 1641450228125,
      "stop" : 1641450229220,
      "duration" : 1095
    },
    "status" : "broken",
    "statusMessage" : "FileNotFoundError: [Errno 2] No such file or directory: '/home/chenlei/backup_sqls/apiautotest_2022-01-06T14_21_46.sql'\n",
    "statusTrace" : "  File \"D:\\PythonCode\\apiAutoTest\\lib\\site-packages\\pluggy\\callers.py\", line 187, in _multicall\n    res = hook_impl.function(*args)\n  File \"D:\\PythonCode\\apiAutoTest\\lib\\site-packages\\_pytest\\fixtures.py\", line 1117, in pytest_fixture_setup\n    result = call_fixture_func(fixturefunc, request, kwargs)\n  File \"D:\\PythonCode\\apiAutoTest\\lib\\site-packages\\_pytest\\fixtures.py\", line 915, in call_fixture_func\n    fixture_result = next(generator)\n  File \"F:\\CODE\\python-test\\apiAutoTest\\test\\conftest.py\", line 24, in data_clearing\n    DataClearing.backup_mysql()\n  File \"F:\\CODE\\python-test\\apiAutoTest\\tools\\data_clearing.py\", line 119, in backup_mysql\n    cls.server.files_action(0,\n  File \"F:\\CODE\\python-test\\apiAutoTest\\tools\\data_clearing.py\", line 77, in files_action\n    self.ftp_client.get(remotepath=remote_path, localpath=file_path)\n  File \"D:\\PythonCode\\apiAutoTest\\lib\\site-packages\\paramiko\\sftp_client.py\", line 801, in get\n    with open(localpath, \"wb\") as fl:\n",
    "steps" : [ ],
    "attachments" : [ ],
    "parameters" : [ ],
    "hasContent" : true,
    "stepsCount" : 0,
    "attachmentsCount" : 0,
    "shouldDisplayMessage" : true
  }, {
    "name" : "data_clearing",
    "time" : {
      "start" : 1641450230257,
      "stop" : 1641450231436,
      "duration" : 1179
    },
    "status" : "broken",
    "statusMessage" : "FileNotFoundError: [Errno 2] No such file or directory: '/home/chenlei/backup_sqls/apiautotest_2022-01-06T14_21_46.sql'\n",
    "statusTrace" : "  File \"D:\\PythonCode\\apiAutoTest\\lib\\site-packages\\pluggy\\callers.py\", line 187, in _multicall\n    res = hook_impl.function(*args)\n  File \"D:\\PythonCode\\apiAutoTest\\lib\\site-packages\\_pytest\\fixtures.py\", line 1117, in pytest_fixture_setup\n    result = call_fixture_func(fixturefunc, request, kwargs)\n  File \"D:\\PythonCode\\apiAutoTest\\lib\\site-packages\\_pytest\\fixtures.py\", line 915, in call_fixture_func\n    fixture_result = next(generator)\n  File \"F:\\CODE\\python-test\\apiAutoTest\\test\\conftest.py\", line 24, in data_clearing\n    DataClearing.backup_mysql()\n  File \"F:\\CODE\\python-test\\apiAutoTest\\tools\\data_clearing.py\", line 119, in backup_mysql\n    cls.server.files_action(0,\n  File \"F:\\CODE\\python-test\\apiAutoTest\\tools\\data_clearing.py\", line 77, in files_action\n    self.ftp_client.get(remotepath=remote_path, localpath=file_path)\n  File \"D:\\PythonCode\\apiAutoTest\\lib\\site-packages\\paramiko\\sftp_client.py\", line 801, in get\n    with open(localpath, \"wb\") as fl:\n",
    "steps" : [ ],
    "attachments" : [ ],
    "parameters" : [ ],
    "hasContent" : true,
    "stepsCount" : 0,
    "attachmentsCount" : 0,
    "shouldDisplayMessage" : true
  }, {
    "name" : "data_clearing",
    "time" : {
      "start" : 1641450232454,
      "stop" : 1641450233519,
      "duration" : 1065
    },
    "status" : "broken",
    "statusMessage" : "FileNotFoundError: [Errno 2] No such file or directory: '/home/chenlei/backup_sqls/apiautotest_2022-01-06T14_21_46.sql'\n",
    "statusTrace" : "  File \"D:\\PythonCode\\apiAutoTest\\lib\\site-packages\\pluggy\\callers.py\", line 187, in _multicall\n    res = hook_impl.function(*args)\n  File \"D:\\PythonCode\\apiAutoTest\\lib\\site-packages\\_pytest\\fixtures.py\", line 1117, in pytest_fixture_setup\n    result = call_fixture_func(fixturefunc, request, kwargs)\n  File \"D:\\PythonCode\\apiAutoTest\\lib\\site-packages\\_pytest\\fixtures.py\", line 915, in call_fixture_func\n    fixture_result = next(generator)\n  File \"F:\\CODE\\python-test\\apiAutoTest\\test\\conftest.py\", line 24, in data_clearing\n    DataClearing.backup_mysql()\n  File \"F:\\CODE\\python-test\\apiAutoTest\\tools\\data_clearing.py\", line 119, in backup_mysql\n    cls.server.files_action(0,\n  File \"F:\\CODE\\python-test\\apiAutoTest\\tools\\data_clearing.py\", line 77, in files_action\n    self.ftp_client.get(remotepath=remote_path, localpath=file_path)\n  File \"D:\\PythonCode\\apiAutoTest\\lib\\site-packages\\paramiko\\sftp_client.py\", line 801, in get\n    with open(localpath, \"wb\") as fl:\n",
    "steps" : [ ],
    "attachments" : [ ],
    "parameters" : [ ],
    "hasContent" : true,
    "stepsCount" : 0,
    "attachmentsCount" : 0,
    "shouldDisplayMessage" : true
  }, {
    "name" : "data_clearing",
    "time" : {
      "start" : 1641450234565,
      "stop" : 1641450235874,
      "duration" : 1309
    },
    "status" : "broken",
    "statusMessage" : "FileNotFoundError: [Errno 2] No such file or directory: '/home/chenlei/backup_sqls/apiautotest_2022-01-06T14_21_46.sql'\n",
    "statusTrace" : "  File \"D:\\PythonCode\\apiAutoTest\\lib\\site-packages\\pluggy\\callers.py\", line 187, in _multicall\n    res = hook_impl.function(*args)\n  File \"D:\\PythonCode\\apiAutoTest\\lib\\site-packages\\_pytest\\fixtures.py\", line 1117, in pytest_fixture_setup\n    result = call_fixture_func(fixturefunc, request, kwargs)\n  File \"D:\\PythonCode\\apiAutoTest\\lib\\site-packages\\_pytest\\fixtures.py\", line 915, in call_fixture_func\n    fixture_result = next(generator)\n  File \"F:\\CODE\\python-test\\apiAutoTest\\test\\conftest.py\", line 24, in data_clearing\n    DataClearing.backup_mysql()\n  File \"F:\\CODE\\python-test\\apiAutoTest\\tools\\data_clearing.py\", line 119, in backup_mysql\n    cls.server.files_action(0,\n  File \"F:\\CODE\\python-test\\apiAutoTest\\tools\\data_clearing.py\", line 77, in files_action\n    self.ftp_client.get(remotepath=remote_path, localpath=file_path)\n  File \"D:\\PythonCode\\apiAutoTest\\lib\\site-packages\\paramiko\\sftp_client.py\", line 801, in get\n    with open(localpath, \"wb\") as fl:\n",
    "steps" : [ ],
    "attachments" : [ ],
    "parameters" : [ ],
    "hasContent" : true,
    "stepsCount" : 0,
    "attachmentsCount" : 0,
    "shouldDisplayMessage" : true
  }, {
    "name" : "data_clearing",
    "time" : {
      "start" : 1641450236894,
      "stop" : 1641450238092,
      "duration" : 1198
    },
    "status" : "broken",
    "statusMessage" : "FileNotFoundError: [Errno 2] No such file or directory: '/home/chenlei/backup_sqls/apiautotest_2022-01-06T14_21_46.sql'\n",
    "statusTrace" : "  File \"D:\\PythonCode\\apiAutoTest\\lib\\site-packages\\pluggy\\callers.py\", line 187, in _multicall\n    res = hook_impl.function(*args)\n  File \"D:\\PythonCode\\apiAutoTest\\lib\\site-packages\\_pytest\\fixtures.py\", line 1117, in pytest_fixture_setup\n    result = call_fixture_func(fixturefunc, request, kwargs)\n  File \"D:\\PythonCode\\apiAutoTest\\lib\\site-packages\\_pytest\\fixtures.py\", line 915, in call_fixture_func\n    fixture_result = next(generator)\n  File \"F:\\CODE\\python-test\\apiAutoTest\\test\\conftest.py\", line 24, in data_clearing\n    DataClearing.backup_mysql()\n  File \"F:\\CODE\\python-test\\apiAutoTest\\tools\\data_clearing.py\", line 119, in backup_mysql\n    cls.server.files_action(0,\n  File \"F:\\CODE\\python-test\\apiAutoTest\\tools\\data_clearing.py\", line 77, in files_action\n    self.ftp_client.get(remotepath=remote_path, localpath=file_path)\n  File \"D:\\PythonCode\\apiAutoTest\\lib\\site-packages\\paramiko\\sftp_client.py\", line 801, in get\n    with open(localpath, \"wb\") as fl:\n",
    "steps" : [ ],
    "attachments" : [ ],
    "parameters" : [ ],
    "hasContent" : true,
    "stepsCount" : 0,
    "attachmentsCount" : 0,
    "shouldDisplayMessage" : true
  }, {
    "name" : "data_clearing",
    "time" : {
      "start" : 1641450239143,
      "stop" : 1641450240438,
      "duration" : 1295
    },
    "status" : "broken",
    "statusMessage" : "FileNotFoundError: [Errno 2] No such file or directory: '/home/chenlei/backup_sqls/apiautotest_2022-01-06T14_21_46.sql'\n",
    "statusTrace" : "  File \"D:\\PythonCode\\apiAutoTest\\lib\\site-packages\\pluggy\\callers.py\", line 187, in _multicall\n    res = hook_impl.function(*args)\n  File \"D:\\PythonCode\\apiAutoTest\\lib\\site-packages\\_pytest\\fixtures.py\", line 1117, in pytest_fixture_setup\n    result = call_fixture_func(fixturefunc, request, kwargs)\n  File \"D:\\PythonCode\\apiAutoTest\\lib\\site-packages\\_pytest\\fixtures.py\", line 915, in call_fixture_func\n    fixture_result = next(generator)\n  File \"F:\\CODE\\python-test\\apiAutoTest\\test\\conftest.py\", line 24, in data_clearing\n    DataClearing.backup_mysql()\n  File \"F:\\CODE\\python-test\\apiAutoTest\\tools\\data_clearing.py\", line 119, in backup_mysql\n    cls.server.files_action(0,\n  File \"F:\\CODE\\python-test\\apiAutoTest\\tools\\data_clearing.py\", line 77, in files_action\n    self.ftp_client.get(remotepath=remote_path, localpath=file_path)\n  File \"D:\\PythonCode\\apiAutoTest\\lib\\site-packages\\paramiko\\sftp_client.py\", line 801, in get\n    with open(localpath, \"wb\") as fl:\n",
    "steps" : [ ],
    "attachments" : [ ],
    "parameters" : [ ],
    "hasContent" : true,
    "stepsCount" : 0,
    "attachmentsCount" : 0,
    "shouldDisplayMessage" : true
  }, {
    "name" : "data_clearing",
    "time" : {
      "start" : 1641450241471,
      "stop" : 1641450242636,
      "duration" : 1165
    },
    "status" : "broken",
    "statusMessage" : "FileNotFoundError: [Errno 2] No such file or directory: '/home/chenlei/backup_sqls/apiautotest_2022-01-06T14_21_46.sql'\n",
    "statusTrace" : "  File \"D:\\PythonCode\\apiAutoTest\\lib\\site-packages\\pluggy\\callers.py\", line 187, in _multicall\n    res = hook_impl.function(*args)\n  File \"D:\\PythonCode\\apiAutoTest\\lib\\site-packages\\_pytest\\fixtures.py\", line 1117, in pytest_fixture_setup\n    result = call_fixture_func(fixturefunc, request, kwargs)\n  File \"D:\\PythonCode\\apiAutoTest\\lib\\site-packages\\_pytest\\fixtures.py\", line 915, in call_fixture_func\n    fixture_result = next(generator)\n  File \"F:\\CODE\\python-test\\apiAutoTest\\test\\conftest.py\", line 24, in data_clearing\n    DataClearing.backup_mysql()\n  File \"F:\\CODE\\python-test\\apiAutoTest\\tools\\data_clearing.py\", line 119, in backup_mysql\n    cls.server.files_action(0,\n  File \"F:\\CODE\\python-test\\apiAutoTest\\tools\\data_clearing.py\", line 77, in files_action\n    self.ftp_client.get(remotepath=remote_path, localpath=file_path)\n  File \"D:\\PythonCode\\apiAutoTest\\lib\\site-packages\\paramiko\\sftp_client.py\", line 801, in get\n    with open(localpath, \"wb\") as fl:\n",
    "steps" : [ ],
    "attachments" : [ ],
    "parameters" : [ ],
    "hasContent" : true,
    "stepsCount" : 0,
    "attachmentsCount" : 0,
    "shouldDisplayMessage" : true
  }, {
    "name" : "data_clearing",
    "time" : {
      "start" : 1641450243680,
      "stop" : 1641450244665,
      "duration" : 985
    },
    "status" : "broken",
    "statusMessage" : "FileNotFoundError: [Errno 2] No such file or directory: '/home/chenlei/backup_sqls/apiautotest_2022-01-06T14_21_46.sql'\n",
    "statusTrace" : "  File \"D:\\PythonCode\\apiAutoTest\\lib\\site-packages\\pluggy\\callers.py\", line 187, in _multicall\n    res = hook_impl.function(*args)\n  File \"D:\\PythonCode\\apiAutoTest\\lib\\site-packages\\_pytest\\fixtures.py\", line 1117, in pytest_fixture_setup\n    result = call_fixture_func(fixturefunc, request, kwargs)\n  File \"D:\\PythonCode\\apiAutoTest\\lib\\site-packages\\_pytest\\fixtures.py\", line 915, in call_fixture_func\n    fixture_result = next(generator)\n  File \"F:\\CODE\\python-test\\apiAutoTest\\test\\conftest.py\", line 24, in data_clearing\n    DataClearing.backup_mysql()\n  File \"F:\\CODE\\python-test\\apiAutoTest\\tools\\data_clearing.py\", line 119, in backup_mysql\n    cls.server.files_action(0,\n  File \"F:\\CODE\\python-test\\apiAutoTest\\tools\\data_clearing.py\", line 77, in files_action\n    self.ftp_client.get(remotepath=remote_path, localpath=file_path)\n  File \"D:\\PythonCode\\apiAutoTest\\lib\\site-packages\\paramiko\\sftp_client.py\", line 801, in get\n    with open(localpath, \"wb\") as fl:\n",
    "steps" : [ ],
    "attachments" : [ ],
    "parameters" : [ ],
    "hasContent" : true,
    "stepsCount" : 0,
    "attachmentsCount" : 0,
    "shouldDisplayMessage" : true
  }, {
    "name" : "data_clearing",
    "time" : {
      "start" : 1641450245696,
      "stop" : 1641450246803,
      "duration" : 1107
    },
    "status" : "broken",
    "statusMessage" : "FileNotFoundError: [Errno 2] No such file or directory: '/home/chenlei/backup_sqls/apiautotest_2022-01-06T14_21_46.sql'\n",
    "statusTrace" : "  File \"D:\\PythonCode\\apiAutoTest\\lib\\site-packages\\pluggy\\callers.py\", line 187, in _multicall\n    res = hook_impl.function(*args)\n  File \"D:\\PythonCode\\apiAutoTest\\lib\\site-packages\\_pytest\\fixtures.py\", line 1117, in pytest_fixture_setup\n    result = call_fixture_func(fixturefunc, request, kwargs)\n  File \"D:\\PythonCode\\apiAutoTest\\lib\\site-packages\\_pytest\\fixtures.py\", line 915, in call_fixture_func\n    fixture_result = next(generator)\n  File \"F:\\CODE\\python-test\\apiAutoTest\\test\\conftest.py\", line 24, in data_clearing\n    DataClearing.backup_mysql()\n  File \"F:\\CODE\\python-test\\apiAutoTest\\tools\\data_clearing.py\", line 119, in backup_mysql\n    cls.server.files_action(0,\n  File \"F:\\CODE\\python-test\\apiAutoTest\\tools\\data_clearing.py\", line 77, in files_action\n    self.ftp_client.get(remotepath=remote_path, localpath=file_path)\n  File \"D:\\PythonCode\\apiAutoTest\\lib\\site-packages\\paramiko\\sftp_client.py\", line 801, in get\n    with open(localpath, \"wb\") as fl:\n",
    "steps" : [ ],
    "attachments" : [ ],
    "parameters" : [ ],
    "hasContent" : true,
    "stepsCount" : 0,
    "attachmentsCount" : 0,
    "shouldDisplayMessage" : true
  }, {
    "name" : "data_clearing",
    "time" : {
      "start" : 1641450247843,
      "stop" : 1641450248872,
      "duration" : 1029
    },
    "status" : "broken",
    "statusMessage" : "FileNotFoundError: [Errno 2] No such file or directory: '/home/chenlei/backup_sqls/apiautotest_2022-01-06T14_21_46.sql'\n",
    "statusTrace" : "  File \"D:\\PythonCode\\apiAutoTest\\lib\\site-packages\\pluggy\\callers.py\", line 187, in _multicall\n    res = hook_impl.function(*args)\n  File \"D:\\PythonCode\\apiAutoTest\\lib\\site-packages\\_pytest\\fixtures.py\", line 1117, in pytest_fixture_setup\n    result = call_fixture_func(fixturefunc, request, kwargs)\n  File \"D:\\PythonCode\\apiAutoTest\\lib\\site-packages\\_pytest\\fixtures.py\", line 915, in call_fixture_func\n    fixture_result = next(generator)\n  File \"F:\\CODE\\python-test\\apiAutoTest\\test\\conftest.py\", line 24, in data_clearing\n    DataClearing.backup_mysql()\n  File \"F:\\CODE\\python-test\\apiAutoTest\\tools\\data_clearing.py\", line 119, in backup_mysql\n    cls.server.files_action(0,\n  File \"F:\\CODE\\python-test\\apiAutoTest\\tools\\data_clearing.py\", line 77, in files_action\n    self.ftp_client.get(remotepath=remote_path, localpath=file_path)\n  File \"D:\\PythonCode\\apiAutoTest\\lib\\site-packages\\paramiko\\sftp_client.py\", line 801, in get\n    with open(localpath, \"wb\") as fl:\n",
    "steps" : [ ],
    "attachments" : [ ],
    "parameters" : [ ],
    "hasContent" : true,
    "stepsCount" : 0,
    "attachmentsCount" : 0,
    "shouldDisplayMessage" : true
  }, {
    "name" : "data_clearing",
    "time" : {
      "start" : 1641450249889,
      "stop" : 1641450251109,
      "duration" : 1220
    },
    "status" : "broken",
    "statusMessage" : "FileNotFoundError: [Errno 2] No such file or directory: '/home/chenlei/backup_sqls/apiautotest_2022-01-06T14_21_46.sql'\n",
    "statusTrace" : "  File \"D:\\PythonCode\\apiAutoTest\\lib\\site-packages\\pluggy\\callers.py\", line 187, in _multicall\n    res = hook_impl.function(*args)\n  File \"D:\\PythonCode\\apiAutoTest\\lib\\site-packages\\_pytest\\fixtures.py\", line 1117, in pytest_fixture_setup\n    result = call_fixture_func(fixturefunc, request, kwargs)\n  File \"D:\\PythonCode\\apiAutoTest\\lib\\site-packages\\_pytest\\fixtures.py\", line 915, in call_fixture_func\n    fixture_result = next(generator)\n  File \"F:\\CODE\\python-test\\apiAutoTest\\test\\conftest.py\", line 24, in data_clearing\n    DataClearing.backup_mysql()\n  File \"F:\\CODE\\python-test\\apiAutoTest\\tools\\data_clearing.py\", line 119, in backup_mysql\n    cls.server.files_action(0,\n  File \"F:\\CODE\\python-test\\apiAutoTest\\tools\\data_clearing.py\", line 77, in files_action\n    self.ftp_client.get(remotepath=remote_path, localpath=file_path)\n  File \"D:\\PythonCode\\apiAutoTest\\lib\\site-packages\\paramiko\\sftp_client.py\", line 801, in get\n    with open(localpath, \"wb\") as fl:\n",
    "steps" : [ ],
    "attachments" : [ ],
    "parameters" : [ ],
    "hasContent" : true,
    "stepsCount" : 0,
    "attachmentsCount" : 0,
    "shouldDisplayMessage" : true
  }, {
    "name" : "data_clearing",
    "time" : {
      "start" : 1641450252151,
      "stop" : 1641450253407,
      "duration" : 1256
    },
    "status" : "broken",
    "statusMessage" : "FileNotFoundError: [Errno 2] No such file or directory: '/home/chenlei/backup_sqls/apiautotest_2022-01-06T14_21_46.sql'\n",
    "statusTrace" : "  File \"D:\\PythonCode\\apiAutoTest\\lib\\site-packages\\pluggy\\callers.py\", line 187, in _multicall\n    res = hook_impl.function(*args)\n  File \"D:\\PythonCode\\apiAutoTest\\lib\\site-packages\\_pytest\\fixtures.py\", line 1117, in pytest_fixture_setup\n    result = call_fixture_func(fixturefunc, request, kwargs)\n  File \"D:\\PythonCode\\apiAutoTest\\lib\\site-packages\\_pytest\\fixtures.py\", line 915, in call_fixture_func\n    fixture_result = next(generator)\n  File \"F:\\CODE\\python-test\\apiAutoTest\\test\\conftest.py\", line 24, in data_clearing\n    DataClearing.backup_mysql()\n  File \"F:\\CODE\\python-test\\apiAutoTest\\tools\\data_clearing.py\", line 119, in backup_mysql\n    cls.server.files_action(0,\n  File \"F:\\CODE\\python-test\\apiAutoTest\\tools\\data_clearing.py\", line 77, in files_action\n    self.ftp_client.get(remotepath=remote_path, localpath=file_path)\n  File \"D:\\PythonCode\\apiAutoTest\\lib\\site-packages\\paramiko\\sftp_client.py\", line 801, in get\n    with open(localpath, \"wb\") as fl:\n",
    "steps" : [ ],
    "attachments" : [ ],
    "parameters" : [ ],
    "hasContent" : true,
    "stepsCount" : 0,
    "attachmentsCount" : 0,
    "shouldDisplayMessage" : true
  }, {
    "name" : "data_clearing",
    "time" : {
      "start" : 1641450254426,
      "stop" : 1641450255863,
      "duration" : 1437
    },
    "status" : "broken",
    "statusMessage" : "FileNotFoundError: [Errno 2] No such file or directory: '/home/chenlei/backup_sqls/apiautotest_2022-01-06T14_21_46.sql'\n",
    "statusTrace" : "  File \"D:\\PythonCode\\apiAutoTest\\lib\\site-packages\\pluggy\\callers.py\", line 187, in _multicall\n    res = hook_impl.function(*args)\n  File \"D:\\PythonCode\\apiAutoTest\\lib\\site-packages\\_pytest\\fixtures.py\", line 1117, in pytest_fixture_setup\n    result = call_fixture_func(fixturefunc, request, kwargs)\n  File \"D:\\PythonCode\\apiAutoTest\\lib\\site-packages\\_pytest\\fixtures.py\", line 915, in call_fixture_func\n    fixture_result = next(generator)\n  File \"F:\\CODE\\python-test\\apiAutoTest\\test\\conftest.py\", line 24, in data_clearing\n    DataClearing.backup_mysql()\n  File \"F:\\CODE\\python-test\\apiAutoTest\\tools\\data_clearing.py\", line 119, in backup_mysql\n    cls.server.files_action(0,\n  File \"F:\\CODE\\python-test\\apiAutoTest\\tools\\data_clearing.py\", line 77, in files_action\n    self.ftp_client.get(remotepath=remote_path, localpath=file_path)\n  File \"D:\\PythonCode\\apiAutoTest\\lib\\site-packages\\paramiko\\sftp_client.py\", line 801, in get\n    with open(localpath, \"wb\") as fl:\n",
    "steps" : [ ],
    "attachments" : [ ],
    "parameters" : [ ],
    "hasContent" : true,
    "stepsCount" : 0,
    "attachmentsCount" : 0,
    "shouldDisplayMessage" : true
  }, {
    "name" : "data_clearing",
    "time" : {
      "start" : 1641450256907,
      "stop" : 1641450258050,
      "duration" : 1143
    },
    "status" : "broken",
    "statusMessage" : "FileNotFoundError: [Errno 2] No such file or directory: '/home/chenlei/backup_sqls/apiautotest_2022-01-06T14_21_46.sql'\n",
    "statusTrace" : "  File \"D:\\PythonCode\\apiAutoTest\\lib\\site-packages\\pluggy\\callers.py\", line 187, in _multicall\n    res = hook_impl.function(*args)\n  File \"D:\\PythonCode\\apiAutoTest\\lib\\site-packages\\_pytest\\fixtures.py\", line 1117, in pytest_fixture_setup\n    result = call_fixture_func(fixturefunc, request, kwargs)\n  File \"D:\\PythonCode\\apiAutoTest\\lib\\site-packages\\_pytest\\fixtures.py\", line 915, in call_fixture_func\n    fixture_result = next(generator)\n  File \"F:\\CODE\\python-test\\apiAutoTest\\test\\conftest.py\", line 24, in data_clearing\n    DataClearing.backup_mysql()\n  File \"F:\\CODE\\python-test\\apiAutoTest\\tools\\data_clearing.py\", line 119, in backup_mysql\n    cls.server.files_action(0,\n  File \"F:\\CODE\\python-test\\apiAutoTest\\tools\\data_clearing.py\", line 77, in files_action\n    self.ftp_client.get(remotepath=remote_path, localpath=file_path)\n  File \"D:\\PythonCode\\apiAutoTest\\lib\\site-packages\\paramiko\\sftp_client.py\", line 801, in get\n    with open(localpath, \"wb\") as fl:\n",
    "steps" : [ ],
    "attachments" : [ ],
    "parameters" : [ ],
    "hasContent" : true,
    "stepsCount" : 0,
    "attachmentsCount" : 0,
    "shouldDisplayMessage" : true
  }, {
    "name" : "data_clearing",
    "time" : {
      "start" : 1641450259074,
      "stop" : 1641450260399,
      "duration" : 1325
    },
    "status" : "broken",
    "statusMessage" : "FileNotFoundError: [Errno 2] No such file or directory: '/home/chenlei/backup_sqls/apiautotest_2022-01-06T14_21_46.sql'\n",
    "statusTrace" : "  File \"D:\\PythonCode\\apiAutoTest\\lib\\site-packages\\pluggy\\callers.py\", line 187, in _multicall\n    res = hook_impl.function(*args)\n  File \"D:\\PythonCode\\apiAutoTest\\lib\\site-packages\\_pytest\\fixtures.py\", line 1117, in pytest_fixture_setup\n    result = call_fixture_func(fixturefunc, request, kwargs)\n  File \"D:\\PythonCode\\apiAutoTest\\lib\\site-packages\\_pytest\\fixtures.py\", line 915, in call_fixture_func\n    fixture_result = next(generator)\n  File \"F:\\CODE\\python-test\\apiAutoTest\\test\\conftest.py\", line 24, in data_clearing\n    DataClearing.backup_mysql()\n  File \"F:\\CODE\\python-test\\apiAutoTest\\tools\\data_clearing.py\", line 119, in backup_mysql\n    cls.server.files_action(0,\n  File \"F:\\CODE\\python-test\\apiAutoTest\\tools\\data_clearing.py\", line 77, in files_action\n    self.ftp_client.get(remotepath=remote_path, localpath=file_path)\n  File \"D:\\PythonCode\\apiAutoTest\\lib\\site-packages\\paramiko\\sftp_client.py\", line 801, in get\n    with open(localpath, \"wb\") as fl:\n",
    "steps" : [ ],
    "attachments" : [ ],
    "parameters" : [ ],
    "hasContent" : true,
    "stepsCount" : 0,
    "attachmentsCount" : 0,
    "shouldDisplayMessage" : true
  }, {
    "name" : "data_clearing",
    "time" : {
      "start" : 1641450261456,
      "stop" : 1641450262441,
      "duration" : 985
    },
    "status" : "broken",
    "statusMessage" : "FileNotFoundError: [Errno 2] No such file or directory: '/home/chenlei/backup_sqls/apiautotest_2022-01-06T14_21_46.sql'\n",
    "statusTrace" : "  File \"D:\\PythonCode\\apiAutoTest\\lib\\site-packages\\pluggy\\callers.py\", line 187, in _multicall\n    res = hook_impl.function(*args)\n  File \"D:\\PythonCode\\apiAutoTest\\lib\\site-packages\\_pytest\\fixtures.py\", line 1117, in pytest_fixture_setup\n    result = call_fixture_func(fixturefunc, request, kwargs)\n  File \"D:\\PythonCode\\apiAutoTest\\lib\\site-packages\\_pytest\\fixtures.py\", line 915, in call_fixture_func\n    fixture_result = next(generator)\n  File \"F:\\CODE\\python-test\\apiAutoTest\\test\\conftest.py\", line 24, in data_clearing\n    DataClearing.backup_mysql()\n  File \"F:\\CODE\\python-test\\apiAutoTest\\tools\\data_clearing.py\", line 119, in backup_mysql\n    cls.server.files_action(0,\n  File \"F:\\CODE\\python-test\\apiAutoTest\\tools\\data_clearing.py\", line 77, in files_action\n    self.ftp_client.get(remotepath=remote_path, localpath=file_path)\n  File \"D:\\PythonCode\\apiAutoTest\\lib\\site-packages\\paramiko\\sftp_client.py\", line 801, in get\n    with open(localpath, \"wb\") as fl:\n",
    "steps" : [ ],
    "attachments" : [ ],
    "parameters" : [ ],
    "hasContent" : true,
    "stepsCount" : 0,
    "attachmentsCount" : 0,
    "shouldDisplayMessage" : true
  }, {
    "name" : "data_clearing",
    "time" : {
      "start" : 1641450263470,
      "stop" : 1641450264778,
      "duration" : 1308
    },
    "status" : "broken",
    "statusMessage" : "FileNotFoundError: [Errno 2] No such file or directory: '/home/chenlei/backup_sqls/apiautotest_2022-01-06T14_21_46.sql'\n",
    "statusTrace" : "  File \"D:\\PythonCode\\apiAutoTest\\lib\\site-packages\\pluggy\\callers.py\", line 187, in _multicall\n    res = hook_impl.function(*args)\n  File \"D:\\PythonCode\\apiAutoTest\\lib\\site-packages\\_pytest\\fixtures.py\", line 1117, in pytest_fixture_setup\n    result = call_fixture_func(fixturefunc, request, kwargs)\n  File \"D:\\PythonCode\\apiAutoTest\\lib\\site-packages\\_pytest\\fixtures.py\", line 915, in call_fixture_func\n    fixture_result = next(generator)\n  File \"F:\\CODE\\python-test\\apiAutoTest\\test\\conftest.py\", line 24, in data_clearing\n    DataClearing.backup_mysql()\n  File \"F:\\CODE\\python-test\\apiAutoTest\\tools\\data_clearing.py\", line 119, in backup_mysql\n    cls.server.files_action(0,\n  File \"F:\\CODE\\python-test\\apiAutoTest\\tools\\data_clearing.py\", line 77, in files_action\n    self.ftp_client.get(remotepath=remote_path, localpath=file_path)\n  File \"D:\\PythonCode\\apiAutoTest\\lib\\site-packages\\paramiko\\sftp_client.py\", line 801, in get\n    with open(localpath, \"wb\") as fl:\n",
    "steps" : [ ],
    "attachments" : [ ],
    "parameters" : [ ],
    "hasContent" : true,
    "stepsCount" : 0,
    "attachmentsCount" : 0,
    "shouldDisplayMessage" : true
  }, {
    "name" : "data_clearing",
    "time" : {
      "start" : 1641450265821,
      "stop" : 1641450266945,
      "duration" : 1124
    },
    "status" : "broken",
    "statusMessage" : "FileNotFoundError: [Errno 2] No such file or directory: '/home/chenlei/backup_sqls/apiautotest_2022-01-06T14_21_46.sql'\n",
    "statusTrace" : "  File \"D:\\PythonCode\\apiAutoTest\\lib\\site-packages\\pluggy\\callers.py\", line 187, in _multicall\n    res = hook_impl.function(*args)\n  File \"D:\\PythonCode\\apiAutoTest\\lib\\site-packages\\_pytest\\fixtures.py\", line 1117, in pytest_fixture_setup\n    result = call_fixture_func(fixturefunc, request, kwargs)\n  File \"D:\\PythonCode\\apiAutoTest\\lib\\site-packages\\_pytest\\fixtures.py\", line 915, in call_fixture_func\n    fixture_result = next(generator)\n  File \"F:\\CODE\\python-test\\apiAutoTest\\test\\conftest.py\", line 24, in data_clearing\n    DataClearing.backup_mysql()\n  File \"F:\\CODE\\python-test\\apiAutoTest\\tools\\data_clearing.py\", line 119, in backup_mysql\n    cls.server.files_action(0,\n  File \"F:\\CODE\\python-test\\apiAutoTest\\tools\\data_clearing.py\", line 77, in files_action\n    self.ftp_client.get(remotepath=remote_path, localpath=file_path)\n  File \"D:\\PythonCode\\apiAutoTest\\lib\\site-packages\\paramiko\\sftp_client.py\", line 801, in get\n    with open(localpath, \"wb\") as fl:\n",
    "steps" : [ ],
    "attachments" : [ ],
    "parameters" : [ ],
    "hasContent" : true,
    "stepsCount" : 0,
    "attachmentsCount" : 0,
    "shouldDisplayMessage" : true
  }, {
    "name" : "data_clearing",
    "time" : {
      "start" : 1641450267975,
      "stop" : 1641450269166,
      "duration" : 1191
    },
    "status" : "broken",
    "statusMessage" : "FileNotFoundError: [Errno 2] No such file or directory: '/home/chenlei/backup_sqls/apiautotest_2022-01-06T14_21_46.sql'\n",
    "statusTrace" : "  File \"D:\\PythonCode\\apiAutoTest\\lib\\site-packages\\pluggy\\callers.py\", line 187, in _multicall\n    res = hook_impl.function(*args)\n  File \"D:\\PythonCode\\apiAutoTest\\lib\\site-packages\\_pytest\\fixtures.py\", line 1117, in pytest_fixture_setup\n    result = call_fixture_func(fixturefunc, request, kwargs)\n  File \"D:\\PythonCode\\apiAutoTest\\lib\\site-packages\\_pytest\\fixtures.py\", line 915, in call_fixture_func\n    fixture_result = next(generator)\n  File \"F:\\CODE\\python-test\\apiAutoTest\\test\\conftest.py\", line 24, in data_clearing\n    DataClearing.backup_mysql()\n  File \"F:\\CODE\\python-test\\apiAutoTest\\tools\\data_clearing.py\", line 119, in backup_mysql\n    cls.server.files_action(0,\n  File \"F:\\CODE\\python-test\\apiAutoTest\\tools\\data_clearing.py\", line 77, in files_action\n    self.ftp_client.get(remotepath=remote_path, localpath=file_path)\n  File \"D:\\PythonCode\\apiAutoTest\\lib\\site-packages\\paramiko\\sftp_client.py\", line 801, in get\n    with open(localpath, \"wb\") as fl:\n",
    "steps" : [ ],
    "attachments" : [ ],
    "parameters" : [ ],
    "hasContent" : true,
    "stepsCount" : 0,
    "attachmentsCount" : 0,
    "shouldDisplayMessage" : true
  }, {
    "name" : "data_clearing",
    "time" : {
      "start" : 1641450270200,
      "stop" : 1641450271256,
      "duration" : 1056
    },
    "status" : "broken",
    "statusMessage" : "FileNotFoundError: [Errno 2] No such file or directory: '/home/chenlei/backup_sqls/apiautotest_2022-01-06T14_21_46.sql'\n",
    "statusTrace" : "  File \"D:\\PythonCode\\apiAutoTest\\lib\\site-packages\\pluggy\\callers.py\", line 187, in _multicall\n    res = hook_impl.function(*args)\n  File \"D:\\PythonCode\\apiAutoTest\\lib\\site-packages\\_pytest\\fixtures.py\", line 1117, in pytest_fixture_setup\n    result = call_fixture_func(fixturefunc, request, kwargs)\n  File \"D:\\PythonCode\\apiAutoTest\\lib\\site-packages\\_pytest\\fixtures.py\", line 915, in call_fixture_func\n    fixture_result = next(generator)\n  File \"F:\\CODE\\python-test\\apiAutoTest\\test\\conftest.py\", line 24, in data_clearing\n    DataClearing.backup_mysql()\n  File \"F:\\CODE\\python-test\\apiAutoTest\\tools\\data_clearing.py\", line 119, in backup_mysql\n    cls.server.files_action(0,\n  File \"F:\\CODE\\python-test\\apiAutoTest\\tools\\data_clearing.py\", line 77, in files_action\n    self.ftp_client.get(remotepath=remote_path, localpath=file_path)\n  File \"D:\\PythonCode\\apiAutoTest\\lib\\site-packages\\paramiko\\sftp_client.py\", line 801, in get\n    with open(localpath, \"wb\") as fl:\n",
    "steps" : [ ],
    "attachments" : [ ],
    "parameters" : [ ],
    "hasContent" : true,
    "stepsCount" : 0,
    "attachmentsCount" : 0,
    "shouldDisplayMessage" : true
  }, {
    "name" : "data_clearing",
    "time" : {
      "start" : 1641450272277,
      "stop" : 1641450273535,
      "duration" : 1258
    },
    "status" : "broken",
    "statusMessage" : "FileNotFoundError: [Errno 2] No such file or directory: '/home/chenlei/backup_sqls/apiautotest_2022-01-06T14_21_46.sql'\n",
    "statusTrace" : "  File \"D:\\PythonCode\\apiAutoTest\\lib\\site-packages\\pluggy\\callers.py\", line 187, in _multicall\n    res = hook_impl.function(*args)\n  File \"D:\\PythonCode\\apiAutoTest\\lib\\site-packages\\_pytest\\fixtures.py\", line 1117, in pytest_fixture_setup\n    result = call_fixture_func(fixturefunc, request, kwargs)\n  File \"D:\\PythonCode\\apiAutoTest\\lib\\site-packages\\_pytest\\fixtures.py\", line 915, in call_fixture_func\n    fixture_result = next(generator)\n  File \"F:\\CODE\\python-test\\apiAutoTest\\test\\conftest.py\", line 24, in data_clearing\n    DataClearing.backup_mysql()\n  File \"F:\\CODE\\python-test\\apiAutoTest\\tools\\data_clearing.py\", line 119, in backup_mysql\n    cls.server.files_action(0,\n  File \"F:\\CODE\\python-test\\apiAutoTest\\tools\\data_clearing.py\", line 77, in files_action\n    self.ftp_client.get(remotepath=remote_path, localpath=file_path)\n  File \"D:\\PythonCode\\apiAutoTest\\lib\\site-packages\\paramiko\\sftp_client.py\", line 801, in get\n    with open(localpath, \"wb\") as fl:\n",
    "steps" : [ ],
    "attachments" : [ ],
    "parameters" : [ ],
    "hasContent" : true,
    "stepsCount" : 0,
    "attachmentsCount" : 0,
    "shouldDisplayMessage" : true
  }, {
    "name" : "data_clearing",
    "time" : {
      "start" : 1641450274580,
      "stop" : 1641450275858,
      "duration" : 1278
    },
    "status" : "broken",
    "statusMessage" : "FileNotFoundError: [Errno 2] No such file or directory: '/home/chenlei/backup_sqls/apiautotest_2022-01-06T14_21_46.sql'\n",
    "statusTrace" : "  File \"D:\\PythonCode\\apiAutoTest\\lib\\site-packages\\pluggy\\callers.py\", line 187, in _multicall\n    res = hook_impl.function(*args)\n  File \"D:\\PythonCode\\apiAutoTest\\lib\\site-packages\\_pytest\\fixtures.py\", line 1117, in pytest_fixture_setup\n    result = call_fixture_func(fixturefunc, request, kwargs)\n  File \"D:\\PythonCode\\apiAutoTest\\lib\\site-packages\\_pytest\\fixtures.py\", line 915, in call_fixture_func\n    fixture_result = next(generator)\n  File \"F:\\CODE\\python-test\\apiAutoTest\\test\\conftest.py\", line 24, in data_clearing\n    DataClearing.backup_mysql()\n  File \"F:\\CODE\\python-test\\apiAutoTest\\tools\\data_clearing.py\", line 119, in backup_mysql\n    cls.server.files_action(0,\n  File \"F:\\CODE\\python-test\\apiAutoTest\\tools\\data_clearing.py\", line 77, in files_action\n    self.ftp_client.get(remotepath=remote_path, localpath=file_path)\n  File \"D:\\PythonCode\\apiAutoTest\\lib\\site-packages\\paramiko\\sftp_client.py\", line 801, in get\n    with open(localpath, \"wb\") as fl:\n",
    "steps" : [ ],
    "attachments" : [ ],
    "parameters" : [ ],
    "hasContent" : true,
    "stepsCount" : 0,
    "attachmentsCount" : 0,
    "shouldDisplayMessage" : true
  }, {
    "name" : "data_clearing",
    "time" : {
      "start" : 1641450276884,
      "stop" : 1641450278320,
      "duration" : 1436
    },
    "status" : "broken",
    "statusMessage" : "FileNotFoundError: [Errno 2] No such file or directory: '/home/chenlei/backup_sqls/apiautotest_2022-01-06T14_21_46.sql'\n",
    "statusTrace" : "  File \"D:\\PythonCode\\apiAutoTest\\lib\\site-packages\\pluggy\\callers.py\", line 187, in _multicall\n    res = hook_impl.function(*args)\n  File \"D:\\PythonCode\\apiAutoTest\\lib\\site-packages\\_pytest\\fixtures.py\", line 1117, in pytest_fixture_setup\n    result = call_fixture_func(fixturefunc, request, kwargs)\n  File \"D:\\PythonCode\\apiAutoTest\\lib\\site-packages\\_pytest\\fixtures.py\", line 915, in call_fixture_func\n    fixture_result = next(generator)\n  File \"F:\\CODE\\python-test\\apiAutoTest\\test\\conftest.py\", line 24, in data_clearing\n    DataClearing.backup_mysql()\n  File \"F:\\CODE\\python-test\\apiAutoTest\\tools\\data_clearing.py\", line 119, in backup_mysql\n    cls.server.files_action(0,\n  File \"F:\\CODE\\python-test\\apiAutoTest\\tools\\data_clearing.py\", line 77, in files_action\n    self.ftp_client.get(remotepath=remote_path, localpath=file_path)\n  File \"D:\\PythonCode\\apiAutoTest\\lib\\site-packages\\paramiko\\sftp_client.py\", line 801, in get\n    with open(localpath, \"wb\") as fl:\n",
    "steps" : [ ],
    "attachments" : [ ],
    "parameters" : [ ],
    "hasContent" : true,
    "stepsCount" : 0,
    "attachmentsCount" : 0,
    "shouldDisplayMessage" : true
  }, {
    "name" : "data_clearing",
    "time" : {
      "start" : 1641450279364,
      "stop" : 1641450280453,
      "duration" : 1089
    },
    "status" : "broken",
    "statusMessage" : "FileNotFoundError: [Errno 2] No such file or directory: '/home/chenlei/backup_sqls/apiautotest_2022-01-06T14_21_46.sql'\n",
    "statusTrace" : "  File \"D:\\PythonCode\\apiAutoTest\\lib\\site-packages\\pluggy\\callers.py\", line 187, in _multicall\n    res = hook_impl.function(*args)\n  File \"D:\\PythonCode\\apiAutoTest\\lib\\site-packages\\_pytest\\fixtures.py\", line 1117, in pytest_fixture_setup\n    result = call_fixture_func(fixturefunc, request, kwargs)\n  File \"D:\\PythonCode\\apiAutoTest\\lib\\site-packages\\_pytest\\fixtures.py\", line 915, in call_fixture_func\n    fixture_result = next(generator)\n  File \"F:\\CODE\\python-test\\apiAutoTest\\test\\conftest.py\", line 24, in data_clearing\n    DataClearing.backup_mysql()\n  File \"F:\\CODE\\python-test\\apiAutoTest\\tools\\data_clearing.py\", line 119, in backup_mysql\n    cls.server.files_action(0,\n  File \"F:\\CODE\\python-test\\apiAutoTest\\tools\\data_clearing.py\", line 77, in files_action\n    self.ftp_client.get(remotepath=remote_path, localpath=file_path)\n  File \"D:\\PythonCode\\apiAutoTest\\lib\\site-packages\\paramiko\\sftp_client.py\", line 801, in get\n    with open(localpath, \"wb\") as fl:\n",
    "steps" : [ ],
    "attachments" : [ ],
    "parameters" : [ ],
    "hasContent" : true,
    "stepsCount" : 0,
    "attachmentsCount" : 0,
    "shouldDisplayMessage" : true
  }, {
    "name" : "data_clearing",
    "time" : {
      "start" : 1641450281484,
      "stop" : 1641450282842,
      "duration" : 1358
    },
    "status" : "broken",
    "statusMessage" : "FileNotFoundError: [Errno 2] No such file or directory: '/home/chenlei/backup_sqls/apiautotest_2022-01-06T14_21_46.sql'\n",
    "statusTrace" : "  File \"D:\\PythonCode\\apiAutoTest\\lib\\site-packages\\pluggy\\callers.py\", line 187, in _multicall\n    res = hook_impl.function(*args)\n  File \"D:\\PythonCode\\apiAutoTest\\lib\\site-packages\\_pytest\\fixtures.py\", line 1117, in pytest_fixture_setup\n    result = call_fixture_func(fixturefunc, request, kwargs)\n  File \"D:\\PythonCode\\apiAutoTest\\lib\\site-packages\\_pytest\\fixtures.py\", line 915, in call_fixture_func\n    fixture_result = next(generator)\n  File \"F:\\CODE\\python-test\\apiAutoTest\\test\\conftest.py\", line 24, in data_clearing\n    DataClearing.backup_mysql()\n  File \"F:\\CODE\\python-test\\apiAutoTest\\tools\\data_clearing.py\", line 119, in backup_mysql\n    cls.server.files_action(0,\n  File \"F:\\CODE\\python-test\\apiAutoTest\\tools\\data_clearing.py\", line 77, in files_action\n    self.ftp_client.get(remotepath=remote_path, localpath=file_path)\n  File \"D:\\PythonCode\\apiAutoTest\\lib\\site-packages\\paramiko\\sftp_client.py\", line 801, in get\n    with open(localpath, \"wb\") as fl:\n",
    "steps" : [ ],
    "attachments" : [ ],
    "parameters" : [ ],
    "hasContent" : true,
    "stepsCount" : 0,
    "attachmentsCount" : 0,
    "shouldDisplayMessage" : true
  }, {
    "name" : "data_clearing",
    "time" : {
      "start" : 1641450283894,
      "stop" : 1641450285347,
      "duration" : 1453
    },
    "status" : "broken",
    "statusMessage" : "FileNotFoundError: [Errno 2] No such file or directory: '/home/chenlei/backup_sqls/apiautotest_2022-01-06T14_21_46.sql'\n",
    "statusTrace" : "  File \"D:\\PythonCode\\apiAutoTest\\lib\\site-packages\\pluggy\\callers.py\", line 187, in _multicall\n    res = hook_impl.function(*args)\n  File \"D:\\PythonCode\\apiAutoTest\\lib\\site-packages\\_pytest\\fixtures.py\", line 1117, in pytest_fixture_setup\n    result = call_fixture_func(fixturefunc, request, kwargs)\n  File \"D:\\PythonCode\\apiAutoTest\\lib\\site-packages\\_pytest\\fixtures.py\", line 915, in call_fixture_func\n    fixture_result = next(generator)\n  File \"F:\\CODE\\python-test\\apiAutoTest\\test\\conftest.py\", line 24, in data_clearing\n    DataClearing.backup_mysql()\n  File \"F:\\CODE\\python-test\\apiAutoTest\\tools\\data_clearing.py\", line 119, in backup_mysql\n    cls.server.files_action(0,\n  File \"F:\\CODE\\python-test\\apiAutoTest\\tools\\data_clearing.py\", line 77, in files_action\n    self.ftp_client.get(remotepath=remote_path, localpath=file_path)\n  File \"D:\\PythonCode\\apiAutoTest\\lib\\site-packages\\paramiko\\sftp_client.py\", line 801, in get\n    with open(localpath, \"wb\") as fl:\n",
    "steps" : [ ],
    "attachments" : [ ],
    "parameters" : [ ],
    "hasContent" : true,
    "stepsCount" : 0,
    "attachmentsCount" : 0,
    "shouldDisplayMessage" : true
  }, {
    "name" : "data_clearing",
    "time" : {
      "start" : 1641450286376,
      "stop" : 1641450287482,
      "duration" : 1106
    },
    "status" : "broken",
    "statusMessage" : "FileNotFoundError: [Errno 2] No such file or directory: '/home/chenlei/backup_sqls/apiautotest_2022-01-06T14_21_46.sql'\n",
    "statusTrace" : "  File \"D:\\PythonCode\\apiAutoTest\\lib\\site-packages\\pluggy\\callers.py\", line 187, in _multicall\n    res = hook_impl.function(*args)\n  File \"D:\\PythonCode\\apiAutoTest\\lib\\site-packages\\_pytest\\fixtures.py\", line 1117, in pytest_fixture_setup\n    result = call_fixture_func(fixturefunc, request, kwargs)\n  File \"D:\\PythonCode\\apiAutoTest\\lib\\site-packages\\_pytest\\fixtures.py\", line 915, in call_fixture_func\n    fixture_result = next(generator)\n  File \"F:\\CODE\\python-test\\apiAutoTest\\test\\conftest.py\", line 24, in data_clearing\n    DataClearing.backup_mysql()\n  File \"F:\\CODE\\python-test\\apiAutoTest\\tools\\data_clearing.py\", line 119, in backup_mysql\n    cls.server.files_action(0,\n  File \"F:\\CODE\\python-test\\apiAutoTest\\tools\\data_clearing.py\", line 77, in files_action\n    self.ftp_client.get(remotepath=remote_path, localpath=file_path)\n  File \"D:\\PythonCode\\apiAutoTest\\lib\\site-packages\\paramiko\\sftp_client.py\", line 801, in get\n    with open(localpath, \"wb\") as fl:\n",
    "steps" : [ ],
    "attachments" : [ ],
    "parameters" : [ ],
    "hasContent" : true,
    "stepsCount" : 0,
    "attachmentsCount" : 0,
    "shouldDisplayMessage" : true
  }, {
    "name" : "data_clearing",
    "time" : {
      "start" : 1641450288527,
      "stop" : 1641450289991,
      "duration" : 1464
    },
    "status" : "broken",
    "statusMessage" : "FileNotFoundError: [Errno 2] No such file or directory: '/home/chenlei/backup_sqls/apiautotest_2022-01-06T14_21_46.sql'\n",
    "statusTrace" : "  File \"D:\\PythonCode\\apiAutoTest\\lib\\site-packages\\pluggy\\callers.py\", line 187, in _multicall\n    res = hook_impl.function(*args)\n  File \"D:\\PythonCode\\apiAutoTest\\lib\\site-packages\\_pytest\\fixtures.py\", line 1117, in pytest_fixture_setup\n    result = call_fixture_func(fixturefunc, request, kwargs)\n  File \"D:\\PythonCode\\apiAutoTest\\lib\\site-packages\\_pytest\\fixtures.py\", line 915, in call_fixture_func\n    fixture_result = next(generator)\n  File \"F:\\CODE\\python-test\\apiAutoTest\\test\\conftest.py\", line 24, in data_clearing\n    DataClearing.backup_mysql()\n  File \"F:\\CODE\\python-test\\apiAutoTest\\tools\\data_clearing.py\", line 119, in backup_mysql\n    cls.server.files_action(0,\n  File \"F:\\CODE\\python-test\\apiAutoTest\\tools\\data_clearing.py\", line 77, in files_action\n    self.ftp_client.get(remotepath=remote_path, localpath=file_path)\n  File \"D:\\PythonCode\\apiAutoTest\\lib\\site-packages\\paramiko\\sftp_client.py\", line 801, in get\n    with open(localpath, \"wb\") as fl:\n",
    "steps" : [ ],
    "attachments" : [ ],
    "parameters" : [ ],
    "hasContent" : true,
    "stepsCount" : 0,
    "attachmentsCount" : 0,
    "shouldDisplayMessage" : true
  }, {
    "name" : "data_clearing",
    "time" : {
      "start" : 1641450291014,
      "stop" : 1641450292744,
      "duration" : 1730
    },
    "status" : "broken",
    "statusMessage" : "FileNotFoundError: [Errno 2] No such file or directory: '/home/chenlei/backup_sqls/apiautotest_2022-01-06T14_21_46.sql'\n",
    "statusTrace" : "  File \"D:\\PythonCode\\apiAutoTest\\lib\\site-packages\\pluggy\\callers.py\", line 187, in _multicall\n    res = hook_impl.function(*args)\n  File \"D:\\PythonCode\\apiAutoTest\\lib\\site-packages\\_pytest\\fixtures.py\", line 1117, in pytest_fixture_setup\n    result = call_fixture_func(fixturefunc, request, kwargs)\n  File \"D:\\PythonCode\\apiAutoTest\\lib\\site-packages\\_pytest\\fixtures.py\", line 915, in call_fixture_func\n    fixture_result = next(generator)\n  File \"F:\\CODE\\python-test\\apiAutoTest\\test\\conftest.py\", line 24, in data_clearing\n    DataClearing.backup_mysql()\n  File \"F:\\CODE\\python-test\\apiAutoTest\\tools\\data_clearing.py\", line 119, in backup_mysql\n    cls.server.files_action(0,\n  File \"F:\\CODE\\python-test\\apiAutoTest\\tools\\data_clearing.py\", line 77, in files_action\n    self.ftp_client.get(remotepath=remote_path, localpath=file_path)\n  File \"D:\\PythonCode\\apiAutoTest\\lib\\site-packages\\paramiko\\sftp_client.py\", line 801, in get\n    with open(localpath, \"wb\") as fl:\n",
    "steps" : [ ],
    "attachments" : [ ],
    "parameters" : [ ],
    "hasContent" : true,
    "stepsCount" : 0,
    "attachmentsCount" : 0,
    "shouldDisplayMessage" : true
  }, {
    "name" : "data_clearing",
    "time" : {
      "start" : 1641450293778,
      "stop" : 1641450294888,
      "duration" : 1110
    },
    "status" : "broken",
    "statusMessage" : "FileNotFoundError: [Errno 2] No such file or directory: '/home/chenlei/backup_sqls/apiautotest_2022-01-06T14_21_46.sql'\n",
    "statusTrace" : "  File \"D:\\PythonCode\\apiAutoTest\\lib\\site-packages\\pluggy\\callers.py\", line 187, in _multicall\n    res = hook_impl.function(*args)\n  File \"D:\\PythonCode\\apiAutoTest\\lib\\site-packages\\_pytest\\fixtures.py\", line 1117, in pytest_fixture_setup\n    result = call_fixture_func(fixturefunc, request, kwargs)\n  File \"D:\\PythonCode\\apiAutoTest\\lib\\site-packages\\_pytest\\fixtures.py\", line 915, in call_fixture_func\n    fixture_result = next(generator)\n  File \"F:\\CODE\\python-test\\apiAutoTest\\test\\conftest.py\", line 24, in data_clearing\n    DataClearing.backup_mysql()\n  File \"F:\\CODE\\python-test\\apiAutoTest\\tools\\data_clearing.py\", line 119, in backup_mysql\n    cls.server.files_action(0,\n  File \"F:\\CODE\\python-test\\apiAutoTest\\tools\\data_clearing.py\", line 77, in files_action\n    self.ftp_client.get(remotepath=remote_path, localpath=file_path)\n  File \"D:\\PythonCode\\apiAutoTest\\lib\\site-packages\\paramiko\\sftp_client.py\", line 801, in get\n    with open(localpath, \"wb\") as fl:\n",
    "steps" : [ ],
    "attachments" : [ ],
    "parameters" : [ ],
    "hasContent" : true,
    "stepsCount" : 0,
    "attachmentsCount" : 0,
    "shouldDisplayMessage" : true
  }, {
    "name" : "data_clearing",
    "time" : {
      "start" : 1641450295906,
      "stop" : 1641450297002,
      "duration" : 1096
    },
    "status" : "broken",
    "statusMessage" : "FileNotFoundError: [Errno 2] No such file or directory: '/home/chenlei/backup_sqls/apiautotest_2022-01-06T14_21_46.sql'\n",
    "statusTrace" : "  File \"D:\\PythonCode\\apiAutoTest\\lib\\site-packages\\pluggy\\callers.py\", line 187, in _multicall\n    res = hook_impl.function(*args)\n  File \"D:\\PythonCode\\apiAutoTest\\lib\\site-packages\\_pytest\\fixtures.py\", line 1117, in pytest_fixture_setup\n    result = call_fixture_func(fixturefunc, request, kwargs)\n  File \"D:\\PythonCode\\apiAutoTest\\lib\\site-packages\\_pytest\\fixtures.py\", line 915, in call_fixture_func\n    fixture_result = next(generator)\n  File \"F:\\CODE\\python-test\\apiAutoTest\\test\\conftest.py\", line 24, in data_clearing\n    DataClearing.backup_mysql()\n  File \"F:\\CODE\\python-test\\apiAutoTest\\tools\\data_clearing.py\", line 119, in backup_mysql\n    cls.server.files_action(0,\n  File \"F:\\CODE\\python-test\\apiAutoTest\\tools\\data_clearing.py\", line 77, in files_action\n    self.ftp_client.get(remotepath=remote_path, localpath=file_path)\n  File \"D:\\PythonCode\\apiAutoTest\\lib\\site-packages\\paramiko\\sftp_client.py\", line 801, in get\n    with open(localpath, \"wb\") as fl:\n",
    "steps" : [ ],
    "attachments" : [ ],
    "parameters" : [ ],
    "hasContent" : true,
    "stepsCount" : 0,
    "attachmentsCount" : 0,
    "shouldDisplayMessage" : true
  }, {
    "name" : "data_clearing",
    "time" : {
      "start" : 1641450298041,
      "stop" : 1641450299275,
      "duration" : 1234
    },
    "status" : "broken",
    "statusMessage" : "FileNotFoundError: [Errno 2] No such file or directory: '/home/chenlei/backup_sqls/apiautotest_2022-01-06T14_21_46.sql'\n",
    "statusTrace" : "  File \"D:\\PythonCode\\apiAutoTest\\lib\\site-packages\\pluggy\\callers.py\", line 187, in _multicall\n    res = hook_impl.function(*args)\n  File \"D:\\PythonCode\\apiAutoTest\\lib\\site-packages\\_pytest\\fixtures.py\", line 1117, in pytest_fixture_setup\n    result = call_fixture_func(fixturefunc, request, kwargs)\n  File \"D:\\PythonCode\\apiAutoTest\\lib\\site-packages\\_pytest\\fixtures.py\", line 915, in call_fixture_func\n    fixture_result = next(generator)\n  File \"F:\\CODE\\python-test\\apiAutoTest\\test\\conftest.py\", line 24, in data_clearing\n    DataClearing.backup_mysql()\n  File \"F:\\CODE\\python-test\\apiAutoTest\\tools\\data_clearing.py\", line 119, in backup_mysql\n    cls.server.files_action(0,\n  File \"F:\\CODE\\python-test\\apiAutoTest\\tools\\data_clearing.py\", line 77, in files_action\n    self.ftp_client.get(remotepath=remote_path, localpath=file_path)\n  File \"D:\\PythonCode\\apiAutoTest\\lib\\site-packages\\paramiko\\sftp_client.py\", line 801, in get\n    with open(localpath, \"wb\") as fl:\n",
    "steps" : [ ],
    "attachments" : [ ],
    "parameters" : [ ],
    "hasContent" : true,
    "stepsCount" : 0,
    "attachmentsCount" : 0,
    "shouldDisplayMessage" : true
  }, {
    "name" : "data_clearing",
    "time" : {
      "start" : 1641450300299,
      "stop" : 1641450301394,
      "duration" : 1095
    },
    "status" : "broken",
    "statusMessage" : "FileNotFoundError: [Errno 2] No such file or directory: '/home/chenlei/backup_sqls/apiautotest_2022-01-06T14_21_46.sql'\n",
    "statusTrace" : "  File \"D:\\PythonCode\\apiAutoTest\\lib\\site-packages\\pluggy\\callers.py\", line 187, in _multicall\n    res = hook_impl.function(*args)\n  File \"D:\\PythonCode\\apiAutoTest\\lib\\site-packages\\_pytest\\fixtures.py\", line 1117, in pytest_fixture_setup\n    result = call_fixture_func(fixturefunc, request, kwargs)\n  File \"D:\\PythonCode\\apiAutoTest\\lib\\site-packages\\_pytest\\fixtures.py\", line 915, in call_fixture_func\n    fixture_result = next(generator)\n  File \"F:\\CODE\\python-test\\apiAutoTest\\test\\conftest.py\", line 24, in data_clearing\n    DataClearing.backup_mysql()\n  File \"F:\\CODE\\python-test\\apiAutoTest\\tools\\data_clearing.py\", line 119, in backup_mysql\n    cls.server.files_action(0,\n  File \"F:\\CODE\\python-test\\apiAutoTest\\tools\\data_clearing.py\", line 77, in files_action\n    self.ftp_client.get(remotepath=remote_path, localpath=file_path)\n  File \"D:\\PythonCode\\apiAutoTest\\lib\\site-packages\\paramiko\\sftp_client.py\", line 801, in get\n    with open(localpath, \"wb\") as fl:\n",
    "steps" : [ ],
    "attachments" : [ ],
    "parameters" : [ ],
    "hasContent" : true,
    "stepsCount" : 0,
    "attachmentsCount" : 0,
    "shouldDisplayMessage" : true
  }, {
    "name" : "data_clearing",
    "time" : {
      "start" : 1641450302431,
      "stop" : 1641450303953,
      "duration" : 1522
    },
    "status" : "broken",
    "statusMessage" : "FileNotFoundError: [Errno 2] No such file or directory: '/home/chenlei/backup_sqls/apiautotest_2022-01-06T14_21_46.sql'\n",
    "statusTrace" : "  File \"D:\\PythonCode\\apiAutoTest\\lib\\site-packages\\pluggy\\callers.py\", line 187, in _multicall\n    res = hook_impl.function(*args)\n  File \"D:\\PythonCode\\apiAutoTest\\lib\\site-packages\\_pytest\\fixtures.py\", line 1117, in pytest_fixture_setup\n    result = call_fixture_func(fixturefunc, request, kwargs)\n  File \"D:\\PythonCode\\apiAutoTest\\lib\\site-packages\\_pytest\\fixtures.py\", line 915, in call_fixture_func\n    fixture_result = next(generator)\n  File \"F:\\CODE\\python-test\\apiAutoTest\\test\\conftest.py\", line 24, in data_clearing\n    DataClearing.backup_mysql()\n  File \"F:\\CODE\\python-test\\apiAutoTest\\tools\\data_clearing.py\", line 119, in backup_mysql\n    cls.server.files_action(0,\n  File \"F:\\CODE\\python-test\\apiAutoTest\\tools\\data_clearing.py\", line 77, in files_action\n    self.ftp_client.get(remotepath=remote_path, localpath=file_path)\n  File \"D:\\PythonCode\\apiAutoTest\\lib\\site-packages\\paramiko\\sftp_client.py\", line 801, in get\n    with open(localpath, \"wb\") as fl:\n",
    "steps" : [ ],
    "attachments" : [ ],
    "parameters" : [ ],
    "hasContent" : true,
    "stepsCount" : 0,
    "attachmentsCount" : 0,
    "shouldDisplayMessage" : true
  }, {
    "name" : "data_clearing",
    "time" : {
      "start" : 1641450304979,
      "stop" : 1641450306387,
      "duration" : 1408
    },
    "status" : "broken",
    "statusMessage" : "FileNotFoundError: [Errno 2] No such file or directory: '/home/chenlei/backup_sqls/apiautotest_2022-01-06T14_21_46.sql'\n",
    "statusTrace" : "  File \"D:\\PythonCode\\apiAutoTest\\lib\\site-packages\\pluggy\\callers.py\", line 187, in _multicall\n    res = hook_impl.function(*args)\n  File \"D:\\PythonCode\\apiAutoTest\\lib\\site-packages\\_pytest\\fixtures.py\", line 1117, in pytest_fixture_setup\n    result = call_fixture_func(fixturefunc, request, kwargs)\n  File \"D:\\PythonCode\\apiAutoTest\\lib\\site-packages\\_pytest\\fixtures.py\", line 915, in call_fixture_func\n    fixture_result = next(generator)\n  File \"F:\\CODE\\python-test\\apiAutoTest\\test\\conftest.py\", line 24, in data_clearing\n    DataClearing.backup_mysql()\n  File \"F:\\CODE\\python-test\\apiAutoTest\\tools\\data_clearing.py\", line 119, in backup_mysql\n    cls.server.files_action(0,\n  File \"F:\\CODE\\python-test\\apiAutoTest\\tools\\data_clearing.py\", line 77, in files_action\n    self.ftp_client.get(remotepath=remote_path, localpath=file_path)\n  File \"D:\\PythonCode\\apiAutoTest\\lib\\site-packages\\paramiko\\sftp_client.py\", line 801, in get\n    with open(localpath, \"wb\") as fl:\n",
    "steps" : [ ],
    "attachments" : [ ],
    "parameters" : [ ],
    "hasContent" : true,
    "stepsCount" : 0,
    "attachmentsCount" : 0,
    "shouldDisplayMessage" : true
  }, {
    "name" : "data_clearing",
    "time" : {
      "start" : 1641450307452,
      "stop" : 1641450308455,
      "duration" : 1003
    },
    "status" : "broken",
    "statusMessage" : "FileNotFoundError: [Errno 2] No such file or directory: '/home/chenlei/backup_sqls/apiautotest_2022-01-06T14_21_46.sql'\n",
    "statusTrace" : "  File \"D:\\PythonCode\\apiAutoTest\\lib\\site-packages\\pluggy\\callers.py\", line 187, in _multicall\n    res = hook_impl.function(*args)\n  File \"D:\\PythonCode\\apiAutoTest\\lib\\site-packages\\_pytest\\fixtures.py\", line 1117, in pytest_fixture_setup\n    result = call_fixture_func(fixturefunc, request, kwargs)\n  File \"D:\\PythonCode\\apiAutoTest\\lib\\site-packages\\_pytest\\fixtures.py\", line 915, in call_fixture_func\n    fixture_result = next(generator)\n  File \"F:\\CODE\\python-test\\apiAutoTest\\test\\conftest.py\", line 24, in data_clearing\n    DataClearing.backup_mysql()\n  File \"F:\\CODE\\python-test\\apiAutoTest\\tools\\data_clearing.py\", line 119, in backup_mysql\n    cls.server.files_action(0,\n  File \"F:\\CODE\\python-test\\apiAutoTest\\tools\\data_clearing.py\", line 77, in files_action\n    self.ftp_client.get(remotepath=remote_path, localpath=file_path)\n  File \"D:\\PythonCode\\apiAutoTest\\lib\\site-packages\\paramiko\\sftp_client.py\", line 801, in get\n    with open(localpath, \"wb\") as fl:\n",
    "steps" : [ ],
    "attachments" : [ ],
    "parameters" : [ ],
    "hasContent" : true,
    "stepsCount" : 0,
    "attachmentsCount" : 0,
    "shouldDisplayMessage" : true
  }, {
    "name" : "data_clearing",
    "time" : {
      "start" : 1641450309481,
      "stop" : 1641450310762,
      "duration" : 1281
    },
    "status" : "broken",
    "statusMessage" : "FileNotFoundError: [Errno 2] No such file or directory: '/home/chenlei/backup_sqls/apiautotest_2022-01-06T14_21_46.sql'\n",
    "statusTrace" : "  File \"D:\\PythonCode\\apiAutoTest\\lib\\site-packages\\pluggy\\callers.py\", line 187, in _multicall\n    res = hook_impl.function(*args)\n  File \"D:\\PythonCode\\apiAutoTest\\lib\\site-packages\\_pytest\\fixtures.py\", line 1117, in pytest_fixture_setup\n    result = call_fixture_func(fixturefunc, request, kwargs)\n  File \"D:\\PythonCode\\apiAutoTest\\lib\\site-packages\\_pytest\\fixtures.py\", line 915, in call_fixture_func\n    fixture_result = next(generator)\n  File \"F:\\CODE\\python-test\\apiAutoTest\\test\\conftest.py\", line 24, in data_clearing\n    DataClearing.backup_mysql()\n  File \"F:\\CODE\\python-test\\apiAutoTest\\tools\\data_clearing.py\", line 119, in backup_mysql\n    cls.server.files_action(0,\n  File \"F:\\CODE\\python-test\\apiAutoTest\\tools\\data_clearing.py\", line 77, in files_action\n    self.ftp_client.get(remotepath=remote_path, localpath=file_path)\n  File \"D:\\PythonCode\\apiAutoTest\\lib\\site-packages\\paramiko\\sftp_client.py\", line 801, in get\n    with open(localpath, \"wb\") as fl:\n",
    "steps" : [ ],
    "attachments" : [ ],
    "parameters" : [ ],
    "hasContent" : true,
    "stepsCount" : 0,
    "attachmentsCount" : 0,
    "shouldDisplayMessage" : true
  }, {
    "name" : "data_clearing",
    "time" : {
      "start" : 1641450311799,
      "stop" : 1641450313160,
      "duration" : 1361
    },
    "status" : "broken",
    "statusMessage" : "FileNotFoundError: [Errno 2] No such file or directory: '/home/chenlei/backup_sqls/apiautotest_2022-01-06T14_21_46.sql'\n",
    "statusTrace" : "  File \"D:\\PythonCode\\apiAutoTest\\lib\\site-packages\\pluggy\\callers.py\", line 187, in _multicall\n    res = hook_impl.function(*args)\n  File \"D:\\PythonCode\\apiAutoTest\\lib\\site-packages\\_pytest\\fixtures.py\", line 1117, in pytest_fixture_setup\n    result = call_fixture_func(fixturefunc, request, kwargs)\n  File \"D:\\PythonCode\\apiAutoTest\\lib\\site-packages\\_pytest\\fixtures.py\", line 915, in call_fixture_func\n    fixture_result = next(generator)\n  File \"F:\\CODE\\python-test\\apiAutoTest\\test\\conftest.py\", line 24, in data_clearing\n    DataClearing.backup_mysql()\n  File \"F:\\CODE\\python-test\\apiAutoTest\\tools\\data_clearing.py\", line 119, in backup_mysql\n    cls.server.files_action(0,\n  File \"F:\\CODE\\python-test\\apiAutoTest\\tools\\data_clearing.py\", line 77, in files_action\n    self.ftp_client.get(remotepath=remote_path, localpath=file_path)\n  File \"D:\\PythonCode\\apiAutoTest\\lib\\site-packages\\paramiko\\sftp_client.py\", line 801, in get\n    with open(localpath, \"wb\") as fl:\n",
    "steps" : [ ],
    "attachments" : [ ],
    "parameters" : [ ],
    "hasContent" : true,
    "stepsCount" : 0,
    "attachmentsCount" : 0,
    "shouldDisplayMessage" : true
  }, {
    "name" : "data_clearing",
    "time" : {
      "start" : 1641450314177,
      "stop" : 1641450315378,
      "duration" : 1201
    },
    "status" : "broken",
    "statusMessage" : "FileNotFoundError: [Errno 2] No such file or directory: '/home/chenlei/backup_sqls/apiautotest_2022-01-06T14_21_46.sql'\n",
    "statusTrace" : "  File \"D:\\PythonCode\\apiAutoTest\\lib\\site-packages\\pluggy\\callers.py\", line 187, in _multicall\n    res = hook_impl.function(*args)\n  File \"D:\\PythonCode\\apiAutoTest\\lib\\site-packages\\_pytest\\fixtures.py\", line 1117, in pytest_fixture_setup\n    result = call_fixture_func(fixturefunc, request, kwargs)\n  File \"D:\\PythonCode\\apiAutoTest\\lib\\site-packages\\_pytest\\fixtures.py\", line 915, in call_fixture_func\n    fixture_result = next(generator)\n  File \"F:\\CODE\\python-test\\apiAutoTest\\test\\conftest.py\", line 24, in data_clearing\n    DataClearing.backup_mysql()\n  File \"F:\\CODE\\python-test\\apiAutoTest\\tools\\data_clearing.py\", line 119, in backup_mysql\n    cls.server.files_action(0,\n  File \"F:\\CODE\\python-test\\apiAutoTest\\tools\\data_clearing.py\", line 77, in files_action\n    self.ftp_client.get(remotepath=remote_path, localpath=file_path)\n  File \"D:\\PythonCode\\apiAutoTest\\lib\\site-packages\\paramiko\\sftp_client.py\", line 801, in get\n    with open(localpath, \"wb\") as fl:\n",
    "steps" : [ ],
    "attachments" : [ ],
    "parameters" : [ ],
    "hasContent" : true,
    "stepsCount" : 0,
    "attachmentsCount" : 0,
    "shouldDisplayMessage" : true
  }, {
    "name" : "data_clearing",
    "time" : {
      "start" : 1641450316421,
      "stop" : 1641450317506,
      "duration" : 1085
    },
    "status" : "broken",
    "statusMessage" : "FileNotFoundError: [Errno 2] No such file or directory: '/home/chenlei/backup_sqls/apiautotest_2022-01-06T14_21_46.sql'\n",
    "statusTrace" : "  File \"D:\\PythonCode\\apiAutoTest\\lib\\site-packages\\pluggy\\callers.py\", line 187, in _multicall\n    res = hook_impl.function(*args)\n  File \"D:\\PythonCode\\apiAutoTest\\lib\\site-packages\\_pytest\\fixtures.py\", line 1117, in pytest_fixture_setup\n    result = call_fixture_func(fixturefunc, request, kwargs)\n  File \"D:\\PythonCode\\apiAutoTest\\lib\\site-packages\\_pytest\\fixtures.py\", line 915, in call_fixture_func\n    fixture_result = next(generator)\n  File \"F:\\CODE\\python-test\\apiAutoTest\\test\\conftest.py\", line 24, in data_clearing\n    DataClearing.backup_mysql()\n  File \"F:\\CODE\\python-test\\apiAutoTest\\tools\\data_clearing.py\", line 119, in backup_mysql\n    cls.server.files_action(0,\n  File \"F:\\CODE\\python-test\\apiAutoTest\\tools\\data_clearing.py\", line 77, in files_action\n    self.ftp_client.get(remotepath=remote_path, localpath=file_path)\n  File \"D:\\PythonCode\\apiAutoTest\\lib\\site-packages\\paramiko\\sftp_client.py\", line 801, in get\n    with open(localpath, \"wb\") as fl:\n",
    "steps" : [ ],
    "attachments" : [ ],
    "parameters" : [ ],
    "hasContent" : true,
    "stepsCount" : 0,
    "attachmentsCount" : 0,
    "shouldDisplayMessage" : true
  }, {
    "name" : "data_clearing",
    "time" : {
      "start" : 1641450318527,
      "stop" : 1641450319534,
      "duration" : 1007
    },
    "status" : "broken",
    "statusMessage" : "FileNotFoundError: [Errno 2] No such file or directory: '/home/chenlei/backup_sqls/apiautotest_2022-01-06T14_21_46.sql'\n",
    "statusTrace" : "  File \"D:\\PythonCode\\apiAutoTest\\lib\\site-packages\\pluggy\\callers.py\", line 187, in _multicall\n    res = hook_impl.function(*args)\n  File \"D:\\PythonCode\\apiAutoTest\\lib\\site-packages\\_pytest\\fixtures.py\", line 1117, in pytest_fixture_setup\n    result = call_fixture_func(fixturefunc, request, kwargs)\n  File \"D:\\PythonCode\\apiAutoTest\\lib\\site-packages\\_pytest\\fixtures.py\", line 915, in call_fixture_func\n    fixture_result = next(generator)\n  File \"F:\\CODE\\python-test\\apiAutoTest\\test\\conftest.py\", line 24, in data_clearing\n    DataClearing.backup_mysql()\n  File \"F:\\CODE\\python-test\\apiAutoTest\\tools\\data_clearing.py\", line 119, in backup_mysql\n    cls.server.files_action(0,\n  File \"F:\\CODE\\python-test\\apiAutoTest\\tools\\data_clearing.py\", line 77, in files_action\n    self.ftp_client.get(remotepath=remote_path, localpath=file_path)\n  File \"D:\\PythonCode\\apiAutoTest\\lib\\site-packages\\paramiko\\sftp_client.py\", line 801, in get\n    with open(localpath, \"wb\") as fl:\n",
    "steps" : [ ],
    "attachments" : [ ],
    "parameters" : [ ],
    "hasContent" : true,
    "stepsCount" : 0,
    "attachmentsCount" : 0,
    "shouldDisplayMessage" : true
  }, {
    "name" : "data_clearing",
    "time" : {
      "start" : 1641450320575,
      "stop" : 1641450321987,
      "duration" : 1412
    },
    "status" : "broken",
    "statusMessage" : "FileNotFoundError: [Errno 2] No such file or directory: '/home/chenlei/backup_sqls/apiautotest_2022-01-06T14_21_46.sql'\n",
    "statusTrace" : "  File \"D:\\PythonCode\\apiAutoTest\\lib\\site-packages\\pluggy\\callers.py\", line 187, in _multicall\n    res = hook_impl.function(*args)\n  File \"D:\\PythonCode\\apiAutoTest\\lib\\site-packages\\_pytest\\fixtures.py\", line 1117, in pytest_fixture_setup\n    result = call_fixture_func(fixturefunc, request, kwargs)\n  File \"D:\\PythonCode\\apiAutoTest\\lib\\site-packages\\_pytest\\fixtures.py\", line 915, in call_fixture_func\n    fixture_result = next(generator)\n  File \"F:\\CODE\\python-test\\apiAutoTest\\test\\conftest.py\", line 24, in data_clearing\n    DataClearing.backup_mysql()\n  File \"F:\\CODE\\python-test\\apiAutoTest\\tools\\data_clearing.py\", line 119, in backup_mysql\n    cls.server.files_action(0,\n  File \"F:\\CODE\\python-test\\apiAutoTest\\tools\\data_clearing.py\", line 77, in files_action\n    self.ftp_client.get(remotepath=remote_path, localpath=file_path)\n  File \"D:\\PythonCode\\apiAutoTest\\lib\\site-packages\\paramiko\\sftp_client.py\", line 801, in get\n    with open(localpath, \"wb\") as fl:\n",
    "steps" : [ ],
    "attachments" : [ ],
    "parameters" : [ ],
    "hasContent" : true,
    "stepsCount" : 0,
    "attachmentsCount" : 0,
    "shouldDisplayMessage" : true
  }, {
    "name" : "data_clearing",
    "time" : {
      "start" : 1641450323014,
      "stop" : 1641450324207,
      "duration" : 1193
    },
    "status" : "broken",
    "statusMessage" : "FileNotFoundError: [Errno 2] No such file or directory: '/home/chenlei/backup_sqls/apiautotest_2022-01-06T14_21_46.sql'\n",
    "statusTrace" : "  File \"D:\\PythonCode\\apiAutoTest\\lib\\site-packages\\pluggy\\callers.py\", line 187, in _multicall\n    res = hook_impl.function(*args)\n  File \"D:\\PythonCode\\apiAutoTest\\lib\\site-packages\\_pytest\\fixtures.py\", line 1117, in pytest_fixture_setup\n    result = call_fixture_func(fixturefunc, request, kwargs)\n  File \"D:\\PythonCode\\apiAutoTest\\lib\\site-packages\\_pytest\\fixtures.py\", line 915, in call_fixture_func\n    fixture_result = next(generator)\n  File \"F:\\CODE\\python-test\\apiAutoTest\\test\\conftest.py\", line 24, in data_clearing\n    DataClearing.backup_mysql()\n  File \"F:\\CODE\\python-test\\apiAutoTest\\tools\\data_clearing.py\", line 119, in backup_mysql\n    cls.server.files_action(0,\n  File \"F:\\CODE\\python-test\\apiAutoTest\\tools\\data_clearing.py\", line 77, in files_action\n    self.ftp_client.get(remotepath=remote_path, localpath=file_path)\n  File \"D:\\PythonCode\\apiAutoTest\\lib\\site-packages\\paramiko\\sftp_client.py\", line 801, in get\n    with open(localpath, \"wb\") as fl:\n",
    "steps" : [ ],
    "attachments" : [ ],
    "parameters" : [ ],
    "hasContent" : true,
    "stepsCount" : 0,
    "attachmentsCount" : 0,
    "shouldDisplayMessage" : true
  }, {
    "name" : "data_clearing",
    "time" : {
      "start" : 1641450325245,
      "stop" : 1641450326543,
      "duration" : 1298
    },
    "status" : "broken",
    "statusMessage" : "FileNotFoundError: [Errno 2] No such file or directory: '/home/chenlei/backup_sqls/apiautotest_2022-01-06T14_21_46.sql'\n",
    "statusTrace" : "  File \"D:\\PythonCode\\apiAutoTest\\lib\\site-packages\\pluggy\\callers.py\", line 187, in _multicall\n    res = hook_impl.function(*args)\n  File \"D:\\PythonCode\\apiAutoTest\\lib\\site-packages\\_pytest\\fixtures.py\", line 1117, in pytest_fixture_setup\n    result = call_fixture_func(fixturefunc, request, kwargs)\n  File \"D:\\PythonCode\\apiAutoTest\\lib\\site-packages\\_pytest\\fixtures.py\", line 915, in call_fixture_func\n    fixture_result = next(generator)\n  File \"F:\\CODE\\python-test\\apiAutoTest\\test\\conftest.py\", line 24, in data_clearing\n    DataClearing.backup_mysql()\n  File \"F:\\CODE\\python-test\\apiAutoTest\\tools\\data_clearing.py\", line 119, in backup_mysql\n    cls.server.files_action(0,\n  File \"F:\\CODE\\python-test\\apiAutoTest\\tools\\data_clearing.py\", line 77, in files_action\n    self.ftp_client.get(remotepath=remote_path, localpath=file_path)\n  File \"D:\\PythonCode\\apiAutoTest\\lib\\site-packages\\paramiko\\sftp_client.py\", line 801, in get\n    with open(localpath, \"wb\") as fl:\n",
    "steps" : [ ],
    "attachments" : [ ],
    "parameters" : [ ],
    "hasContent" : true,
    "stepsCount" : 0,
    "attachmentsCount" : 0,
    "shouldDisplayMessage" : true
  }, {
    "name" : "data_clearing",
    "time" : {
      "start" : 1641450327570,
      "stop" : 1641450328687,
      "duration" : 1117
    },
    "status" : "broken",
    "statusMessage" : "FileNotFoundError: [Errno 2] No such file or directory: '/home/chenlei/backup_sqls/apiautotest_2022-01-06T14_21_46.sql'\n",
    "statusTrace" : "  File \"D:\\PythonCode\\apiAutoTest\\lib\\site-packages\\pluggy\\callers.py\", line 187, in _multicall\n    res = hook_impl.function(*args)\n  File \"D:\\PythonCode\\apiAutoTest\\lib\\site-packages\\_pytest\\fixtures.py\", line 1117, in pytest_fixture_setup\n    result = call_fixture_func(fixturefunc, request, kwargs)\n  File \"D:\\PythonCode\\apiAutoTest\\lib\\site-packages\\_pytest\\fixtures.py\", line 915, in call_fixture_func\n    fixture_result = next(generator)\n  File \"F:\\CODE\\python-test\\apiAutoTest\\test\\conftest.py\", line 24, in data_clearing\n    DataClearing.backup_mysql()\n  File \"F:\\CODE\\python-test\\apiAutoTest\\tools\\data_clearing.py\", line 119, in backup_mysql\n    cls.server.files_action(0,\n  File \"F:\\CODE\\python-test\\apiAutoTest\\tools\\data_clearing.py\", line 77, in files_action\n    self.ftp_client.get(remotepath=remote_path, localpath=file_path)\n  File \"D:\\PythonCode\\apiAutoTest\\lib\\site-packages\\paramiko\\sftp_client.py\", line 801, in get\n    with open(localpath, \"wb\") as fl:\n",
    "steps" : [ ],
    "attachments" : [ ],
    "parameters" : [ ],
    "hasContent" : true,
    "stepsCount" : 0,
    "attachmentsCount" : 0,
    "shouldDisplayMessage" : true
  }, {
    "name" : "data_clearing",
    "time" : {
      "start" : 1641450329753,
      "stop" : 1641450331212,
      "duration" : 1459
    },
    "status" : "broken",
    "statusMessage" : "FileNotFoundError: [Errno 2] No such file or directory: '/home/chenlei/backup_sqls/apiautotest_2022-01-06T14_21_46.sql'\n",
    "statusTrace" : "  File \"D:\\PythonCode\\apiAutoTest\\lib\\site-packages\\pluggy\\callers.py\", line 187, in _multicall\n    res = hook_impl.function(*args)\n  File \"D:\\PythonCode\\apiAutoTest\\lib\\site-packages\\_pytest\\fixtures.py\", line 1117, in pytest_fixture_setup\n    result = call_fixture_func(fixturefunc, request, kwargs)\n  File \"D:\\PythonCode\\apiAutoTest\\lib\\site-packages\\_pytest\\fixtures.py\", line 915, in call_fixture_func\n    fixture_result = next(generator)\n  File \"F:\\CODE\\python-test\\apiAutoTest\\test\\conftest.py\", line 24, in data_clearing\n    DataClearing.backup_mysql()\n  File \"F:\\CODE\\python-test\\apiAutoTest\\tools\\data_clearing.py\", line 119, in backup_mysql\n    cls.server.files_action(0,\n  File \"F:\\CODE\\python-test\\apiAutoTest\\tools\\data_clearing.py\", line 77, in files_action\n    self.ftp_client.get(remotepath=remote_path, localpath=file_path)\n  File \"D:\\PythonCode\\apiAutoTest\\lib\\site-packages\\paramiko\\sftp_client.py\", line 801, in get\n    with open(localpath, \"wb\") as fl:\n",
    "steps" : [ ],
    "attachments" : [ ],
    "parameters" : [ ],
    "hasContent" : true,
    "stepsCount" : 0,
    "attachmentsCount" : 0,
    "shouldDisplayMessage" : true
  }, {
    "name" : "data_clearing",
    "time" : {
      "start" : 1641450332230,
      "stop" : 1641450333255,
      "duration" : 1025
    },
    "status" : "broken",
    "statusMessage" : "FileNotFoundError: [Errno 2] No such file or directory: '/home/chenlei/backup_sqls/apiautotest_2022-01-06T14_21_46.sql'\n",
    "statusTrace" : "  File \"D:\\PythonCode\\apiAutoTest\\lib\\site-packages\\pluggy\\callers.py\", line 187, in _multicall\n    res = hook_impl.function(*args)\n  File \"D:\\PythonCode\\apiAutoTest\\lib\\site-packages\\_pytest\\fixtures.py\", line 1117, in pytest_fixture_setup\n    result = call_fixture_func(fixturefunc, request, kwargs)\n  File \"D:\\PythonCode\\apiAutoTest\\lib\\site-packages\\_pytest\\fixtures.py\", line 915, in call_fixture_func\n    fixture_result = next(generator)\n  File \"F:\\CODE\\python-test\\apiAutoTest\\test\\conftest.py\", line 24, in data_clearing\n    DataClearing.backup_mysql()\n  File \"F:\\CODE\\python-test\\apiAutoTest\\tools\\data_clearing.py\", line 119, in backup_mysql\n    cls.server.files_action(0,\n  File \"F:\\CODE\\python-test\\apiAutoTest\\tools\\data_clearing.py\", line 77, in files_action\n    self.ftp_client.get(remotepath=remote_path, localpath=file_path)\n  File \"D:\\PythonCode\\apiAutoTest\\lib\\site-packages\\paramiko\\sftp_client.py\", line 801, in get\n    with open(localpath, \"wb\") as fl:\n",
    "steps" : [ ],
    "attachments" : [ ],
    "parameters" : [ ],
    "hasContent" : true,
    "stepsCount" : 0,
    "attachmentsCount" : 0,
    "shouldDisplayMessage" : true
  }, {
    "name" : "data_clearing",
    "time" : {
      "start" : 1641450334288,
      "stop" : 1641450335331,
      "duration" : 1043
    },
    "status" : "broken",
    "statusMessage" : "FileNotFoundError: [Errno 2] No such file or directory: '/home/chenlei/backup_sqls/apiautotest_2022-01-06T14_21_46.sql'\n",
    "statusTrace" : "  File \"D:\\PythonCode\\apiAutoTest\\lib\\site-packages\\pluggy\\callers.py\", line 187, in _multicall\n    res = hook_impl.function(*args)\n  File \"D:\\PythonCode\\apiAutoTest\\lib\\site-packages\\_pytest\\fixtures.py\", line 1117, in pytest_fixture_setup\n    result = call_fixture_func(fixturefunc, request, kwargs)\n  File \"D:\\PythonCode\\apiAutoTest\\lib\\site-packages\\_pytest\\fixtures.py\", line 915, in call_fixture_func\n    fixture_result = next(generator)\n  File \"F:\\CODE\\python-test\\apiAutoTest\\test\\conftest.py\", line 24, in data_clearing\n    DataClearing.backup_mysql()\n  File \"F:\\CODE\\python-test\\apiAutoTest\\tools\\data_clearing.py\", line 119, in backup_mysql\n    cls.server.files_action(0,\n  File \"F:\\CODE\\python-test\\apiAutoTest\\tools\\data_clearing.py\", line 77, in files_action\n    self.ftp_client.get(remotepath=remote_path, localpath=file_path)\n  File \"D:\\PythonCode\\apiAutoTest\\lib\\site-packages\\paramiko\\sftp_client.py\", line 801, in get\n    with open(localpath, \"wb\") as fl:\n",
    "steps" : [ ],
    "attachments" : [ ],
    "parameters" : [ ],
    "hasContent" : true,
    "stepsCount" : 0,
    "attachmentsCount" : 0,
    "shouldDisplayMessage" : true
  }, {
    "name" : "data_clearing",
    "time" : {
      "start" : 1641450336349,
      "stop" : 1641450337848,
      "duration" : 1499
    },
    "status" : "broken",
    "statusMessage" : "FileNotFoundError: [Errno 2] No such file or directory: '/home/chenlei/backup_sqls/apiautotest_2022-01-06T14_21_46.sql'\n",
    "statusTrace" : "  File \"D:\\PythonCode\\apiAutoTest\\lib\\site-packages\\pluggy\\callers.py\", line 187, in _multicall\n    res = hook_impl.function(*args)\n  File \"D:\\PythonCode\\apiAutoTest\\lib\\site-packages\\_pytest\\fixtures.py\", line 1117, in pytest_fixture_setup\n    result = call_fixture_func(fixturefunc, request, kwargs)\n  File \"D:\\PythonCode\\apiAutoTest\\lib\\site-packages\\_pytest\\fixtures.py\", line 915, in call_fixture_func\n    fixture_result = next(generator)\n  File \"F:\\CODE\\python-test\\apiAutoTest\\test\\conftest.py\", line 24, in data_clearing\n    DataClearing.backup_mysql()\n  File \"F:\\CODE\\python-test\\apiAutoTest\\tools\\data_clearing.py\", line 119, in backup_mysql\n    cls.server.files_action(0,\n  File \"F:\\CODE\\python-test\\apiAutoTest\\tools\\data_clearing.py\", line 77, in files_action\n    self.ftp_client.get(remotepath=remote_path, localpath=file_path)\n  File \"D:\\PythonCode\\apiAutoTest\\lib\\site-packages\\paramiko\\sftp_client.py\", line 801, in get\n    with open(localpath, \"wb\") as fl:\n",
    "steps" : [ ],
    "attachments" : [ ],
    "parameters" : [ ],
    "hasContent" : true,
    "stepsCount" : 0,
    "attachmentsCount" : 0,
    "shouldDisplayMessage" : true
  }, {
    "name" : "data_clearing",
    "time" : {
      "start" : 1641450338878,
      "stop" : 1641450340351,
      "duration" : 1473
    },
    "status" : "broken",
    "statusMessage" : "FileNotFoundError: [Errno 2] No such file or directory: '/home/chenlei/backup_sqls/apiautotest_2022-01-06T14_21_46.sql'\n",
    "statusTrace" : "  File \"D:\\PythonCode\\apiAutoTest\\lib\\site-packages\\pluggy\\callers.py\", line 187, in _multicall\n    res = hook_impl.function(*args)\n  File \"D:\\PythonCode\\apiAutoTest\\lib\\site-packages\\_pytest\\fixtures.py\", line 1117, in pytest_fixture_setup\n    result = call_fixture_func(fixturefunc, request, kwargs)\n  File \"D:\\PythonCode\\apiAutoTest\\lib\\site-packages\\_pytest\\fixtures.py\", line 915, in call_fixture_func\n    fixture_result = next(generator)\n  File \"F:\\CODE\\python-test\\apiAutoTest\\test\\conftest.py\", line 24, in data_clearing\n    DataClearing.backup_mysql()\n  File \"F:\\CODE\\python-test\\apiAutoTest\\tools\\data_clearing.py\", line 119, in backup_mysql\n    cls.server.files_action(0,\n  File \"F:\\CODE\\python-test\\apiAutoTest\\tools\\data_clearing.py\", line 77, in files_action\n    self.ftp_client.get(remotepath=remote_path, localpath=file_path)\n  File \"D:\\PythonCode\\apiAutoTest\\lib\\site-packages\\paramiko\\sftp_client.py\", line 801, in get\n    with open(localpath, \"wb\") as fl:\n",
    "steps" : [ ],
    "attachments" : [ ],
    "parameters" : [ ],
    "hasContent" : true,
    "stepsCount" : 0,
    "attachmentsCount" : 0,
    "shouldDisplayMessage" : true
  }, {
    "name" : "data_clearing",
    "time" : {
      "start" : 1641450341375,
      "stop" : 1641450342779,
      "duration" : 1404
    },
    "status" : "broken",
    "statusMessage" : "FileNotFoundError: [Errno 2] No such file or directory: '/home/chenlei/backup_sqls/apiautotest_2022-01-06T14_21_46.sql'\n",
    "statusTrace" : "  File \"D:\\PythonCode\\apiAutoTest\\lib\\site-packages\\pluggy\\callers.py\", line 187, in _multicall\n    res = hook_impl.function(*args)\n  File \"D:\\PythonCode\\apiAutoTest\\lib\\site-packages\\_pytest\\fixtures.py\", line 1117, in pytest_fixture_setup\n    result = call_fixture_func(fixturefunc, request, kwargs)\n  File \"D:\\PythonCode\\apiAutoTest\\lib\\site-packages\\_pytest\\fixtures.py\", line 915, in call_fixture_func\n    fixture_result = next(generator)\n  File \"F:\\CODE\\python-test\\apiAutoTest\\test\\conftest.py\", line 24, in data_clearing\n    DataClearing.backup_mysql()\n  File \"F:\\CODE\\python-test\\apiAutoTest\\tools\\data_clearing.py\", line 119, in backup_mysql\n    cls.server.files_action(0,\n  File \"F:\\CODE\\python-test\\apiAutoTest\\tools\\data_clearing.py\", line 77, in files_action\n    self.ftp_client.get(remotepath=remote_path, localpath=file_path)\n  File \"D:\\PythonCode\\apiAutoTest\\lib\\site-packages\\paramiko\\sftp_client.py\", line 801, in get\n    with open(localpath, \"wb\") as fl:\n",
    "steps" : [ ],
    "attachments" : [ ],
    "parameters" : [ ],
    "hasContent" : true,
    "stepsCount" : 0,
    "attachmentsCount" : 0,
    "shouldDisplayMessage" : true
  }, {
    "name" : "data_clearing",
    "time" : {
      "start" : 1641450343813,
      "stop" : 1641450344924,
      "duration" : 1111
    },
    "status" : "broken",
    "statusMessage" : "FileNotFoundError: [Errno 2] No such file or directory: '/home/chenlei/backup_sqls/apiautotest_2022-01-06T14_21_46.sql'\n",
    "statusTrace" : "  File \"D:\\PythonCode\\apiAutoTest\\lib\\site-packages\\pluggy\\callers.py\", line 187, in _multicall\n    res = hook_impl.function(*args)\n  File \"D:\\PythonCode\\apiAutoTest\\lib\\site-packages\\_pytest\\fixtures.py\", line 1117, in pytest_fixture_setup\n    result = call_fixture_func(fixturefunc, request, kwargs)\n  File \"D:\\PythonCode\\apiAutoTest\\lib\\site-packages\\_pytest\\fixtures.py\", line 915, in call_fixture_func\n    fixture_result = next(generator)\n  File \"F:\\CODE\\python-test\\apiAutoTest\\test\\conftest.py\", line 24, in data_clearing\n    DataClearing.backup_mysql()\n  File \"F:\\CODE\\python-test\\apiAutoTest\\tools\\data_clearing.py\", line 119, in backup_mysql\n    cls.server.files_action(0,\n  File \"F:\\CODE\\python-test\\apiAutoTest\\tools\\data_clearing.py\", line 77, in files_action\n    self.ftp_client.get(remotepath=remote_path, localpath=file_path)\n  File \"D:\\PythonCode\\apiAutoTest\\lib\\site-packages\\paramiko\\sftp_client.py\", line 801, in get\n    with open(localpath, \"wb\") as fl:\n",
    "steps" : [ ],
    "attachments" : [ ],
    "parameters" : [ ],
    "hasContent" : true,
    "stepsCount" : 0,
    "attachmentsCount" : 0,
    "shouldDisplayMessage" : true
  }, {
    "name" : "data_clearing",
    "time" : {
      "start" : 1641450345942,
      "stop" : 1641450347310,
      "duration" : 1368
    },
    "status" : "broken",
    "statusMessage" : "FileNotFoundError: [Errno 2] No such file or directory: '/home/chenlei/backup_sqls/apiautotest_2022-01-06T14_21_46.sql'\n",
    "statusTrace" : "  File \"D:\\PythonCode\\apiAutoTest\\lib\\site-packages\\pluggy\\callers.py\", line 187, in _multicall\n    res = hook_impl.function(*args)\n  File \"D:\\PythonCode\\apiAutoTest\\lib\\site-packages\\_pytest\\fixtures.py\", line 1117, in pytest_fixture_setup\n    result = call_fixture_func(fixturefunc, request, kwargs)\n  File \"D:\\PythonCode\\apiAutoTest\\lib\\site-packages\\_pytest\\fixtures.py\", line 915, in call_fixture_func\n    fixture_result = next(generator)\n  File \"F:\\CODE\\python-test\\apiAutoTest\\test\\conftest.py\", line 24, in data_clearing\n    DataClearing.backup_mysql()\n  File \"F:\\CODE\\python-test\\apiAutoTest\\tools\\data_clearing.py\", line 119, in backup_mysql\n    cls.server.files_action(0,\n  File \"F:\\CODE\\python-test\\apiAutoTest\\tools\\data_clearing.py\", line 77, in files_action\n    self.ftp_client.get(remotepath=remote_path, localpath=file_path)\n  File \"D:\\PythonCode\\apiAutoTest\\lib\\site-packages\\paramiko\\sftp_client.py\", line 801, in get\n    with open(localpath, \"wb\") as fl:\n",
    "steps" : [ ],
    "attachments" : [ ],
    "parameters" : [ ],
    "hasContent" : true,
    "stepsCount" : 0,
    "attachmentsCount" : 0,
    "shouldDisplayMessage" : true
  }, {
    "name" : "data_clearing",
    "time" : {
      "start" : 1641450348352,
      "stop" : 1641450349879,
      "duration" : 1527
    },
    "status" : "broken",
    "statusMessage" : "FileNotFoundError: [Errno 2] No such file or directory: '/home/chenlei/backup_sqls/apiautotest_2022-01-06T14_21_46.sql'\n",
    "statusTrace" : "  File \"D:\\PythonCode\\apiAutoTest\\lib\\site-packages\\pluggy\\callers.py\", line 187, in _multicall\n    res = hook_impl.function(*args)\n  File \"D:\\PythonCode\\apiAutoTest\\lib\\site-packages\\_pytest\\fixtures.py\", line 1117, in pytest_fixture_setup\n    result = call_fixture_func(fixturefunc, request, kwargs)\n  File \"D:\\PythonCode\\apiAutoTest\\lib\\site-packages\\_pytest\\fixtures.py\", line 915, in call_fixture_func\n    fixture_result = next(generator)\n  File \"F:\\CODE\\python-test\\apiAutoTest\\test\\conftest.py\", line 24, in data_clearing\n    DataClearing.backup_mysql()\n  File \"F:\\CODE\\python-test\\apiAutoTest\\tools\\data_clearing.py\", line 119, in backup_mysql\n    cls.server.files_action(0,\n  File \"F:\\CODE\\python-test\\apiAutoTest\\tools\\data_clearing.py\", line 77, in files_action\n    self.ftp_client.get(remotepath=remote_path, localpath=file_path)\n  File \"D:\\PythonCode\\apiAutoTest\\lib\\site-packages\\paramiko\\sftp_client.py\", line 801, in get\n    with open(localpath, \"wb\") as fl:\n",
    "steps" : [ ],
    "attachments" : [ ],
    "parameters" : [ ],
    "hasContent" : true,
    "stepsCount" : 0,
    "attachmentsCount" : 0,
    "shouldDisplayMessage" : true
  }, {
    "name" : "data_clearing",
    "time" : {
      "start" : 1641450350896,
      "stop" : 1641450352638,
      "duration" : 1742
    },
    "status" : "broken",
    "statusMessage" : "FileNotFoundError: [Errno 2] No such file or directory: '/home/chenlei/backup_sqls/apiautotest_2022-01-06T14_21_46.sql'\n",
    "statusTrace" : "  File \"D:\\PythonCode\\apiAutoTest\\lib\\site-packages\\pluggy\\callers.py\", line 187, in _multicall\n    res = hook_impl.function(*args)\n  File \"D:\\PythonCode\\apiAutoTest\\lib\\site-packages\\_pytest\\fixtures.py\", line 1117, in pytest_fixture_setup\n    result = call_fixture_func(fixturefunc, request, kwargs)\n  File \"D:\\PythonCode\\apiAutoTest\\lib\\site-packages\\_pytest\\fixtures.py\", line 915, in call_fixture_func\n    fixture_result = next(generator)\n  File \"F:\\CODE\\python-test\\apiAutoTest\\test\\conftest.py\", line 24, in data_clearing\n    DataClearing.backup_mysql()\n  File \"F:\\CODE\\python-test\\apiAutoTest\\tools\\data_clearing.py\", line 119, in backup_mysql\n    cls.server.files_action(0,\n  File \"F:\\CODE\\python-test\\apiAutoTest\\tools\\data_clearing.py\", line 77, in files_action\n    self.ftp_client.get(remotepath=remote_path, localpath=file_path)\n  File \"D:\\PythonCode\\apiAutoTest\\lib\\site-packages\\paramiko\\sftp_client.py\", line 801, in get\n    with open(localpath, \"wb\") as fl:\n",
    "steps" : [ ],
    "attachments" : [ ],
    "parameters" : [ ],
    "hasContent" : true,
    "stepsCount" : 0,
    "attachmentsCount" : 0,
    "shouldDisplayMessage" : true
  } ],
  "testStage" : {
    "status" : "broken",
    "statusMessage" : "FileNotFoundError: [Errno 2] No such file or directory: '/home/chenlei/backup_sqls/apiautotest_2022-01-06T14_21_46.sql'",
    "statusTrace" : "@pytest.fixture(scope=\"session\")\n    def data_clearing():\n        \"\"\"数据清洗\"\"\"\n        DataClearing.server_init()\n        # 1. 备份数据库\n>       DataClearing.backup_mysql()\n\ntest\\conftest.py:24: \n_ _ _ _ _ _ _ _ _ _ _ _ _ _ _ _ _ _ _ _ _ _ _ _ _ _ _ _ _ _ _ _ _ _ _ _ _ _ _ _\ntools\\data_clearing.py:119: in backup_mysql\n    cls.server.files_action(0,\ntools\\data_clearing.py:77: in files_action\n    self.ftp_client.get(remotepath=remote_path, localpath=file_path)\n_ _ _ _ _ _ _ _ _ _ _ _ _ _ _ _ _ _ _ _ _ _ _ _ _ _ _ _ _ _ _ _ _ _ _ _ _ _ _ _\n\nself = <paramiko.sftp_client.SFTPClient object at 0x0000017F68F53670>\nremotepath = '/root/backup_sql/apiautotest_2022-01-06T14_21_46.sql'\nlocalpath = '/home/chenlei/backup_sqls/apiautotest_2022-01-06T14_21_46.sql'\ncallback = None\n\n    def get(self, remotepath, localpath, callback=None):\n        \"\"\"\n        Copy a remote file (``remotepath``) from the SFTP server to the local\n        host as ``localpath``.  Any exception raised by operations will be\n        passed through.  This method is primarily provided as a convenience.\n    \n        :param str remotepath: the remote file to copy\n        :param str localpath: the destination path on the local host\n        :param callable callback:\n            optional callback function (form: ``func(int, int)``) that accepts\n            the bytes transferred so far and the total bytes to be transferred\n    \n        .. versionadded:: 1.4\n        .. versionchanged:: 1.7.4\n            Added the ``callback`` param\n        \"\"\"\n>       with open(localpath, \"wb\") as fl:\nE       FileNotFoundError: [Errno 2] No such file or directory: '/home/chenlei/backup_sqls/apiautotest_2022-01-06T14_21_46.sql'\n\nD:\\PythonCode\\apiAutoTest\\lib\\site-packages\\paramiko\\sftp_client.py:801: FileNotFoundError",
    "steps" : [ ],
    "attachments" : [ {
      "uid" : "f48c0849ce0d4b0e",
      "name" : "stderr",
      "source" : "f48c0849ce0d4b0e.txt",
      "type" : "text/plain",
      "size" : 2368
    } ],
    "parameters" : [ ],
    "hasContent" : true,
    "stepsCount" : 0,
    "attachmentsCount" : 1,
    "shouldDisplayMessage" : true
  },
  "afterStages" : [ ],
  "labels" : [ {
    "name" : "tag",
    "value" : "flaky(reruns=2, reruns_delay=1)"
  }, {
    "name" : "parentSuite",
    "value" : "test"
  }, {
    "name" : "suite",
    "value" : "test_api"
  }, {
    "name" : "host",
    "value" : "DESKTOP-BNVFIE4"
  }, {
    "name" : "thread",
    "value" : "23664-MainThread"
  }, {
    "name" : "framework",
    "value" : "pytest"
  }, {
    "name" : "language",
    "value" : "cpython3"
  }, {
    "name" : "package",
    "value" : "test.test_api"
  }, {
    "name" : "resultFormat",
    "value" : "allure2"
  } ],
  "parameters" : [ {
    "name" : "cases",
    "value" : "['c51', '服务质量关', '{\"Authorization\": \"${token}\"}', 'config/update', 'post', 'json', '', '{\"key\":\"qos.switch\",\"value\":\"0\",\"configType\":\"global\"}', '', '', '{\"$.data.msg\": \"success\"}']"
  } ],
  "links" : [ ],
  "hidden" : false,
  "retry" : false,
  "extra" : {
    "severity" : "normal",
    "retries" : [ {
      "uid" : "6e4aef9956e32ec4",
      "status" : "broken",
      "statusDetails" : "FileNotFoundError: [Errno 2] No such file or directory: '/home/chenlei/backup_sqls/apiautotest_2022-01-06T14_21_46.sql'",
      "time" : {
        "start" : 1641450338878,
        "stop" : 1641450338878,
        "duration" : 0
      }
    }, {
      "uid" : "2a702cebdbf3b11e",
      "status" : "broken",
      "statusDetails" : "FileNotFoundError: [Errno 2] No such file or directory: '/home/chenlei/backup_sqls/apiautotest_2022-01-06T14_21_46.sql'",
      "time" : {
        "start" : 1641450337864,
        "stop" : 1641450337864,
        "duration" : 0
      }
    } ],
    "categories" : [ {
      "name" : "Test defects",
      "matchedStatuses" : [ ],
      "flaky" : false
    } ],
    "tags" : [ "flaky(reruns=2, reruns_delay=1)" ]
  },
  "source" : "3d65f199f46823ed.json",
  "parameterValues" : [ "['c51', '服务质量关', '{\"Authorization\": \"${token}\"}', 'config/update', 'post', 'json', '', '{\"key\":\"qos.switch\",\"value\":\"0\",\"configType\":\"global\"}', '', '', '{\"$.data.msg\": \"success\"}']" ]
}