{"uuid": "2b75a4b0-9a11-4319-a7c6-bc65f3345b1f", "children": ["4068c933-efd4-41b1-acdd-f533520e8366"], "befores": [{"name": "data_clearing", "status": "broken", "statusDetails": {"message": "FileNotFoundError: [Errno 2] No such file or directory: '/home/chenlei/backup_sqls/apiautotest_2022-01-06T14_21_46.sql'\n", "trace": "  File \"D:\\PythonCode\\apiAutoTest\\lib\\site-packages\\pluggy\\callers.py\", line 187, in _multicall\n    res = hook_impl.function(*args)\n  File \"D:\\PythonCode\\apiAutoTest\\lib\\site-packages\\_pytest\\fixtures.py\", line 1117, in pytest_fixture_setup\n    result = call_fixture_func(fixturefunc, request, kwargs)\n  File \"D:\\PythonCode\\apiAutoTest\\lib\\site-packages\\_pytest\\fixtures.py\", line 915, in call_fixture_func\n    fixture_result = next(generator)\n  File \"F:\\CODE\\python-test\\apiAutoTest\\test\\conftest.py\", line 24, in data_clearing\n    DataClearing.backup_mysql()\n  File \"F:\\CODE\\python-test\\apiAutoTest\\tools\\data_clearing.py\", line 119, in backup_mysql\n    cls.server.files_action(0,\n  File \"F:\\CODE\\python-test\\apiAutoTest\\tools\\data_clearing.py\", line 77, in files_action\n    self.ftp_client.get(remotepath=remote_path, localpath=file_path)\n  File \"D:\\PythonCode\\apiAutoTest\\lib\\site-packages\\paramiko\\sftp_client.py\", line 801, in get\n    with open(localpath, \"wb\") as fl:\n"}, "start": 1641450355890, "stop": 1641450357231}], "start": 1641450355890, "stop": 1641450357247}