{"uuid": "e7285c72-0616-4173-bb8a-76141a52e80b", "children": ["23a023a2-ab46-4dfc-a76b-4b20dc9eb739", "31b2a429-104d-43a1-baa0-64a0f498f966", "5f8e3d25-c60a-40e4-9e6b-b5d06d450b6d", "726f7380-8789-464e-a2e2-0ac4b0dea984", "a7d1bfc1-919c-401f-ae65-7e88cfcf12c9", "3eef8884-da3b-40bf-ac04-9c0dece5b70e", "913a4347-fb19-4c85-a5b5-5c689b287700", "e9241d22-6686-4296-befd-44a3ed34c513", "37c82f91-8d1e-4cc8-9933-7a50db217113", "b1af93ce-23ff-418b-872a-00aa88f54525", "3b7034ca-7d6d-44b9-b1db-00b71a185fab", "1b73e9e1-1227-4bb6-812a-679f1e8d2a5e", "907fb6f1-94ff-47c7-b329-fa229d0cd523", "02c11c8c-25e6-452b-85c9-c4e1e87814d5", "3608a34b-675b-4169-a7ac-4995325156ea", "5e9e73e2-425c-43fa-b022-81e2e3da7005", "2e76c23f-aa1b-428c-b2c5-f8990ba0bca1", "292c576c-f58f-4665-b9cd-92e053c0a9ab", "1a9152cb-8112-4ab5-aa45-4c85368e7443", "1ec52bb7-68d8-4b31-8e3c-6b03b8107102", "8b22cb8e-8ecf-4e21-817a-26795800641f", "25c7b753-7c85-4580-906a-83873c2dded0", "96108a8a-1959-4a78-a08e-7b5165d5a4cf", "b59e302d-3526-46f0-a933-6ad653273164", "b43c17d1-379a-41d3-8672-8d0f9bd0f3bf", "4552e491-d59d-4659-b30a-bff63102907f", "c266f783-98d5-407d-840e-c9ddc4b56f63", "7b70db37-5073-41a2-91d7-1085449b58b8", "5ab0eed3-134f-49e0-9328-947caf2f4f4d", "dfb622f3-0788-4f55-b404-b17569f71b03", "c263e8ba-81a7-4e31-b00d-deb6dc3ca27e", "3455fef0-b602-4f46-895c-67fdea3945da", "b2c1a47a-83c3-4f56-b619-7a0fec10ef0f", "ff93a57a-e0c2-495a-bbf3-e09ea2012475", "e9be53b3-d53e-45f1-9f8a-dc5b97152110", "a0182577-1e4d-4e47-9027-20c5d4146dd3", "d3552915-9668-4d46-973e-f88af3b576fb", "3ee768f8-46e8-44d9-a971-d42e562c52c9", "5a450eaf-1d1c-40bc-9f05-27e849dc6d44", "6a97cbcf-ce28-4d3c-85f6-fac3f79743d3", "ca287416-bd47-4557-85c1-b6000b997114", "d0271109-4649-4d07-a0c6-273eca0ca2bf", "c00121ea-4551-4720-bd18-b57eb6b2170a", "8e55aef7-8812-4d2b-b84f-45aa496647f6", "35622917-cee2-4f24-854e-fc59d9d694d9", "198aa145-7e52-440b-ab3b-c82957765fda", "7bb2cdda-9b71-46bb-9925-f9ebf63f2db0", "76f8d7ca-911e-456a-a103-0a5f11d0ea68", "5ac679c4-c64a-46cb-ac19-c201e734f9d2", "33be2c5c-4263-4ae6-829e-201f56b805b3", "cd460fde-83b1-4314-a4b3-55dccf3583f7", "cfcf6223-450f-4bc7-9914-ba558d9ce654", "e4ddbd4b-5c8c-4cf4-8199-61b80f14e9b9", "78cd9ce8-e3e6-41ea-9f5f-28dd5401e7db", "d1372514-9997-41a2-a14b-cbd0084be3d2", "8d5cd63a-24f4-4f8d-9f6a-d8527cae8675", "36791207-c7cb-4b28-99ff-d1ee70435af1", "aea745b3-e4d3-480a-ad6e-ee46cd497807", "18365ba2-bd53-410b-b030-4089601507c1", "6d4df0d3-88af-4ff5-a5b4-01694636a07b", "39f4e0c8-0e73-46e4-b131-18e7af869b8f", "b9b1880b-15df-49df-8b62-c706d53c8439", "20366e9f-5209-4efa-ad5a-3c9a832b3733", "568de083-fb79-492a-ad72-9d6a3291f1e5", "69afd053-1c1f-4506-bb17-30f95bd6678e", "1af57d55-de84-4fa2-b984-9b5c7be6ec43", "c27de03f-50b8-4aa1-abd2-3f217cd99647", "5d9cd795-bb10-4db5-8519-a18869681a6f", "8a4473b5-d15c-4463-b13b-586b0d1ec25f", "0bb24a77-8ae1-4e58-8107-5571ade7a95f", "9097319d-4609-47c5-a3ca-8be17af305b6", "8047f85a-3af4-492c-8d8f-9db22c92fd8a", "c65bcbf1-893f-4d4e-be46-ae955024e198", "970e7312-2f2c-4b85-aab9-2deb5ae4a4c5", "0f2b8409-ccee-4017-adac-09a3c5b5d2b9", "6285c175-4326-4c3a-80d0-eb0705321966", "ccbbb321-9dfe-4d9b-9b6a-db27eb81ead2", "5c162c8f-2a44-4f59-ba14-5c6758e1a10f", "074c4ba9-12b3-4ef2-b37c-385047002617", "f8d717b2-0504-47d1-812c-f33f39c67db3", "194ac857-0354-4803-b5d4-b2e10c7a394d", "b06a663c-7733-4c93-a6fa-0175b7293c8c", "8dbde9b2-27da-46d2-ac7b-ad28a6ca65cd", "ef56f7ab-d245-4d1c-b322-cb2dd5c91444", "8640644d-a37e-4037-abdc-78c75e1c3c32", "6e3b4792-cc8c-4d12-9192-a9f08359b782", "5068b8d4-55c6-4ecb-a903-7f12265f61ec", "db30b1f9-4bdf-4af7-b228-bccf4e561a2e", "b988566f-e2f0-446b-a057-d98fab1e6e13", "e433b497-4089-40e4-90ab-854526db277f", "0c487e7c-b546-4ea4-883e-f5f740e66f01", "8bb52165-1625-40e4-bba6-c5464db1e7ab", "2595aff6-e039-4c81-80c4-e3d66d5d0d3c", "5e3a74cf-cb25-4d38-b1c3-68b74f9a13b5", "f55a7906-dcb1-442d-9b3d-92dbe706ccce", "c24d3075-42e3-4ecf-9ba4-bc6898e1142d", "58a50bef-e4a0-46e6-a433-90c1e868dbb5", "e00d264e-7761-4b02-87fc-5e7ab5dfd267", "8809a800-65f8-4edf-8e59-a386ce419ba2", "c005f748-994d-4ef3-bd65-ee32582302f2", "d729ace2-f06e-4597-a90f-4782d5678c5a", "fb40b94f-3c4e-4c4c-882d-b8d0128e5df0", "509e95c5-91ca-4fdd-b77c-5f0689c5abc0", "4aa3a1f1-a545-4fa6-a6f7-9ed4ce648d84", "9f5ab845-f6a6-4fe6-b5e1-d177ed487e84", "d0bf6fae-1dc4-444d-8d0c-fd72920b2a4d", "ea963533-9d6e-4a4e-b919-13b64651cb55", "78a492ab-cb51-4593-b4b4-8e93404cf1ab", "8d369066-432b-4d6c-a264-2cced7e2cfee", "aa00a40e-1d63-4254-a0ee-f777c035bc02", "8c3df1f5-07ec-441c-94da-55b42582f25e", "768afe63-c3d5-412f-8a4e-f7de4df10d8c", "4f6b1481-c5af-4e51-82b7-682fa126efa8", "ff9a8074-c78c-4620-8ddc-6407599eebf3", "58a80d3e-9026-485c-90ef-878889baac55", "376a750e-ebcf-43db-bfe6-ba416976b97f", "e8b7e98e-1d4a-489c-87a0-e78f984ce313", "211e0ede-717e-4a60-9bd2-8e0de1b21266", "5fa26085-345c-4fe2-a322-f3cf9694d1e6", "42092da2-4c5e-4945-acce-5542f8edfbfc", "df72650f-b170-4184-a962-1da48504db93", "59a63707-37cb-460b-b9a1-ceacba56e8ff", "a007bff4-a898-4541-9095-9901453cb0da", "2ee022ff-9a92-46ef-bae0-fda8a3d12949", "adc8ac3b-13cb-4771-ab05-a35cd235ae03", "59a6f899-e5f6-490a-a299-5c76822f345b", "a46c9a61-be7d-4a2a-a22c-cd95487aba43", "90449a6c-9724-446b-9234-aff0e00440a6", "bc2cf8a6-03c4-40d5-a4aa-2202778c2cb9", "245781cd-dce5-4e26-ab13-0fac7abec615", "cfe048f8-67d7-45e3-b080-1830e32224d9", "7cdf31b1-654a-4777-82be-82c4c02cb0e3", "1e659930-716c-4668-8c45-45a6f4bfa8a7", "8e3e01f3-5aa9-4817-8ca0-5c8da63388bd", "b40bdb14-5abc-4531-a446-ef8fe0e4e1e4", "0254d926-1652-44ec-aadf-65c796c27f36", "b4bbee11-f819-4a5e-a1dc-f027dc5024df", "a195b8d8-2e23-4f45-b9b2-69fc3b33cf59", "e17377c2-eb2e-4f6a-8ea5-91a3c4d510a7", "ef19cf80-90c7-4d96-b7d0-ab7a864ba41c", "499260ff-e7ed-447a-ab67-97bba69aab5a", "02be7a8f-e168-481a-86b4-568b4e6015af", "7d99b363-8220-486e-bc3d-27bf4558919e", "c63ebac0-f6e3-4808-9b8e-08969dd1ce9c", "2bb8f4c2-b944-4c4d-b1f5-5e350b3e90b3", "af521e9c-3d47-4d90-8b86-e8af5077b84a", "a3b3a60f-7f8e-44c9-87ec-a3dc6f16453f", "e07deae4-6d1a-41e6-a2ff-91aa888b4817", "627d4d34-70ef-4e82-a2f8-213a0d607b09", "300f9058-dd6f-4805-8735-912afbca6a83", "29c72d44-7416-4741-b437-e015c76aed5a", "2e9d696c-5a29-4bcb-afa7-1804a05e8e4a", "cf12f619-583e-4a34-b371-a3e199bfa5fe", "622feaca-2eec-4f31-9d94-5b644806cf82", "6ad3742f-e0f5-4931-b5ea-3a3b7b4fac38", "ed47e68b-d41c-4b55-b3a1-680107248c7f", "b1320043-a243-4351-af34-837296af6759", "a54075dc-6de1-4893-8354-092992f870d1", "c51b67e1-e0a2-4d49-b07f-5403f8af1982", "7307e64b-4f9b-4dca-96da-e2f5f7e98591"], "befores": [{"name": "data_clearing", "status": "broken", "statusDetails": {"message": "FileNotFoundError: [Errno 2] No such file or directory: '/home/chenlei/backup_sqls/apiautotest_2022-01-06T14_21_46.sql'\n", "trace": "  File \"D:\\PythonCode\\apiAutoTest\\lib\\site-packages\\pluggy\\callers.py\", line 187, in _multicall\n    res = hook_impl.function(*args)\n  File \"D:\\PythonCode\\apiAutoTest\\lib\\site-packages\\_pytest\\fixtures.py\", line 1117, in pytest_fixture_setup\n    result = call_fixture_func(fixturefunc, request, kwargs)\n  File \"D:\\PythonCode\\apiAutoTest\\lib\\site-packages\\_pytest\\fixtures.py\", line 915, in call_fixture_func\n    fixture_result = next(generator)\n  File \"F:\\CODE\\python-test\\apiAutoTest\\test\\conftest.py\", line 24, in data_clearing\n    DataClearing.backup_mysql()\n  File \"F:\\CODE\\python-test\\apiAutoTest\\tools\\data_clearing.py\", line 119, in backup_mysql\n    cls.server.files_action(0,\n  File \"F:\\CODE\\python-test\\apiAutoTest\\tools\\data_clearing.py\", line 77, in files_action\n    self.ftp_client.get(remotepath=remote_path, localpath=file_path)\n  File \"D:\\PythonCode\\apiAutoTest\\lib\\site-packages\\paramiko\\sftp_client.py\", line 801, in get\n    with open(localpath, \"wb\") as fl:\n"}, "start": 1641450107419, "stop": 1641450108813}, {"name": "data_clearing", "status": "broken", "statusDetails": {"message": "FileNotFoundError: [Errno 2] No such file or directory: '/home/chenlei/backup_sqls/apiautotest_2022-01-06T14_21_46.sql'\n", "trace": "  File \"D:\\PythonCode\\apiAutoTest\\lib\\site-packages\\pluggy\\callers.py\", line 187, in _multicall\n    res = hook_impl.function(*args)\n  File \"D:\\PythonCode\\apiAutoTest\\lib\\site-packages\\_pytest\\fixtures.py\", line 1117, in pytest_fixture_setup\n    result = call_fixture_func(fixturefunc, request, kwargs)\n  File \"D:\\PythonCode\\apiAutoTest\\lib\\site-packages\\_pytest\\fixtures.py\", line 915, in call_fixture_func\n    fixture_result = next(generator)\n  File \"F:\\CODE\\python-test\\apiAutoTest\\test\\conftest.py\", line 24, in data_clearing\n    DataClearing.backup_mysql()\n  File \"F:\\CODE\\python-test\\apiAutoTest\\tools\\data_clearing.py\", line 119, in backup_mysql\n    cls.server.files_action(0,\n  File \"F:\\CODE\\python-test\\apiAutoTest\\tools\\data_clearing.py\", line 77, in files_action\n    self.ftp_client.get(remotepath=remote_path, localpath=file_path)\n  File \"D:\\PythonCode\\apiAutoTest\\lib\\site-packages\\paramiko\\sftp_client.py\", line 801, in get\n    with open(localpath, \"wb\") as fl:\n"}, "start": 1641450109969, "stop": 1641450111546}, {"name": "data_clearing", "status": "broken", "statusDetails": {"message": "FileNotFoundError: [Errno 2] No such file or directory: '/home/chenlei/backup_sqls/apiautotest_2022-01-06T14_21_46.sql'\n", "trace": "  File \"D:\\PythonCode\\apiAutoTest\\lib\\site-packages\\pluggy\\callers.py\", line 187, in _multicall\n    res = hook_impl.function(*args)\n  File \"D:\\PythonCode\\apiAutoTest\\lib\\site-packages\\_pytest\\fixtures.py\", line 1117, in pytest_fixture_setup\n    result = call_fixture_func(fixturefunc, request, kwargs)\n  File \"D:\\PythonCode\\apiAutoTest\\lib\\site-packages\\_pytest\\fixtures.py\", line 915, in call_fixture_func\n    fixture_result = next(generator)\n  File \"F:\\CODE\\python-test\\apiAutoTest\\test\\conftest.py\", line 24, in data_clearing\n    DataClearing.backup_mysql()\n  File \"F:\\CODE\\python-test\\apiAutoTest\\tools\\data_clearing.py\", line 119, in backup_mysql\n    cls.server.files_action(0,\n  File \"F:\\CODE\\python-test\\apiAutoTest\\tools\\data_clearing.py\", line 77, in files_action\n    self.ftp_client.get(remotepath=remote_path, localpath=file_path)\n  File \"D:\\PythonCode\\apiAutoTest\\lib\\site-packages\\paramiko\\sftp_client.py\", line 801, in get\n    with open(localpath, \"wb\") as fl:\n"}, "start": 1641450112576, "stop": 1641450113897}, {"name": "data_clearing", "status": "broken", "statusDetails": {"message": "FileNotFoundError: [Errno 2] No such file or directory: '/home/chenlei/backup_sqls/apiautotest_2022-01-06T14_21_46.sql'\n", "trace": "  File \"D:\\PythonCode\\apiAutoTest\\lib\\site-packages\\pluggy\\callers.py\", line 187, in _multicall\n    res = hook_impl.function(*args)\n  File \"D:\\PythonCode\\apiAutoTest\\lib\\site-packages\\_pytest\\fixtures.py\", line 1117, in pytest_fixture_setup\n    result = call_fixture_func(fixturefunc, request, kwargs)\n  File \"D:\\PythonCode\\apiAutoTest\\lib\\site-packages\\_pytest\\fixtures.py\", line 915, in call_fixture_func\n    fixture_result = next(generator)\n  File \"F:\\CODE\\python-test\\apiAutoTest\\test\\conftest.py\", line 24, in data_clearing\n    DataClearing.backup_mysql()\n  File \"F:\\CODE\\python-test\\apiAutoTest\\tools\\data_clearing.py\", line 119, in backup_mysql\n    cls.server.files_action(0,\n  File \"F:\\CODE\\python-test\\apiAutoTest\\tools\\data_clearing.py\", line 77, in files_action\n    self.ftp_client.get(remotepath=remote_path, localpath=file_path)\n  File \"D:\\PythonCode\\apiAutoTest\\lib\\site-packages\\paramiko\\sftp_client.py\", line 801, in get\n    with open(localpath, \"wb\") as fl:\n"}, "start": 1641450114931, "stop": 1641450116080}, {"name": "data_clearing", "status": "broken", "statusDetails": {"message": "FileNotFoundError: [Errno 2] No such file or directory: '/home/chenlei/backup_sqls/apiautotest_2022-01-06T14_21_46.sql'\n", "trace": "  File \"D:\\PythonCode\\apiAutoTest\\lib\\site-packages\\pluggy\\callers.py\", line 187, in _multicall\n    res = hook_impl.function(*args)\n  File \"D:\\PythonCode\\apiAutoTest\\lib\\site-packages\\_pytest\\fixtures.py\", line 1117, in pytest_fixture_setup\n    result = call_fixture_func(fixturefunc, request, kwargs)\n  File \"D:\\PythonCode\\apiAutoTest\\lib\\site-packages\\_pytest\\fixtures.py\", line 915, in call_fixture_func\n    fixture_result = next(generator)\n  File \"F:\\CODE\\python-test\\apiAutoTest\\test\\conftest.py\", line 24, in data_clearing\n    DataClearing.backup_mysql()\n  File \"F:\\CODE\\python-test\\apiAutoTest\\tools\\data_clearing.py\", line 119, in backup_mysql\n    cls.server.files_action(0,\n  File \"F:\\CODE\\python-test\\apiAutoTest\\tools\\data_clearing.py\", line 77, in files_action\n    self.ftp_client.get(remotepath=remote_path, localpath=file_path)\n  File \"D:\\PythonCode\\apiAutoTest\\lib\\site-packages\\paramiko\\sftp_client.py\", line 801, in get\n    with open(localpath, \"wb\") as fl:\n"}, "start": 1641450117103, "stop": 1641450118359}, {"name": "data_clearing", "status": "broken", "statusDetails": {"message": "FileNotFoundError: [Errno 2] No such file or directory: '/home/chenlei/backup_sqls/apiautotest_2022-01-06T14_21_46.sql'\n", "trace": "  File \"D:\\PythonCode\\apiAutoTest\\lib\\site-packages\\pluggy\\callers.py\", line 187, in _multicall\n    res = hook_impl.function(*args)\n  File \"D:\\PythonCode\\apiAutoTest\\lib\\site-packages\\_pytest\\fixtures.py\", line 1117, in pytest_fixture_setup\n    result = call_fixture_func(fixturefunc, request, kwargs)\n  File \"D:\\PythonCode\\apiAutoTest\\lib\\site-packages\\_pytest\\fixtures.py\", line 915, in call_fixture_func\n    fixture_result = next(generator)\n  File \"F:\\CODE\\python-test\\apiAutoTest\\test\\conftest.py\", line 24, in data_clearing\n    DataClearing.backup_mysql()\n  File \"F:\\CODE\\python-test\\apiAutoTest\\tools\\data_clearing.py\", line 119, in backup_mysql\n    cls.server.files_action(0,\n  File \"F:\\CODE\\python-test\\apiAutoTest\\tools\\data_clearing.py\", line 77, in files_action\n    self.ftp_client.get(remotepath=remote_path, localpath=file_path)\n  File \"D:\\PythonCode\\apiAutoTest\\lib\\site-packages\\paramiko\\sftp_client.py\", line 801, in get\n    with open(localpath, \"wb\") as fl:\n"}, "start": 1641450119435, "stop": 1641450120502}, {"name": "data_clearing", "status": "broken", "statusDetails": {"message": "FileNotFoundError: [Errno 2] No such file or directory: '/home/chenlei/backup_sqls/apiautotest_2022-01-06T14_21_46.sql'\n", "trace": "  File \"D:\\PythonCode\\apiAutoTest\\lib\\site-packages\\pluggy\\callers.py\", line 187, in _multicall\n    res = hook_impl.function(*args)\n  File \"D:\\PythonCode\\apiAutoTest\\lib\\site-packages\\_pytest\\fixtures.py\", line 1117, in pytest_fixture_setup\n    result = call_fixture_func(fixturefunc, request, kwargs)\n  File \"D:\\PythonCode\\apiAutoTest\\lib\\site-packages\\_pytest\\fixtures.py\", line 915, in call_fixture_func\n    fixture_result = next(generator)\n  File \"F:\\CODE\\python-test\\apiAutoTest\\test\\conftest.py\", line 24, in data_clearing\n    DataClearing.backup_mysql()\n  File \"F:\\CODE\\python-test\\apiAutoTest\\tools\\data_clearing.py\", line 119, in backup_mysql\n    cls.server.files_action(0,\n  File \"F:\\CODE\\python-test\\apiAutoTest\\tools\\data_clearing.py\", line 77, in files_action\n    self.ftp_client.get(remotepath=remote_path, localpath=file_path)\n  File \"D:\\PythonCode\\apiAutoTest\\lib\\site-packages\\paramiko\\sftp_client.py\", line 801, in get\n    with open(localpath, \"wb\") as fl:\n"}, "start": 1641450121527, "stop": 1641450122874}, {"name": "data_clearing", "status": "broken", "statusDetails": {"message": "FileNotFoundError: [Errno 2] No such file or directory: '/home/chenlei/backup_sqls/apiautotest_2022-01-06T14_21_46.sql'\n", "trace": "  File \"D:\\PythonCode\\apiAutoTest\\lib\\site-packages\\pluggy\\callers.py\", line 187, in _multicall\n    res = hook_impl.function(*args)\n  File \"D:\\PythonCode\\apiAutoTest\\lib\\site-packages\\_pytest\\fixtures.py\", line 1117, in pytest_fixture_setup\n    result = call_fixture_func(fixturefunc, request, kwargs)\n  File \"D:\\PythonCode\\apiAutoTest\\lib\\site-packages\\_pytest\\fixtures.py\", line 915, in call_fixture_func\n    fixture_result = next(generator)\n  File \"F:\\CODE\\python-test\\apiAutoTest\\test\\conftest.py\", line 24, in data_clearing\n    DataClearing.backup_mysql()\n  File \"F:\\CODE\\python-test\\apiAutoTest\\tools\\data_clearing.py\", line 119, in backup_mysql\n    cls.server.files_action(0,\n  File \"F:\\CODE\\python-test\\apiAutoTest\\tools\\data_clearing.py\", line 77, in files_action\n    self.ftp_client.get(remotepath=remote_path, localpath=file_path)\n  File \"D:\\PythonCode\\apiAutoTest\\lib\\site-packages\\paramiko\\sftp_client.py\", line 801, in get\n    with open(localpath, \"wb\") as fl:\n"}, "start": 1641450123910, "stop": 1641450125574}, {"name": "data_clearing", "status": "broken", "statusDetails": {"message": "FileNotFoundError: [Errno 2] No such file or directory: '/home/chenlei/backup_sqls/apiautotest_2022-01-06T14_21_46.sql'\n", "trace": "  File \"D:\\PythonCode\\apiAutoTest\\lib\\site-packages\\pluggy\\callers.py\", line 187, in _multicall\n    res = hook_impl.function(*args)\n  File \"D:\\PythonCode\\apiAutoTest\\lib\\site-packages\\_pytest\\fixtures.py\", line 1117, in pytest_fixture_setup\n    result = call_fixture_func(fixturefunc, request, kwargs)\n  File \"D:\\PythonCode\\apiAutoTest\\lib\\site-packages\\_pytest\\fixtures.py\", line 915, in call_fixture_func\n    fixture_result = next(generator)\n  File \"F:\\CODE\\python-test\\apiAutoTest\\test\\conftest.py\", line 24, in data_clearing\n    DataClearing.backup_mysql()\n  File \"F:\\CODE\\python-test\\apiAutoTest\\tools\\data_clearing.py\", line 119, in backup_mysql\n    cls.server.files_action(0,\n  File \"F:\\CODE\\python-test\\apiAutoTest\\tools\\data_clearing.py\", line 77, in files_action\n    self.ftp_client.get(remotepath=remote_path, localpath=file_path)\n  File \"D:\\PythonCode\\apiAutoTest\\lib\\site-packages\\paramiko\\sftp_client.py\", line 801, in get\n    with open(localpath, \"wb\") as fl:\n"}, "start": 1641450126611, "stop": 1641450127781}, {"name": "data_clearing", "status": "broken", "statusDetails": {"message": "FileNotFoundError: [Errno 2] No such file or directory: '/home/chenlei/backup_sqls/apiautotest_2022-01-06T14_21_46.sql'\n", "trace": "  File \"D:\\PythonCode\\apiAutoTest\\lib\\site-packages\\pluggy\\callers.py\", line 187, in _multicall\n    res = hook_impl.function(*args)\n  File \"D:\\PythonCode\\apiAutoTest\\lib\\site-packages\\_pytest\\fixtures.py\", line 1117, in pytest_fixture_setup\n    result = call_fixture_func(fixturefunc, request, kwargs)\n  File \"D:\\PythonCode\\apiAutoTest\\lib\\site-packages\\_pytest\\fixtures.py\", line 915, in call_fixture_func\n    fixture_result = next(generator)\n  File \"F:\\CODE\\python-test\\apiAutoTest\\test\\conftest.py\", line 24, in data_clearing\n    DataClearing.backup_mysql()\n  File \"F:\\CODE\\python-test\\apiAutoTest\\tools\\data_clearing.py\", line 119, in backup_mysql\n    cls.server.files_action(0,\n  File \"F:\\CODE\\python-test\\apiAutoTest\\tools\\data_clearing.py\", line 77, in files_action\n    self.ftp_client.get(remotepath=remote_path, localpath=file_path)\n  File \"D:\\PythonCode\\apiAutoTest\\lib\\site-packages\\paramiko\\sftp_client.py\", line 801, in get\n    with open(localpath, \"wb\") as fl:\n"}, "start": 1641450128813, "stop": 1641450130016}, {"name": "data_clearing", "status": "broken", "statusDetails": {"message": "FileNotFoundError: [Errno 2] No such file or directory: '/home/chenlei/backup_sqls/apiautotest_2022-01-06T14_21_46.sql'\n", "trace": "  File \"D:\\PythonCode\\apiAutoTest\\lib\\site-packages\\pluggy\\callers.py\", line 187, in _multicall\n    res = hook_impl.function(*args)\n  File \"D:\\PythonCode\\apiAutoTest\\lib\\site-packages\\_pytest\\fixtures.py\", line 1117, in pytest_fixture_setup\n    result = call_fixture_func(fixturefunc, request, kwargs)\n  File \"D:\\PythonCode\\apiAutoTest\\lib\\site-packages\\_pytest\\fixtures.py\", line 915, in call_fixture_func\n    fixture_result = next(generator)\n  File \"F:\\CODE\\python-test\\apiAutoTest\\test\\conftest.py\", line 24, in data_clearing\n    DataClearing.backup_mysql()\n  File \"F:\\CODE\\python-test\\apiAutoTest\\tools\\data_clearing.py\", line 119, in backup_mysql\n    cls.server.files_action(0,\n  File \"F:\\CODE\\python-test\\apiAutoTest\\tools\\data_clearing.py\", line 77, in files_action\n    self.ftp_client.get(remotepath=remote_path, localpath=file_path)\n  File \"D:\\PythonCode\\apiAutoTest\\lib\\site-packages\\paramiko\\sftp_client.py\", line 801, in get\n    with open(localpath, \"wb\") as fl:\n"}, "start": 1641450131040, "stop": 1641450132799}, {"name": "data_clearing", "status": "broken", "statusDetails": {"message": "FileNotFoundError: [Errno 2] No such file or directory: '/home/chenlei/backup_sqls/apiautotest_2022-01-06T14_21_46.sql'\n", "trace": "  File \"D:\\PythonCode\\apiAutoTest\\lib\\site-packages\\pluggy\\callers.py\", line 187, in _multicall\n    res = hook_impl.function(*args)\n  File \"D:\\PythonCode\\apiAutoTest\\lib\\site-packages\\_pytest\\fixtures.py\", line 1117, in pytest_fixture_setup\n    result = call_fixture_func(fixturefunc, request, kwargs)\n  File \"D:\\PythonCode\\apiAutoTest\\lib\\site-packages\\_pytest\\fixtures.py\", line 915, in call_fixture_func\n    fixture_result = next(generator)\n  File \"F:\\CODE\\python-test\\apiAutoTest\\test\\conftest.py\", line 24, in data_clearing\n    DataClearing.backup_mysql()\n  File \"F:\\CODE\\python-test\\apiAutoTest\\tools\\data_clearing.py\", line 119, in backup_mysql\n    cls.server.files_action(0,\n  File \"F:\\CODE\\python-test\\apiAutoTest\\tools\\data_clearing.py\", line 77, in files_action\n    self.ftp_client.get(remotepath=remote_path, localpath=file_path)\n  File \"D:\\PythonCode\\apiAutoTest\\lib\\site-packages\\paramiko\\sftp_client.py\", line 801, in get\n    with open(localpath, \"wb\") as fl:\n"}, "start": 1641450133835, "stop": 1641450135079}, {"name": "data_clearing", "status": "broken", "statusDetails": {"message": "FileNotFoundError: [Errno 2] No such file or directory: '/home/chenlei/backup_sqls/apiautotest_2022-01-06T14_21_46.sql'\n", "trace": "  File \"D:\\PythonCode\\apiAutoTest\\lib\\site-packages\\pluggy\\callers.py\", line 187, in _multicall\n    res = hook_impl.function(*args)\n  File \"D:\\PythonCode\\apiAutoTest\\lib\\site-packages\\_pytest\\fixtures.py\", line 1117, in pytest_fixture_setup\n    result = call_fixture_func(fixturefunc, request, kwargs)\n  File \"D:\\PythonCode\\apiAutoTest\\lib\\site-packages\\_pytest\\fixtures.py\", line 915, in call_fixture_func\n    fixture_result = next(generator)\n  File \"F:\\CODE\\python-test\\apiAutoTest\\test\\conftest.py\", line 24, in data_clearing\n    DataClearing.backup_mysql()\n  File \"F:\\CODE\\python-test\\apiAutoTest\\tools\\data_clearing.py\", line 119, in backup_mysql\n    cls.server.files_action(0,\n  File \"F:\\CODE\\python-test\\apiAutoTest\\tools\\data_clearing.py\", line 77, in files_action\n    self.ftp_client.get(remotepath=remote_path, localpath=file_path)\n  File \"D:\\PythonCode\\apiAutoTest\\lib\\site-packages\\paramiko\\sftp_client.py\", line 801, in get\n    with open(localpath, \"wb\") as fl:\n"}, "start": 1641450136110, "stop": 1641450137282}, {"name": "data_clearing", "status": "broken", "statusDetails": {"message": "FileNotFoundError: [Errno 2] No such file or directory: '/home/chenlei/backup_sqls/apiautotest_2022-01-06T14_21_46.sql'\n", "trace": "  File \"D:\\PythonCode\\apiAutoTest\\lib\\site-packages\\pluggy\\callers.py\", line 187, in _multicall\n    res = hook_impl.function(*args)\n  File \"D:\\PythonCode\\apiAutoTest\\lib\\site-packages\\_pytest\\fixtures.py\", line 1117, in pytest_fixture_setup\n    result = call_fixture_func(fixturefunc, request, kwargs)\n  File \"D:\\PythonCode\\apiAutoTest\\lib\\site-packages\\_pytest\\fixtures.py\", line 915, in call_fixture_func\n    fixture_result = next(generator)\n  File \"F:\\CODE\\python-test\\apiAutoTest\\test\\conftest.py\", line 24, in data_clearing\n    DataClearing.backup_mysql()\n  File \"F:\\CODE\\python-test\\apiAutoTest\\tools\\data_clearing.py\", line 119, in backup_mysql\n    cls.server.files_action(0,\n  File \"F:\\CODE\\python-test\\apiAutoTest\\tools\\data_clearing.py\", line 77, in files_action\n    self.ftp_client.get(remotepath=remote_path, localpath=file_path)\n  File \"D:\\PythonCode\\apiAutoTest\\lib\\site-packages\\paramiko\\sftp_client.py\", line 801, in get\n    with open(localpath, \"wb\") as fl:\n"}, "start": 1641450138321, "stop": 1641450139590}, {"name": "data_clearing", "status": "broken", "statusDetails": {"message": "FileNotFoundError: [Errno 2] No such file or directory: '/home/chenlei/backup_sqls/apiautotest_2022-01-06T14_21_46.sql'\n", "trace": "  File \"D:\\PythonCode\\apiAutoTest\\lib\\site-packages\\pluggy\\callers.py\", line 187, in _multicall\n    res = hook_impl.function(*args)\n  File \"D:\\PythonCode\\apiAutoTest\\lib\\site-packages\\_pytest\\fixtures.py\", line 1117, in pytest_fixture_setup\n    result = call_fixture_func(fixturefunc, request, kwargs)\n  File \"D:\\PythonCode\\apiAutoTest\\lib\\site-packages\\_pytest\\fixtures.py\", line 915, in call_fixture_func\n    fixture_result = next(generator)\n  File \"F:\\CODE\\python-test\\apiAutoTest\\test\\conftest.py\", line 24, in data_clearing\n    DataClearing.backup_mysql()\n  File \"F:\\CODE\\python-test\\apiAutoTest\\tools\\data_clearing.py\", line 119, in backup_mysql\n    cls.server.files_action(0,\n  File \"F:\\CODE\\python-test\\apiAutoTest\\tools\\data_clearing.py\", line 77, in files_action\n    self.ftp_client.get(remotepath=remote_path, localpath=file_path)\n  File \"D:\\PythonCode\\apiAutoTest\\lib\\site-packages\\paramiko\\sftp_client.py\", line 801, in get\n    with open(localpath, \"wb\") as fl:\n"}, "start": 1641450140614, "stop": 1641450141947}, {"name": "data_clearing", "status": "broken", "statusDetails": {"message": "FileNotFoundError: [Errno 2] No such file or directory: '/home/chenlei/backup_sqls/apiautotest_2022-01-06T14_21_46.sql'\n", "trace": "  File \"D:\\PythonCode\\apiAutoTest\\lib\\site-packages\\pluggy\\callers.py\", line 187, in _multicall\n    res = hook_impl.function(*args)\n  File \"D:\\PythonCode\\apiAutoTest\\lib\\site-packages\\_pytest\\fixtures.py\", line 1117, in pytest_fixture_setup\n    result = call_fixture_func(fixturefunc, request, kwargs)\n  File \"D:\\PythonCode\\apiAutoTest\\lib\\site-packages\\_pytest\\fixtures.py\", line 915, in call_fixture_func\n    fixture_result = next(generator)\n  File \"F:\\CODE\\python-test\\apiAutoTest\\test\\conftest.py\", line 24, in data_clearing\n    DataClearing.backup_mysql()\n  File \"F:\\CODE\\python-test\\apiAutoTest\\tools\\data_clearing.py\", line 119, in backup_mysql\n    cls.server.files_action(0,\n  File \"F:\\CODE\\python-test\\apiAutoTest\\tools\\data_clearing.py\", line 77, in files_action\n    self.ftp_client.get(remotepath=remote_path, localpath=file_path)\n  File \"D:\\PythonCode\\apiAutoTest\\lib\\site-packages\\paramiko\\sftp_client.py\", line 801, in get\n    with open(localpath, \"wb\") as fl:\n"}, "start": 1641450142991, "stop": 1641450144142}, {"name": "data_clearing", "status": "broken", "statusDetails": {"message": "FileNotFoundError: [Errno 2] No such file or directory: '/home/chenlei/backup_sqls/apiautotest_2022-01-06T14_21_46.sql'\n", "trace": "  File \"D:\\PythonCode\\apiAutoTest\\lib\\site-packages\\pluggy\\callers.py\", line 187, in _multicall\n    res = hook_impl.function(*args)\n  File \"D:\\PythonCode\\apiAutoTest\\lib\\site-packages\\_pytest\\fixtures.py\", line 1117, in pytest_fixture_setup\n    result = call_fixture_func(fixturefunc, request, kwargs)\n  File \"D:\\PythonCode\\apiAutoTest\\lib\\site-packages\\_pytest\\fixtures.py\", line 915, in call_fixture_func\n    fixture_result = next(generator)\n  File \"F:\\CODE\\python-test\\apiAutoTest\\test\\conftest.py\", line 24, in data_clearing\n    DataClearing.backup_mysql()\n  File \"F:\\CODE\\python-test\\apiAutoTest\\tools\\data_clearing.py\", line 119, in backup_mysql\n    cls.server.files_action(0,\n  File \"F:\\CODE\\python-test\\apiAutoTest\\tools\\data_clearing.py\", line 77, in files_action\n    self.ftp_client.get(remotepath=remote_path, localpath=file_path)\n  File \"D:\\PythonCode\\apiAutoTest\\lib\\site-packages\\paramiko\\sftp_client.py\", line 801, in get\n    with open(localpath, \"wb\") as fl:\n"}, "start": 1641450145165, "stop": 1641450146218}, {"name": "data_clearing", "status": "broken", "statusDetails": {"message": "FileNotFoundError: [Errno 2] No such file or directory: '/home/chenlei/backup_sqls/apiautotest_2022-01-06T14_21_46.sql'\n", "trace": "  File \"D:\\PythonCode\\apiAutoTest\\lib\\site-packages\\pluggy\\callers.py\", line 187, in _multicall\n    res = hook_impl.function(*args)\n  File \"D:\\PythonCode\\apiAutoTest\\lib\\site-packages\\_pytest\\fixtures.py\", line 1117, in pytest_fixture_setup\n    result = call_fixture_func(fixturefunc, request, kwargs)\n  File \"D:\\PythonCode\\apiAutoTest\\lib\\site-packages\\_pytest\\fixtures.py\", line 915, in call_fixture_func\n    fixture_result = next(generator)\n  File \"F:\\CODE\\python-test\\apiAutoTest\\test\\conftest.py\", line 24, in data_clearing\n    DataClearing.backup_mysql()\n  File \"F:\\CODE\\python-test\\apiAutoTest\\tools\\data_clearing.py\", line 119, in backup_mysql\n    cls.server.files_action(0,\n  File \"F:\\CODE\\python-test\\apiAutoTest\\tools\\data_clearing.py\", line 77, in files_action\n    self.ftp_client.get(remotepath=remote_path, localpath=file_path)\n  File \"D:\\PythonCode\\apiAutoTest\\lib\\site-packages\\paramiko\\sftp_client.py\", line 801, in get\n    with open(localpath, \"wb\") as fl:\n"}, "start": 1641450147252, "stop": 1641450148412}, {"name": "data_clearing", "status": "broken", "statusDetails": {"message": "FileNotFoundError: [Errno 2] No such file or directory: '/home/chenlei/backup_sqls/apiautotest_2022-01-06T14_21_46.sql'\n", "trace": "  File \"D:\\PythonCode\\apiAutoTest\\lib\\site-packages\\pluggy\\callers.py\", line 187, in _multicall\n    res = hook_impl.function(*args)\n  File \"D:\\PythonCode\\apiAutoTest\\lib\\site-packages\\_pytest\\fixtures.py\", line 1117, in pytest_fixture_setup\n    result = call_fixture_func(fixturefunc, request, kwargs)\n  File \"D:\\PythonCode\\apiAutoTest\\lib\\site-packages\\_pytest\\fixtures.py\", line 915, in call_fixture_func\n    fixture_result = next(generator)\n  File \"F:\\CODE\\python-test\\apiAutoTest\\test\\conftest.py\", line 24, in data_clearing\n    DataClearing.backup_mysql()\n  File \"F:\\CODE\\python-test\\apiAutoTest\\tools\\data_clearing.py\", line 119, in backup_mysql\n    cls.server.files_action(0,\n  File \"F:\\CODE\\python-test\\apiAutoTest\\tools\\data_clearing.py\", line 77, in files_action\n    self.ftp_client.get(remotepath=remote_path, localpath=file_path)\n  File \"D:\\PythonCode\\apiAutoTest\\lib\\site-packages\\paramiko\\sftp_client.py\", line 801, in get\n    with open(localpath, \"wb\") as fl:\n"}, "start": 1641450149446, "stop": 1641450150471}, {"name": "data_clearing", "status": "broken", "statusDetails": {"message": "FileNotFoundError: [Errno 2] No such file or directory: '/home/chenlei/backup_sqls/apiautotest_2022-01-06T14_21_46.sql'\n", "trace": "  File \"D:\\PythonCode\\apiAutoTest\\lib\\site-packages\\pluggy\\callers.py\", line 187, in _multicall\n    res = hook_impl.function(*args)\n  File \"D:\\PythonCode\\apiAutoTest\\lib\\site-packages\\_pytest\\fixtures.py\", line 1117, in pytest_fixture_setup\n    result = call_fixture_func(fixturefunc, request, kwargs)\n  File \"D:\\PythonCode\\apiAutoTest\\lib\\site-packages\\_pytest\\fixtures.py\", line 915, in call_fixture_func\n    fixture_result = next(generator)\n  File \"F:\\CODE\\python-test\\apiAutoTest\\test\\conftest.py\", line 24, in data_clearing\n    DataClearing.backup_mysql()\n  File \"F:\\CODE\\python-test\\apiAutoTest\\tools\\data_clearing.py\", line 119, in backup_mysql\n    cls.server.files_action(0,\n  File \"F:\\CODE\\python-test\\apiAutoTest\\tools\\data_clearing.py\", line 77, in files_action\n    self.ftp_client.get(remotepath=remote_path, localpath=file_path)\n  File \"D:\\PythonCode\\apiAutoTest\\lib\\site-packages\\paramiko\\sftp_client.py\", line 801, in get\n    with open(localpath, \"wb\") as fl:\n"}, "start": 1641450151505, "stop": 1641450152945}, {"name": "data_clearing", "status": "broken", "statusDetails": {"message": "FileNotFoundError: [Errno 2] No such file or directory: '/home/chenlei/backup_sqls/apiautotest_2022-01-06T14_21_46.sql'\n", "trace": "  File \"D:\\PythonCode\\apiAutoTest\\lib\\site-packages\\pluggy\\callers.py\", line 187, in _multicall\n    res = hook_impl.function(*args)\n  File \"D:\\PythonCode\\apiAutoTest\\lib\\site-packages\\_pytest\\fixtures.py\", line 1117, in pytest_fixture_setup\n    result = call_fixture_func(fixturefunc, request, kwargs)\n  File \"D:\\PythonCode\\apiAutoTest\\lib\\site-packages\\_pytest\\fixtures.py\", line 915, in call_fixture_func\n    fixture_result = next(generator)\n  File \"F:\\CODE\\python-test\\apiAutoTest\\test\\conftest.py\", line 24, in data_clearing\n    DataClearing.backup_mysql()\n  File \"F:\\CODE\\python-test\\apiAutoTest\\tools\\data_clearing.py\", line 119, in backup_mysql\n    cls.server.files_action(0,\n  File \"F:\\CODE\\python-test\\apiAutoTest\\tools\\data_clearing.py\", line 77, in files_action\n    self.ftp_client.get(remotepath=remote_path, localpath=file_path)\n  File \"D:\\PythonCode\\apiAutoTest\\lib\\site-packages\\paramiko\\sftp_client.py\", line 801, in get\n    with open(localpath, \"wb\") as fl:\n"}, "start": 1641450153963, "stop": 1641450155182}, {"name": "data_clearing", "status": "broken", "statusDetails": {"message": "FileNotFoundError: [Errno 2] No such file or directory: '/home/chenlei/backup_sqls/apiautotest_2022-01-06T14_21_46.sql'\n", "trace": "  File \"D:\\PythonCode\\apiAutoTest\\lib\\site-packages\\pluggy\\callers.py\", line 187, in _multicall\n    res = hook_impl.function(*args)\n  File \"D:\\PythonCode\\apiAutoTest\\lib\\site-packages\\_pytest\\fixtures.py\", line 1117, in pytest_fixture_setup\n    result = call_fixture_func(fixturefunc, request, kwargs)\n  File \"D:\\PythonCode\\apiAutoTest\\lib\\site-packages\\_pytest\\fixtures.py\", line 915, in call_fixture_func\n    fixture_result = next(generator)\n  File \"F:\\CODE\\python-test\\apiAutoTest\\test\\conftest.py\", line 24, in data_clearing\n    DataClearing.backup_mysql()\n  File \"F:\\CODE\\python-test\\apiAutoTest\\tools\\data_clearing.py\", line 119, in backup_mysql\n    cls.server.files_action(0,\n  File \"F:\\CODE\\python-test\\apiAutoTest\\tools\\data_clearing.py\", line 77, in files_action\n    self.ftp_client.get(remotepath=remote_path, localpath=file_path)\n  File \"D:\\PythonCode\\apiAutoTest\\lib\\site-packages\\paramiko\\sftp_client.py\", line 801, in get\n    with open(localpath, \"wb\") as fl:\n"}, "start": 1641450156219, "stop": 1641450157501}, {"name": "data_clearing", "status": "broken", "statusDetails": {"message": "FileNotFoundError: [Errno 2] No such file or directory: '/home/chenlei/backup_sqls/apiautotest_2022-01-06T14_21_46.sql'\n", "trace": "  File \"D:\\PythonCode\\apiAutoTest\\lib\\site-packages\\pluggy\\callers.py\", line 187, in _multicall\n    res = hook_impl.function(*args)\n  File \"D:\\PythonCode\\apiAutoTest\\lib\\site-packages\\_pytest\\fixtures.py\", line 1117, in pytest_fixture_setup\n    result = call_fixture_func(fixturefunc, request, kwargs)\n  File \"D:\\PythonCode\\apiAutoTest\\lib\\site-packages\\_pytest\\fixtures.py\", line 915, in call_fixture_func\n    fixture_result = next(generator)\n  File \"F:\\CODE\\python-test\\apiAutoTest\\test\\conftest.py\", line 24, in data_clearing\n    DataClearing.backup_mysql()\n  File \"F:\\CODE\\python-test\\apiAutoTest\\tools\\data_clearing.py\", line 119, in backup_mysql\n    cls.server.files_action(0,\n  File \"F:\\CODE\\python-test\\apiAutoTest\\tools\\data_clearing.py\", line 77, in files_action\n    self.ftp_client.get(remotepath=remote_path, localpath=file_path)\n  File \"D:\\PythonCode\\apiAutoTest\\lib\\site-packages\\paramiko\\sftp_client.py\", line 801, in get\n    with open(localpath, \"wb\") as fl:\n"}, "start": 1641450158525, "stop": 1641450159578}, {"name": "data_clearing", "status": "broken", "statusDetails": {"message": "FileNotFoundError: [Errno 2] No such file or directory: '/home/chenlei/backup_sqls/apiautotest_2022-01-06T14_21_46.sql'\n", "trace": "  File \"D:\\PythonCode\\apiAutoTest\\lib\\site-packages\\pluggy\\callers.py\", line 187, in _multicall\n    res = hook_impl.function(*args)\n  File \"D:\\PythonCode\\apiAutoTest\\lib\\site-packages\\_pytest\\fixtures.py\", line 1117, in pytest_fixture_setup\n    result = call_fixture_func(fixturefunc, request, kwargs)\n  File \"D:\\PythonCode\\apiAutoTest\\lib\\site-packages\\_pytest\\fixtures.py\", line 915, in call_fixture_func\n    fixture_result = next(generator)\n  File \"F:\\CODE\\python-test\\apiAutoTest\\test\\conftest.py\", line 24, in data_clearing\n    DataClearing.backup_mysql()\n  File \"F:\\CODE\\python-test\\apiAutoTest\\tools\\data_clearing.py\", line 119, in backup_mysql\n    cls.server.files_action(0,\n  File \"F:\\CODE\\python-test\\apiAutoTest\\tools\\data_clearing.py\", line 77, in files_action\n    self.ftp_client.get(remotepath=remote_path, localpath=file_path)\n  File \"D:\\PythonCode\\apiAutoTest\\lib\\site-packages\\paramiko\\sftp_client.py\", line 801, in get\n    with open(localpath, \"wb\") as fl:\n"}, "start": 1641450160612, "stop": 1641450161975}, {"name": "data_clearing", "status": "broken", "statusDetails": {"message": "FileNotFoundError: [Errno 2] No such file or directory: '/home/chenlei/backup_sqls/apiautotest_2022-01-06T14_21_46.sql'\n", "trace": "  File \"D:\\PythonCode\\apiAutoTest\\lib\\site-packages\\pluggy\\callers.py\", line 187, in _multicall\n    res = hook_impl.function(*args)\n  File \"D:\\PythonCode\\apiAutoTest\\lib\\site-packages\\_pytest\\fixtures.py\", line 1117, in pytest_fixture_setup\n    result = call_fixture_func(fixturefunc, request, kwargs)\n  File \"D:\\PythonCode\\apiAutoTest\\lib\\site-packages\\_pytest\\fixtures.py\", line 915, in call_fixture_func\n    fixture_result = next(generator)\n  File \"F:\\CODE\\python-test\\apiAutoTest\\test\\conftest.py\", line 24, in data_clearing\n    DataClearing.backup_mysql()\n  File \"F:\\CODE\\python-test\\apiAutoTest\\tools\\data_clearing.py\", line 119, in backup_mysql\n    cls.server.files_action(0,\n  File \"F:\\CODE\\python-test\\apiAutoTest\\tools\\data_clearing.py\", line 77, in files_action\n    self.ftp_client.get(remotepath=remote_path, localpath=file_path)\n  File \"D:\\PythonCode\\apiAutoTest\\lib\\site-packages\\paramiko\\sftp_client.py\", line 801, in get\n    with open(localpath, \"wb\") as fl:\n"}, "start": 1641450163003, "stop": 1641450164425}, {"name": "data_clearing", "status": "broken", "statusDetails": {"message": "FileNotFoundError: [Errno 2] No such file or directory: '/home/chenlei/backup_sqls/apiautotest_2022-01-06T14_21_46.sql'\n", "trace": "  File \"D:\\PythonCode\\apiAutoTest\\lib\\site-packages\\pluggy\\callers.py\", line 187, in _multicall\n    res = hook_impl.function(*args)\n  File \"D:\\PythonCode\\apiAutoTest\\lib\\site-packages\\_pytest\\fixtures.py\", line 1117, in pytest_fixture_setup\n    result = call_fixture_func(fixturefunc, request, kwargs)\n  File \"D:\\PythonCode\\apiAutoTest\\lib\\site-packages\\_pytest\\fixtures.py\", line 915, in call_fixture_func\n    fixture_result = next(generator)\n  File \"F:\\CODE\\python-test\\apiAutoTest\\test\\conftest.py\", line 24, in data_clearing\n    DataClearing.backup_mysql()\n  File \"F:\\CODE\\python-test\\apiAutoTest\\tools\\data_clearing.py\", line 119, in backup_mysql\n    cls.server.files_action(0,\n  File \"F:\\CODE\\python-test\\apiAutoTest\\tools\\data_clearing.py\", line 77, in files_action\n    self.ftp_client.get(remotepath=remote_path, localpath=file_path)\n  File \"D:\\PythonCode\\apiAutoTest\\lib\\site-packages\\paramiko\\sftp_client.py\", line 801, in get\n    with open(localpath, \"wb\") as fl:\n"}, "start": 1641450165460, "stop": 1641450166940}, {"name": "data_clearing", "status": "broken", "statusDetails": {"message": "FileNotFoundError: [Errno 2] No such file or directory: '/home/chenlei/backup_sqls/apiautotest_2022-01-06T14_21_46.sql'\n", "trace": "  File \"D:\\PythonCode\\apiAutoTest\\lib\\site-packages\\pluggy\\callers.py\", line 187, in _multicall\n    res = hook_impl.function(*args)\n  File \"D:\\PythonCode\\apiAutoTest\\lib\\site-packages\\_pytest\\fixtures.py\", line 1117, in pytest_fixture_setup\n    result = call_fixture_func(fixturefunc, request, kwargs)\n  File \"D:\\PythonCode\\apiAutoTest\\lib\\site-packages\\_pytest\\fixtures.py\", line 915, in call_fixture_func\n    fixture_result = next(generator)\n  File \"F:\\CODE\\python-test\\apiAutoTest\\test\\conftest.py\", line 24, in data_clearing\n    DataClearing.backup_mysql()\n  File \"F:\\CODE\\python-test\\apiAutoTest\\tools\\data_clearing.py\", line 119, in backup_mysql\n    cls.server.files_action(0,\n  File \"F:\\CODE\\python-test\\apiAutoTest\\tools\\data_clearing.py\", line 77, in files_action\n    self.ftp_client.get(remotepath=remote_path, localpath=file_path)\n  File \"D:\\PythonCode\\apiAutoTest\\lib\\site-packages\\paramiko\\sftp_client.py\", line 801, in get\n    with open(localpath, \"wb\") as fl:\n"}, "start": 1641450167970, "stop": 1641450169161}, {"name": "data_clearing", "status": "broken", "statusDetails": {"message": "FileNotFoundError: [Errno 2] No such file or directory: '/home/chenlei/backup_sqls/apiautotest_2022-01-06T14_21_46.sql'\n", "trace": "  File \"D:\\PythonCode\\apiAutoTest\\lib\\site-packages\\pluggy\\callers.py\", line 187, in _multicall\n    res = hook_impl.function(*args)\n  File \"D:\\PythonCode\\apiAutoTest\\lib\\site-packages\\_pytest\\fixtures.py\", line 1117, in pytest_fixture_setup\n    result = call_fixture_func(fixturefunc, request, kwargs)\n  File \"D:\\PythonCode\\apiAutoTest\\lib\\site-packages\\_pytest\\fixtures.py\", line 915, in call_fixture_func\n    fixture_result = next(generator)\n  File \"F:\\CODE\\python-test\\apiAutoTest\\test\\conftest.py\", line 24, in data_clearing\n    DataClearing.backup_mysql()\n  File \"F:\\CODE\\python-test\\apiAutoTest\\tools\\data_clearing.py\", line 119, in backup_mysql\n    cls.server.files_action(0,\n  File \"F:\\CODE\\python-test\\apiAutoTest\\tools\\data_clearing.py\", line 77, in files_action\n    self.ftp_client.get(remotepath=remote_path, localpath=file_path)\n  File \"D:\\PythonCode\\apiAutoTest\\lib\\site-packages\\paramiko\\sftp_client.py\", line 801, in get\n    with open(localpath, \"wb\") as fl:\n"}, "start": 1641450170202, "stop": 1641450171644}, {"name": "data_clearing", "status": "broken", "statusDetails": {"message": "FileNotFoundError: [Errno 2] No such file or directory: '/home/chenlei/backup_sqls/apiautotest_2022-01-06T14_21_46.sql'\n", "trace": "  File \"D:\\PythonCode\\apiAutoTest\\lib\\site-packages\\pluggy\\callers.py\", line 187, in _multicall\n    res = hook_impl.function(*args)\n  File \"D:\\PythonCode\\apiAutoTest\\lib\\site-packages\\_pytest\\fixtures.py\", line 1117, in pytest_fixture_setup\n    result = call_fixture_func(fixturefunc, request, kwargs)\n  File \"D:\\PythonCode\\apiAutoTest\\lib\\site-packages\\_pytest\\fixtures.py\", line 915, in call_fixture_func\n    fixture_result = next(generator)\n  File \"F:\\CODE\\python-test\\apiAutoTest\\test\\conftest.py\", line 24, in data_clearing\n    DataClearing.backup_mysql()\n  File \"F:\\CODE\\python-test\\apiAutoTest\\tools\\data_clearing.py\", line 119, in backup_mysql\n    cls.server.files_action(0,\n  File \"F:\\CODE\\python-test\\apiAutoTest\\tools\\data_clearing.py\", line 77, in files_action\n    self.ftp_client.get(remotepath=remote_path, localpath=file_path)\n  File \"D:\\PythonCode\\apiAutoTest\\lib\\site-packages\\paramiko\\sftp_client.py\", line 801, in get\n    with open(localpath, \"wb\") as fl:\n"}, "start": 1641450172681, "stop": 1641450173962}, {"name": "data_clearing", "status": "broken", "statusDetails": {"message": "FileNotFoundError: [Errno 2] No such file or directory: '/home/chenlei/backup_sqls/apiautotest_2022-01-06T14_21_46.sql'\n", "trace": "  File \"D:\\PythonCode\\apiAutoTest\\lib\\site-packages\\pluggy\\callers.py\", line 187, in _multicall\n    res = hook_impl.function(*args)\n  File \"D:\\PythonCode\\apiAutoTest\\lib\\site-packages\\_pytest\\fixtures.py\", line 1117, in pytest_fixture_setup\n    result = call_fixture_func(fixturefunc, request, kwargs)\n  File \"D:\\PythonCode\\apiAutoTest\\lib\\site-packages\\_pytest\\fixtures.py\", line 915, in call_fixture_func\n    fixture_result = next(generator)\n  File \"F:\\CODE\\python-test\\apiAutoTest\\test\\conftest.py\", line 24, in data_clearing\n    DataClearing.backup_mysql()\n  File \"F:\\CODE\\python-test\\apiAutoTest\\tools\\data_clearing.py\", line 119, in backup_mysql\n    cls.server.files_action(0,\n  File \"F:\\CODE\\python-test\\apiAutoTest\\tools\\data_clearing.py\", line 77, in files_action\n    self.ftp_client.get(remotepath=remote_path, localpath=file_path)\n  File \"D:\\PythonCode\\apiAutoTest\\lib\\site-packages\\paramiko\\sftp_client.py\", line 801, in get\n    with open(localpath, \"wb\") as fl:\n"}, "start": 1641450175002, "stop": 1641450176103}, {"name": "data_clearing", "status": "broken", "statusDetails": {"message": "FileNotFoundError: [Errno 2] No such file or directory: '/home/chenlei/backup_sqls/apiautotest_2022-01-06T14_21_46.sql'\n", "trace": "  File \"D:\\PythonCode\\apiAutoTest\\lib\\site-packages\\pluggy\\callers.py\", line 187, in _multicall\n    res = hook_impl.function(*args)\n  File \"D:\\PythonCode\\apiAutoTest\\lib\\site-packages\\_pytest\\fixtures.py\", line 1117, in pytest_fixture_setup\n    result = call_fixture_func(fixturefunc, request, kwargs)\n  File \"D:\\PythonCode\\apiAutoTest\\lib\\site-packages\\_pytest\\fixtures.py\", line 915, in call_fixture_func\n    fixture_result = next(generator)\n  File \"F:\\CODE\\python-test\\apiAutoTest\\test\\conftest.py\", line 24, in data_clearing\n    DataClearing.backup_mysql()\n  File \"F:\\CODE\\python-test\\apiAutoTest\\tools\\data_clearing.py\", line 119, in backup_mysql\n    cls.server.files_action(0,\n  File \"F:\\CODE\\python-test\\apiAutoTest\\tools\\data_clearing.py\", line 77, in files_action\n    self.ftp_client.get(remotepath=remote_path, localpath=file_path)\n  File \"D:\\PythonCode\\apiAutoTest\\lib\\site-packages\\paramiko\\sftp_client.py\", line 801, in get\n    with open(localpath, \"wb\") as fl:\n"}, "start": 1641450177123, "stop": 1641450178354}, {"name": "data_clearing", "status": "broken", "statusDetails": {"message": "FileNotFoundError: [Errno 2] No such file or directory: '/home/chenlei/backup_sqls/apiautotest_2022-01-06T14_21_46.sql'\n", "trace": "  File \"D:\\PythonCode\\apiAutoTest\\lib\\site-packages\\pluggy\\callers.py\", line 187, in _multicall\n    res = hook_impl.function(*args)\n  File \"D:\\PythonCode\\apiAutoTest\\lib\\site-packages\\_pytest\\fixtures.py\", line 1117, in pytest_fixture_setup\n    result = call_fixture_func(fixturefunc, request, kwargs)\n  File \"D:\\PythonCode\\apiAutoTest\\lib\\site-packages\\_pytest\\fixtures.py\", line 915, in call_fixture_func\n    fixture_result = next(generator)\n  File \"F:\\CODE\\python-test\\apiAutoTest\\test\\conftest.py\", line 24, in data_clearing\n    DataClearing.backup_mysql()\n  File \"F:\\CODE\\python-test\\apiAutoTest\\tools\\data_clearing.py\", line 119, in backup_mysql\n    cls.server.files_action(0,\n  File \"F:\\CODE\\python-test\\apiAutoTest\\tools\\data_clearing.py\", line 77, in files_action\n    self.ftp_client.get(remotepath=remote_path, localpath=file_path)\n  File \"D:\\PythonCode\\apiAutoTest\\lib\\site-packages\\paramiko\\sftp_client.py\", line 801, in get\n    with open(localpath, \"wb\") as fl:\n"}, "start": 1641450179390, "stop": 1641450180951}, {"name": "data_clearing", "status": "broken", "statusDetails": {"message": "FileNotFoundError: [Errno 2] No such file or directory: '/home/chenlei/backup_sqls/apiautotest_2022-01-06T14_21_46.sql'\n", "trace": "  File \"D:\\PythonCode\\apiAutoTest\\lib\\site-packages\\pluggy\\callers.py\", line 187, in _multicall\n    res = hook_impl.function(*args)\n  File \"D:\\PythonCode\\apiAutoTest\\lib\\site-packages\\_pytest\\fixtures.py\", line 1117, in pytest_fixture_setup\n    result = call_fixture_func(fixturefunc, request, kwargs)\n  File \"D:\\PythonCode\\apiAutoTest\\lib\\site-packages\\_pytest\\fixtures.py\", line 915, in call_fixture_func\n    fixture_result = next(generator)\n  File \"F:\\CODE\\python-test\\apiAutoTest\\test\\conftest.py\", line 24, in data_clearing\n    DataClearing.backup_mysql()\n  File \"F:\\CODE\\python-test\\apiAutoTest\\tools\\data_clearing.py\", line 119, in backup_mysql\n    cls.server.files_action(0,\n  File \"F:\\CODE\\python-test\\apiAutoTest\\tools\\data_clearing.py\", line 77, in files_action\n    self.ftp_client.get(remotepath=remote_path, localpath=file_path)\n  File \"D:\\PythonCode\\apiAutoTest\\lib\\site-packages\\paramiko\\sftp_client.py\", line 801, in get\n    with open(localpath, \"wb\") as fl:\n"}, "start": 1641450181982, "stop": 1641450183196}, {"name": "data_clearing", "status": "broken", "statusDetails": {"message": "FileNotFoundError: [Errno 2] No such file or directory: '/home/chenlei/backup_sqls/apiautotest_2022-01-06T14_21_46.sql'\n", "trace": "  File \"D:\\PythonCode\\apiAutoTest\\lib\\site-packages\\pluggy\\callers.py\", line 187, in _multicall\n    res = hook_impl.function(*args)\n  File \"D:\\PythonCode\\apiAutoTest\\lib\\site-packages\\_pytest\\fixtures.py\", line 1117, in pytest_fixture_setup\n    result = call_fixture_func(fixturefunc, request, kwargs)\n  File \"D:\\PythonCode\\apiAutoTest\\lib\\site-packages\\_pytest\\fixtures.py\", line 915, in call_fixture_func\n    fixture_result = next(generator)\n  File \"F:\\CODE\\python-test\\apiAutoTest\\test\\conftest.py\", line 24, in data_clearing\n    DataClearing.backup_mysql()\n  File \"F:\\CODE\\python-test\\apiAutoTest\\tools\\data_clearing.py\", line 119, in backup_mysql\n    cls.server.files_action(0,\n  File \"F:\\CODE\\python-test\\apiAutoTest\\tools\\data_clearing.py\", line 77, in files_action\n    self.ftp_client.get(remotepath=remote_path, localpath=file_path)\n  File \"D:\\PythonCode\\apiAutoTest\\lib\\site-packages\\paramiko\\sftp_client.py\", line 801, in get\n    with open(localpath, \"wb\") as fl:\n"}, "start": 1641450184239, "stop": 1641450185506}, {"name": "data_clearing", "status": "broken", "statusDetails": {"message": "FileNotFoundError: [Errno 2] No such file or directory: '/home/chenlei/backup_sqls/apiautotest_2022-01-06T14_21_46.sql'\n", "trace": "  File \"D:\\PythonCode\\apiAutoTest\\lib\\site-packages\\pluggy\\callers.py\", line 187, in _multicall\n    res = hook_impl.function(*args)\n  File \"D:\\PythonCode\\apiAutoTest\\lib\\site-packages\\_pytest\\fixtures.py\", line 1117, in pytest_fixture_setup\n    result = call_fixture_func(fixturefunc, request, kwargs)\n  File \"D:\\PythonCode\\apiAutoTest\\lib\\site-packages\\_pytest\\fixtures.py\", line 915, in call_fixture_func\n    fixture_result = next(generator)\n  File \"F:\\CODE\\python-test\\apiAutoTest\\test\\conftest.py\", line 24, in data_clearing\n    DataClearing.backup_mysql()\n  File \"F:\\CODE\\python-test\\apiAutoTest\\tools\\data_clearing.py\", line 119, in backup_mysql\n    cls.server.files_action(0,\n  File \"F:\\CODE\\python-test\\apiAutoTest\\tools\\data_clearing.py\", line 77, in files_action\n    self.ftp_client.get(remotepath=remote_path, localpath=file_path)\n  File \"D:\\PythonCode\\apiAutoTest\\lib\\site-packages\\paramiko\\sftp_client.py\", line 801, in get\n    with open(localpath, \"wb\") as fl:\n"}, "start": 1641450186532, "stop": 1641450187662}, {"name": "data_clearing", "status": "broken", "statusDetails": {"message": "FileNotFoundError: [Errno 2] No such file or directory: '/home/chenlei/backup_sqls/apiautotest_2022-01-06T14_21_46.sql'\n", "trace": "  File \"D:\\PythonCode\\apiAutoTest\\lib\\site-packages\\pluggy\\callers.py\", line 187, in _multicall\n    res = hook_impl.function(*args)\n  File \"D:\\PythonCode\\apiAutoTest\\lib\\site-packages\\_pytest\\fixtures.py\", line 1117, in pytest_fixture_setup\n    result = call_fixture_func(fixturefunc, request, kwargs)\n  File \"D:\\PythonCode\\apiAutoTest\\lib\\site-packages\\_pytest\\fixtures.py\", line 915, in call_fixture_func\n    fixture_result = next(generator)\n  File \"F:\\CODE\\python-test\\apiAutoTest\\test\\conftest.py\", line 24, in data_clearing\n    DataClearing.backup_mysql()\n  File \"F:\\CODE\\python-test\\apiAutoTest\\tools\\data_clearing.py\", line 119, in backup_mysql\n    cls.server.files_action(0,\n  File \"F:\\CODE\\python-test\\apiAutoTest\\tools\\data_clearing.py\", line 77, in files_action\n    self.ftp_client.get(remotepath=remote_path, localpath=file_path)\n  File \"D:\\PythonCode\\apiAutoTest\\lib\\site-packages\\paramiko\\sftp_client.py\", line 801, in get\n    with open(localpath, \"wb\") as fl:\n"}, "start": 1641450188697, "stop": 1641450190113}, {"name": "data_clearing", "status": "broken", "statusDetails": {"message": "FileNotFoundError: [Errno 2] No such file or directory: '/home/chenlei/backup_sqls/apiautotest_2022-01-06T14_21_46.sql'\n", "trace": "  File \"D:\\PythonCode\\apiAutoTest\\lib\\site-packages\\pluggy\\callers.py\", line 187, in _multicall\n    res = hook_impl.function(*args)\n  File \"D:\\PythonCode\\apiAutoTest\\lib\\site-packages\\_pytest\\fixtures.py\", line 1117, in pytest_fixture_setup\n    result = call_fixture_func(fixturefunc, request, kwargs)\n  File \"D:\\PythonCode\\apiAutoTest\\lib\\site-packages\\_pytest\\fixtures.py\", line 915, in call_fixture_func\n    fixture_result = next(generator)\n  File \"F:\\CODE\\python-test\\apiAutoTest\\test\\conftest.py\", line 24, in data_clearing\n    DataClearing.backup_mysql()\n  File \"F:\\CODE\\python-test\\apiAutoTest\\tools\\data_clearing.py\", line 119, in backup_mysql\n    cls.server.files_action(0,\n  File \"F:\\CODE\\python-test\\apiAutoTest\\tools\\data_clearing.py\", line 77, in files_action\n    self.ftp_client.get(remotepath=remote_path, localpath=file_path)\n  File \"D:\\PythonCode\\apiAutoTest\\lib\\site-packages\\paramiko\\sftp_client.py\", line 801, in get\n    with open(localpath, \"wb\") as fl:\n"}, "start": 1641450191143, "stop": 1641450192779}, {"name": "data_clearing", "status": "broken", "statusDetails": {"message": "FileNotFoundError: [Errno 2] No such file or directory: '/home/chenlei/backup_sqls/apiautotest_2022-01-06T14_21_46.sql'\n", "trace": "  File \"D:\\PythonCode\\apiAutoTest\\lib\\site-packages\\pluggy\\callers.py\", line 187, in _multicall\n    res = hook_impl.function(*args)\n  File \"D:\\PythonCode\\apiAutoTest\\lib\\site-packages\\_pytest\\fixtures.py\", line 1117, in pytest_fixture_setup\n    result = call_fixture_func(fixturefunc, request, kwargs)\n  File \"D:\\PythonCode\\apiAutoTest\\lib\\site-packages\\_pytest\\fixtures.py\", line 915, in call_fixture_func\n    fixture_result = next(generator)\n  File \"F:\\CODE\\python-test\\apiAutoTest\\test\\conftest.py\", line 24, in data_clearing\n    DataClearing.backup_mysql()\n  File \"F:\\CODE\\python-test\\apiAutoTest\\tools\\data_clearing.py\", line 119, in backup_mysql\n    cls.server.files_action(0,\n  File \"F:\\CODE\\python-test\\apiAutoTest\\tools\\data_clearing.py\", line 77, in files_action\n    self.ftp_client.get(remotepath=remote_path, localpath=file_path)\n  File \"D:\\PythonCode\\apiAutoTest\\lib\\site-packages\\paramiko\\sftp_client.py\", line 801, in get\n    with open(localpath, \"wb\") as fl:\n"}, "start": 1641450193814, "stop": 1641450195099}, {"name": "data_clearing", "status": "broken", "statusDetails": {"message": "FileNotFoundError: [Errno 2] No such file or directory: '/home/chenlei/backup_sqls/apiautotest_2022-01-06T14_21_46.sql'\n", "trace": "  File \"D:\\PythonCode\\apiAutoTest\\lib\\site-packages\\pluggy\\callers.py\", line 187, in _multicall\n    res = hook_impl.function(*args)\n  File \"D:\\PythonCode\\apiAutoTest\\lib\\site-packages\\_pytest\\fixtures.py\", line 1117, in pytest_fixture_setup\n    result = call_fixture_func(fixturefunc, request, kwargs)\n  File \"D:\\PythonCode\\apiAutoTest\\lib\\site-packages\\_pytest\\fixtures.py\", line 915, in call_fixture_func\n    fixture_result = next(generator)\n  File \"F:\\CODE\\python-test\\apiAutoTest\\test\\conftest.py\", line 24, in data_clearing\n    DataClearing.backup_mysql()\n  File \"F:\\CODE\\python-test\\apiAutoTest\\tools\\data_clearing.py\", line 119, in backup_mysql\n    cls.server.files_action(0,\n  File \"F:\\CODE\\python-test\\apiAutoTest\\tools\\data_clearing.py\", line 77, in files_action\n    self.ftp_client.get(remotepath=remote_path, localpath=file_path)\n  File \"D:\\PythonCode\\apiAutoTest\\lib\\site-packages\\paramiko\\sftp_client.py\", line 801, in get\n    with open(localpath, \"wb\") as fl:\n"}, "start": 1641450196137, "stop": 1641450197283}, {"name": "data_clearing", "status": "broken", "statusDetails": {"message": "FileNotFoundError: [Errno 2] No such file or directory: '/home/chenlei/backup_sqls/apiautotest_2022-01-06T14_21_46.sql'\n", "trace": "  File \"D:\\PythonCode\\apiAutoTest\\lib\\site-packages\\pluggy\\callers.py\", line 187, in _multicall\n    res = hook_impl.function(*args)\n  File \"D:\\PythonCode\\apiAutoTest\\lib\\site-packages\\_pytest\\fixtures.py\", line 1117, in pytest_fixture_setup\n    result = call_fixture_func(fixturefunc, request, kwargs)\n  File \"D:\\PythonCode\\apiAutoTest\\lib\\site-packages\\_pytest\\fixtures.py\", line 915, in call_fixture_func\n    fixture_result = next(generator)\n  File \"F:\\CODE\\python-test\\apiAutoTest\\test\\conftest.py\", line 24, in data_clearing\n    DataClearing.backup_mysql()\n  File \"F:\\CODE\\python-test\\apiAutoTest\\tools\\data_clearing.py\", line 119, in backup_mysql\n    cls.server.files_action(0,\n  File \"F:\\CODE\\python-test\\apiAutoTest\\tools\\data_clearing.py\", line 77, in files_action\n    self.ftp_client.get(remotepath=remote_path, localpath=file_path)\n  File \"D:\\PythonCode\\apiAutoTest\\lib\\site-packages\\paramiko\\sftp_client.py\", line 801, in get\n    with open(localpath, \"wb\") as fl:\n"}, "start": 1641450198320, "stop": 1641450199596}, {"name": "data_clearing", "status": "broken", "statusDetails": {"message": "FileNotFoundError: [Errno 2] No such file or directory: '/home/chenlei/backup_sqls/apiautotest_2022-01-06T14_21_46.sql'\n", "trace": "  File \"D:\\PythonCode\\apiAutoTest\\lib\\site-packages\\pluggy\\callers.py\", line 187, in _multicall\n    res = hook_impl.function(*args)\n  File \"D:\\PythonCode\\apiAutoTest\\lib\\site-packages\\_pytest\\fixtures.py\", line 1117, in pytest_fixture_setup\n    result = call_fixture_func(fixturefunc, request, kwargs)\n  File \"D:\\PythonCode\\apiAutoTest\\lib\\site-packages\\_pytest\\fixtures.py\", line 915, in call_fixture_func\n    fixture_result = next(generator)\n  File \"F:\\CODE\\python-test\\apiAutoTest\\test\\conftest.py\", line 24, in data_clearing\n    DataClearing.backup_mysql()\n  File \"F:\\CODE\\python-test\\apiAutoTest\\tools\\data_clearing.py\", line 119, in backup_mysql\n    cls.server.files_action(0,\n  File \"F:\\CODE\\python-test\\apiAutoTest\\tools\\data_clearing.py\", line 77, in files_action\n    self.ftp_client.get(remotepath=remote_path, localpath=file_path)\n  File \"D:\\PythonCode\\apiAutoTest\\lib\\site-packages\\paramiko\\sftp_client.py\", line 801, in get\n    with open(localpath, \"wb\") as fl:\n"}, "start": 1641450200615, "stop": 1641450201702}, {"name": "data_clearing", "status": "broken", "statusDetails": {"message": "FileNotFoundError: [Errno 2] No such file or directory: '/home/chenlei/backup_sqls/apiautotest_2022-01-06T14_21_46.sql'\n", "trace": "  File \"D:\\PythonCode\\apiAutoTest\\lib\\site-packages\\pluggy\\callers.py\", line 187, in _multicall\n    res = hook_impl.function(*args)\n  File \"D:\\PythonCode\\apiAutoTest\\lib\\site-packages\\_pytest\\fixtures.py\", line 1117, in pytest_fixture_setup\n    result = call_fixture_func(fixturefunc, request, kwargs)\n  File \"D:\\PythonCode\\apiAutoTest\\lib\\site-packages\\_pytest\\fixtures.py\", line 915, in call_fixture_func\n    fixture_result = next(generator)\n  File \"F:\\CODE\\python-test\\apiAutoTest\\test\\conftest.py\", line 24, in data_clearing\n    DataClearing.backup_mysql()\n  File \"F:\\CODE\\python-test\\apiAutoTest\\tools\\data_clearing.py\", line 119, in backup_mysql\n    cls.server.files_action(0,\n  File \"F:\\CODE\\python-test\\apiAutoTest\\tools\\data_clearing.py\", line 77, in files_action\n    self.ftp_client.get(remotepath=remote_path, localpath=file_path)\n  File \"D:\\PythonCode\\apiAutoTest\\lib\\site-packages\\paramiko\\sftp_client.py\", line 801, in get\n    with open(localpath, \"wb\") as fl:\n"}, "start": 1641450202736, "stop": 1641450203998}, {"name": "data_clearing", "status": "broken", "statusDetails": {"message": "FileNotFoundError: [Errno 2] No such file or directory: '/home/chenlei/backup_sqls/apiautotest_2022-01-06T14_21_46.sql'\n", "trace": "  File \"D:\\PythonCode\\apiAutoTest\\lib\\site-packages\\pluggy\\callers.py\", line 187, in _multicall\n    res = hook_impl.function(*args)\n  File \"D:\\PythonCode\\apiAutoTest\\lib\\site-packages\\_pytest\\fixtures.py\", line 1117, in pytest_fixture_setup\n    result = call_fixture_func(fixturefunc, request, kwargs)\n  File \"D:\\PythonCode\\apiAutoTest\\lib\\site-packages\\_pytest\\fixtures.py\", line 915, in call_fixture_func\n    fixture_result = next(generator)\n  File \"F:\\CODE\\python-test\\apiAutoTest\\test\\conftest.py\", line 24, in data_clearing\n    DataClearing.backup_mysql()\n  File \"F:\\CODE\\python-test\\apiAutoTest\\tools\\data_clearing.py\", line 119, in backup_mysql\n    cls.server.files_action(0,\n  File \"F:\\CODE\\python-test\\apiAutoTest\\tools\\data_clearing.py\", line 77, in files_action\n    self.ftp_client.get(remotepath=remote_path, localpath=file_path)\n  File \"D:\\PythonCode\\apiAutoTest\\lib\\site-packages\\paramiko\\sftp_client.py\", line 801, in get\n    with open(localpath, \"wb\") as fl:\n"}, "start": 1641450205024, "stop": 1641450206317}, {"name": "data_clearing", "status": "broken", "statusDetails": {"message": "FileNotFoundError: [Errno 2] No such file or directory: '/home/chenlei/backup_sqls/apiautotest_2022-01-06T14_21_46.sql'\n", "trace": "  File \"D:\\PythonCode\\apiAutoTest\\lib\\site-packages\\pluggy\\callers.py\", line 187, in _multicall\n    res = hook_impl.function(*args)\n  File \"D:\\PythonCode\\apiAutoTest\\lib\\site-packages\\_pytest\\fixtures.py\", line 1117, in pytest_fixture_setup\n    result = call_fixture_func(fixturefunc, request, kwargs)\n  File \"D:\\PythonCode\\apiAutoTest\\lib\\site-packages\\_pytest\\fixtures.py\", line 915, in call_fixture_func\n    fixture_result = next(generator)\n  File \"F:\\CODE\\python-test\\apiAutoTest\\test\\conftest.py\", line 24, in data_clearing\n    DataClearing.backup_mysql()\n  File \"F:\\CODE\\python-test\\apiAutoTest\\tools\\data_clearing.py\", line 119, in backup_mysql\n    cls.server.files_action(0,\n  File \"F:\\CODE\\python-test\\apiAutoTest\\tools\\data_clearing.py\", line 77, in files_action\n    self.ftp_client.get(remotepath=remote_path, localpath=file_path)\n  File \"D:\\PythonCode\\apiAutoTest\\lib\\site-packages\\paramiko\\sftp_client.py\", line 801, in get\n    with open(localpath, \"wb\") as fl:\n"}, "start": 1641450207359, "stop": 1641450208843}, {"name": "data_clearing", "status": "broken", "statusDetails": {"message": "FileNotFoundError: [Errno 2] No such file or directory: '/home/chenlei/backup_sqls/apiautotest_2022-01-06T14_21_46.sql'\n", "trace": "  File \"D:\\PythonCode\\apiAutoTest\\lib\\site-packages\\pluggy\\callers.py\", line 187, in _multicall\n    res = hook_impl.function(*args)\n  File \"D:\\PythonCode\\apiAutoTest\\lib\\site-packages\\_pytest\\fixtures.py\", line 1117, in pytest_fixture_setup\n    result = call_fixture_func(fixturefunc, request, kwargs)\n  File \"D:\\PythonCode\\apiAutoTest\\lib\\site-packages\\_pytest\\fixtures.py\", line 915, in call_fixture_func\n    fixture_result = next(generator)\n  File \"F:\\CODE\\python-test\\apiAutoTest\\test\\conftest.py\", line 24, in data_clearing\n    DataClearing.backup_mysql()\n  File \"F:\\CODE\\python-test\\apiAutoTest\\tools\\data_clearing.py\", line 119, in backup_mysql\n    cls.server.files_action(0,\n  File \"F:\\CODE\\python-test\\apiAutoTest\\tools\\data_clearing.py\", line 77, in files_action\n    self.ftp_client.get(remotepath=remote_path, localpath=file_path)\n  File \"D:\\PythonCode\\apiAutoTest\\lib\\site-packages\\paramiko\\sftp_client.py\", line 801, in get\n    with open(localpath, \"wb\") as fl:\n"}, "start": 1641450209872, "stop": 1641450211049}, {"name": "data_clearing", "status": "broken", "statusDetails": {"message": "FileNotFoundError: [Errno 2] No such file or directory: '/home/chenlei/backup_sqls/apiautotest_2022-01-06T14_21_46.sql'\n", "trace": "  File \"D:\\PythonCode\\apiAutoTest\\lib\\site-packages\\pluggy\\callers.py\", line 187, in _multicall\n    res = hook_impl.function(*args)\n  File \"D:\\PythonCode\\apiAutoTest\\lib\\site-packages\\_pytest\\fixtures.py\", line 1117, in pytest_fixture_setup\n    result = call_fixture_func(fixturefunc, request, kwargs)\n  File \"D:\\PythonCode\\apiAutoTest\\lib\\site-packages\\_pytest\\fixtures.py\", line 915, in call_fixture_func\n    fixture_result = next(generator)\n  File \"F:\\CODE\\python-test\\apiAutoTest\\test\\conftest.py\", line 24, in data_clearing\n    DataClearing.backup_mysql()\n  File \"F:\\CODE\\python-test\\apiAutoTest\\tools\\data_clearing.py\", line 119, in backup_mysql\n    cls.server.files_action(0,\n  File \"F:\\CODE\\python-test\\apiAutoTest\\tools\\data_clearing.py\", line 77, in files_action\n    self.ftp_client.get(remotepath=remote_path, localpath=file_path)\n  File \"D:\\PythonCode\\apiAutoTest\\lib\\site-packages\\paramiko\\sftp_client.py\", line 801, in get\n    with open(localpath, \"wb\") as fl:\n"}, "start": 1641450212089, "stop": 1641450213223}, {"name": "data_clearing", "status": "broken", "statusDetails": {"message": "FileNotFoundError: [Errno 2] No such file or directory: '/home/chenlei/backup_sqls/apiautotest_2022-01-06T14_21_46.sql'\n", "trace": "  File \"D:\\PythonCode\\apiAutoTest\\lib\\site-packages\\pluggy\\callers.py\", line 187, in _multicall\n    res = hook_impl.function(*args)\n  File \"D:\\PythonCode\\apiAutoTest\\lib\\site-packages\\_pytest\\fixtures.py\", line 1117, in pytest_fixture_setup\n    result = call_fixture_func(fixturefunc, request, kwargs)\n  File \"D:\\PythonCode\\apiAutoTest\\lib\\site-packages\\_pytest\\fixtures.py\", line 915, in call_fixture_func\n    fixture_result = next(generator)\n  File \"F:\\CODE\\python-test\\apiAutoTest\\test\\conftest.py\", line 24, in data_clearing\n    DataClearing.backup_mysql()\n  File \"F:\\CODE\\python-test\\apiAutoTest\\tools\\data_clearing.py\", line 119, in backup_mysql\n    cls.server.files_action(0,\n  File \"F:\\CODE\\python-test\\apiAutoTest\\tools\\data_clearing.py\", line 77, in files_action\n    self.ftp_client.get(remotepath=remote_path, localpath=file_path)\n  File \"D:\\PythonCode\\apiAutoTest\\lib\\site-packages\\paramiko\\sftp_client.py\", line 801, in get\n    with open(localpath, \"wb\") as fl:\n"}, "start": 1641450214253, "stop": 1641450215529}, {"name": "data_clearing", "status": "broken", "statusDetails": {"message": "FileNotFoundError: [Errno 2] No such file or directory: '/home/chenlei/backup_sqls/apiautotest_2022-01-06T14_21_46.sql'\n", "trace": "  File \"D:\\PythonCode\\apiAutoTest\\lib\\site-packages\\pluggy\\callers.py\", line 187, in _multicall\n    res = hook_impl.function(*args)\n  File \"D:\\PythonCode\\apiAutoTest\\lib\\site-packages\\_pytest\\fixtures.py\", line 1117, in pytest_fixture_setup\n    result = call_fixture_func(fixturefunc, request, kwargs)\n  File \"D:\\PythonCode\\apiAutoTest\\lib\\site-packages\\_pytest\\fixtures.py\", line 915, in call_fixture_func\n    fixture_result = next(generator)\n  File \"F:\\CODE\\python-test\\apiAutoTest\\test\\conftest.py\", line 24, in data_clearing\n    DataClearing.backup_mysql()\n  File \"F:\\CODE\\python-test\\apiAutoTest\\tools\\data_clearing.py\", line 119, in backup_mysql\n    cls.server.files_action(0,\n  File \"F:\\CODE\\python-test\\apiAutoTest\\tools\\data_clearing.py\", line 77, in files_action\n    self.ftp_client.get(remotepath=remote_path, localpath=file_path)\n  File \"D:\\PythonCode\\apiAutoTest\\lib\\site-packages\\paramiko\\sftp_client.py\", line 801, in get\n    with open(localpath, \"wb\") as fl:\n"}, "start": 1641450216593, "stop": 1641450217619}, {"name": "data_clearing", "status": "broken", "statusDetails": {"message": "FileNotFoundError: [Errno 2] No such file or directory: '/home/chenlei/backup_sqls/apiautotest_2022-01-06T14_21_46.sql'\n", "trace": "  File \"D:\\PythonCode\\apiAutoTest\\lib\\site-packages\\pluggy\\callers.py\", line 187, in _multicall\n    res = hook_impl.function(*args)\n  File \"D:\\PythonCode\\apiAutoTest\\lib\\site-packages\\_pytest\\fixtures.py\", line 1117, in pytest_fixture_setup\n    result = call_fixture_func(fixturefunc, request, kwargs)\n  File \"D:\\PythonCode\\apiAutoTest\\lib\\site-packages\\_pytest\\fixtures.py\", line 915, in call_fixture_func\n    fixture_result = next(generator)\n  File \"F:\\CODE\\python-test\\apiAutoTest\\test\\conftest.py\", line 24, in data_clearing\n    DataClearing.backup_mysql()\n  File \"F:\\CODE\\python-test\\apiAutoTest\\tools\\data_clearing.py\", line 119, in backup_mysql\n    cls.server.files_action(0,\n  File \"F:\\CODE\\python-test\\apiAutoTest\\tools\\data_clearing.py\", line 77, in files_action\n    self.ftp_client.get(remotepath=remote_path, localpath=file_path)\n  File \"D:\\PythonCode\\apiAutoTest\\lib\\site-packages\\paramiko\\sftp_client.py\", line 801, in get\n    with open(localpath, \"wb\") as fl:\n"}, "start": 1641450218650, "stop": 1641450219856}, {"name": "data_clearing", "status": "broken", "statusDetails": {"message": "FileNotFoundError: [Errno 2] No such file or directory: '/home/chenlei/backup_sqls/apiautotest_2022-01-06T14_21_46.sql'\n", "trace": "  File \"D:\\PythonCode\\apiAutoTest\\lib\\site-packages\\pluggy\\callers.py\", line 187, in _multicall\n    res = hook_impl.function(*args)\n  File \"D:\\PythonCode\\apiAutoTest\\lib\\site-packages\\_pytest\\fixtures.py\", line 1117, in pytest_fixture_setup\n    result = call_fixture_func(fixturefunc, request, kwargs)\n  File \"D:\\PythonCode\\apiAutoTest\\lib\\site-packages\\_pytest\\fixtures.py\", line 915, in call_fixture_func\n    fixture_result = next(generator)\n  File \"F:\\CODE\\python-test\\apiAutoTest\\test\\conftest.py\", line 24, in data_clearing\n    DataClearing.backup_mysql()\n  File \"F:\\CODE\\python-test\\apiAutoTest\\tools\\data_clearing.py\", line 119, in backup_mysql\n    cls.server.files_action(0,\n  File \"F:\\CODE\\python-test\\apiAutoTest\\tools\\data_clearing.py\", line 77, in files_action\n    self.ftp_client.get(remotepath=remote_path, localpath=file_path)\n  File \"D:\\PythonCode\\apiAutoTest\\lib\\site-packages\\paramiko\\sftp_client.py\", line 801, in get\n    with open(localpath, \"wb\") as fl:\n"}, "start": 1641450220891, "stop": 1641450222270}, {"name": "data_clearing", "status": "broken", "statusDetails": {"message": "FileNotFoundError: [Errno 2] No such file or directory: '/home/chenlei/backup_sqls/apiautotest_2022-01-06T14_21_46.sql'\n", "trace": "  File \"D:\\PythonCode\\apiAutoTest\\lib\\site-packages\\pluggy\\callers.py\", line 187, in _multicall\n    res = hook_impl.function(*args)\n  File \"D:\\PythonCode\\apiAutoTest\\lib\\site-packages\\_pytest\\fixtures.py\", line 1117, in pytest_fixture_setup\n    result = call_fixture_func(fixturefunc, request, kwargs)\n  File \"D:\\PythonCode\\apiAutoTest\\lib\\site-packages\\_pytest\\fixtures.py\", line 915, in call_fixture_func\n    fixture_result = next(generator)\n  File \"F:\\CODE\\python-test\\apiAutoTest\\test\\conftest.py\", line 24, in data_clearing\n    DataClearing.backup_mysql()\n  File \"F:\\CODE\\python-test\\apiAutoTest\\tools\\data_clearing.py\", line 119, in backup_mysql\n    cls.server.files_action(0,\n  File \"F:\\CODE\\python-test\\apiAutoTest\\tools\\data_clearing.py\", line 77, in files_action\n    self.ftp_client.get(remotepath=remote_path, localpath=file_path)\n  File \"D:\\PythonCode\\apiAutoTest\\lib\\site-packages\\paramiko\\sftp_client.py\", line 801, in get\n    with open(localpath, \"wb\") as fl:\n"}, "start": 1641450223295, "stop": 1641450224799}, {"name": "data_clearing", "status": "broken", "statusDetails": {"message": "FileNotFoundError: [Errno 2] No such file or directory: '/home/chenlei/backup_sqls/apiautotest_2022-01-06T14_21_46.sql'\n", "trace": "  File \"D:\\PythonCode\\apiAutoTest\\lib\\site-packages\\pluggy\\callers.py\", line 187, in _multicall\n    res = hook_impl.function(*args)\n  File \"D:\\PythonCode\\apiAutoTest\\lib\\site-packages\\_pytest\\fixtures.py\", line 1117, in pytest_fixture_setup\n    result = call_fixture_func(fixturefunc, request, kwargs)\n  File \"D:\\PythonCode\\apiAutoTest\\lib\\site-packages\\_pytest\\fixtures.py\", line 915, in call_fixture_func\n    fixture_result = next(generator)\n  File \"F:\\CODE\\python-test\\apiAutoTest\\test\\conftest.py\", line 24, in data_clearing\n    DataClearing.backup_mysql()\n  File \"F:\\CODE\\python-test\\apiAutoTest\\tools\\data_clearing.py\", line 119, in backup_mysql\n    cls.server.files_action(0,\n  File \"F:\\CODE\\python-test\\apiAutoTest\\tools\\data_clearing.py\", line 77, in files_action\n    self.ftp_client.get(remotepath=remote_path, localpath=file_path)\n  File \"D:\\PythonCode\\apiAutoTest\\lib\\site-packages\\paramiko\\sftp_client.py\", line 801, in get\n    with open(localpath, \"wb\") as fl:\n"}, "start": 1641450225839, "stop": 1641450227107}, {"name": "data_clearing", "status": "broken", "statusDetails": {"message": "FileNotFoundError: [Errno 2] No such file or directory: '/home/chenlei/backup_sqls/apiautotest_2022-01-06T14_21_46.sql'\n", "trace": "  File \"D:\\PythonCode\\apiAutoTest\\lib\\site-packages\\pluggy\\callers.py\", line 187, in _multicall\n    res = hook_impl.function(*args)\n  File \"D:\\PythonCode\\apiAutoTest\\lib\\site-packages\\_pytest\\fixtures.py\", line 1117, in pytest_fixture_setup\n    result = call_fixture_func(fixturefunc, request, kwargs)\n  File \"D:\\PythonCode\\apiAutoTest\\lib\\site-packages\\_pytest\\fixtures.py\", line 915, in call_fixture_func\n    fixture_result = next(generator)\n  File \"F:\\CODE\\python-test\\apiAutoTest\\test\\conftest.py\", line 24, in data_clearing\n    DataClearing.backup_mysql()\n  File \"F:\\CODE\\python-test\\apiAutoTest\\tools\\data_clearing.py\", line 119, in backup_mysql\n    cls.server.files_action(0,\n  File \"F:\\CODE\\python-test\\apiAutoTest\\tools\\data_clearing.py\", line 77, in files_action\n    self.ftp_client.get(remotepath=remote_path, localpath=file_path)\n  File \"D:\\PythonCode\\apiAutoTest\\lib\\site-packages\\paramiko\\sftp_client.py\", line 801, in get\n    with open(localpath, \"wb\") as fl:\n"}, "start": 1641450228125, "stop": 1641450229220}, {"name": "data_clearing", "status": "broken", "statusDetails": {"message": "FileNotFoundError: [Errno 2] No such file or directory: '/home/chenlei/backup_sqls/apiautotest_2022-01-06T14_21_46.sql'\n", "trace": "  File \"D:\\PythonCode\\apiAutoTest\\lib\\site-packages\\pluggy\\callers.py\", line 187, in _multicall\n    res = hook_impl.function(*args)\n  File \"D:\\PythonCode\\apiAutoTest\\lib\\site-packages\\_pytest\\fixtures.py\", line 1117, in pytest_fixture_setup\n    result = call_fixture_func(fixturefunc, request, kwargs)\n  File \"D:\\PythonCode\\apiAutoTest\\lib\\site-packages\\_pytest\\fixtures.py\", line 915, in call_fixture_func\n    fixture_result = next(generator)\n  File \"F:\\CODE\\python-test\\apiAutoTest\\test\\conftest.py\", line 24, in data_clearing\n    DataClearing.backup_mysql()\n  File \"F:\\CODE\\python-test\\apiAutoTest\\tools\\data_clearing.py\", line 119, in backup_mysql\n    cls.server.files_action(0,\n  File \"F:\\CODE\\python-test\\apiAutoTest\\tools\\data_clearing.py\", line 77, in files_action\n    self.ftp_client.get(remotepath=remote_path, localpath=file_path)\n  File \"D:\\PythonCode\\apiAutoTest\\lib\\site-packages\\paramiko\\sftp_client.py\", line 801, in get\n    with open(localpath, \"wb\") as fl:\n"}, "start": 1641450230257, "stop": 1641450231436}, {"name": "data_clearing", "status": "broken", "statusDetails": {"message": "FileNotFoundError: [Errno 2] No such file or directory: '/home/chenlei/backup_sqls/apiautotest_2022-01-06T14_21_46.sql'\n", "trace": "  File \"D:\\PythonCode\\apiAutoTest\\lib\\site-packages\\pluggy\\callers.py\", line 187, in _multicall\n    res = hook_impl.function(*args)\n  File \"D:\\PythonCode\\apiAutoTest\\lib\\site-packages\\_pytest\\fixtures.py\", line 1117, in pytest_fixture_setup\n    result = call_fixture_func(fixturefunc, request, kwargs)\n  File \"D:\\PythonCode\\apiAutoTest\\lib\\site-packages\\_pytest\\fixtures.py\", line 915, in call_fixture_func\n    fixture_result = next(generator)\n  File \"F:\\CODE\\python-test\\apiAutoTest\\test\\conftest.py\", line 24, in data_clearing\n    DataClearing.backup_mysql()\n  File \"F:\\CODE\\python-test\\apiAutoTest\\tools\\data_clearing.py\", line 119, in backup_mysql\n    cls.server.files_action(0,\n  File \"F:\\CODE\\python-test\\apiAutoTest\\tools\\data_clearing.py\", line 77, in files_action\n    self.ftp_client.get(remotepath=remote_path, localpath=file_path)\n  File \"D:\\PythonCode\\apiAutoTest\\lib\\site-packages\\paramiko\\sftp_client.py\", line 801, in get\n    with open(localpath, \"wb\") as fl:\n"}, "start": 1641450232454, "stop": 1641450233519}, {"name": "data_clearing", "status": "broken", "statusDetails": {"message": "FileNotFoundError: [Errno 2] No such file or directory: '/home/chenlei/backup_sqls/apiautotest_2022-01-06T14_21_46.sql'\n", "trace": "  File \"D:\\PythonCode\\apiAutoTest\\lib\\site-packages\\pluggy\\callers.py\", line 187, in _multicall\n    res = hook_impl.function(*args)\n  File \"D:\\PythonCode\\apiAutoTest\\lib\\site-packages\\_pytest\\fixtures.py\", line 1117, in pytest_fixture_setup\n    result = call_fixture_func(fixturefunc, request, kwargs)\n  File \"D:\\PythonCode\\apiAutoTest\\lib\\site-packages\\_pytest\\fixtures.py\", line 915, in call_fixture_func\n    fixture_result = next(generator)\n  File \"F:\\CODE\\python-test\\apiAutoTest\\test\\conftest.py\", line 24, in data_clearing\n    DataClearing.backup_mysql()\n  File \"F:\\CODE\\python-test\\apiAutoTest\\tools\\data_clearing.py\", line 119, in backup_mysql\n    cls.server.files_action(0,\n  File \"F:\\CODE\\python-test\\apiAutoTest\\tools\\data_clearing.py\", line 77, in files_action\n    self.ftp_client.get(remotepath=remote_path, localpath=file_path)\n  File \"D:\\PythonCode\\apiAutoTest\\lib\\site-packages\\paramiko\\sftp_client.py\", line 801, in get\n    with open(localpath, \"wb\") as fl:\n"}, "start": 1641450234565, "stop": 1641450235874}, {"name": "data_clearing", "status": "broken", "statusDetails": {"message": "FileNotFoundError: [Errno 2] No such file or directory: '/home/chenlei/backup_sqls/apiautotest_2022-01-06T14_21_46.sql'\n", "trace": "  File \"D:\\PythonCode\\apiAutoTest\\lib\\site-packages\\pluggy\\callers.py\", line 187, in _multicall\n    res = hook_impl.function(*args)\n  File \"D:\\PythonCode\\apiAutoTest\\lib\\site-packages\\_pytest\\fixtures.py\", line 1117, in pytest_fixture_setup\n    result = call_fixture_func(fixturefunc, request, kwargs)\n  File \"D:\\PythonCode\\apiAutoTest\\lib\\site-packages\\_pytest\\fixtures.py\", line 915, in call_fixture_func\n    fixture_result = next(generator)\n  File \"F:\\CODE\\python-test\\apiAutoTest\\test\\conftest.py\", line 24, in data_clearing\n    DataClearing.backup_mysql()\n  File \"F:\\CODE\\python-test\\apiAutoTest\\tools\\data_clearing.py\", line 119, in backup_mysql\n    cls.server.files_action(0,\n  File \"F:\\CODE\\python-test\\apiAutoTest\\tools\\data_clearing.py\", line 77, in files_action\n    self.ftp_client.get(remotepath=remote_path, localpath=file_path)\n  File \"D:\\PythonCode\\apiAutoTest\\lib\\site-packages\\paramiko\\sftp_client.py\", line 801, in get\n    with open(localpath, \"wb\") as fl:\n"}, "start": 1641450236894, "stop": 1641450238092}, {"name": "data_clearing", "status": "broken", "statusDetails": {"message": "FileNotFoundError: [Errno 2] No such file or directory: '/home/chenlei/backup_sqls/apiautotest_2022-01-06T14_21_46.sql'\n", "trace": "  File \"D:\\PythonCode\\apiAutoTest\\lib\\site-packages\\pluggy\\callers.py\", line 187, in _multicall\n    res = hook_impl.function(*args)\n  File \"D:\\PythonCode\\apiAutoTest\\lib\\site-packages\\_pytest\\fixtures.py\", line 1117, in pytest_fixture_setup\n    result = call_fixture_func(fixturefunc, request, kwargs)\n  File \"D:\\PythonCode\\apiAutoTest\\lib\\site-packages\\_pytest\\fixtures.py\", line 915, in call_fixture_func\n    fixture_result = next(generator)\n  File \"F:\\CODE\\python-test\\apiAutoTest\\test\\conftest.py\", line 24, in data_clearing\n    DataClearing.backup_mysql()\n  File \"F:\\CODE\\python-test\\apiAutoTest\\tools\\data_clearing.py\", line 119, in backup_mysql\n    cls.server.files_action(0,\n  File \"F:\\CODE\\python-test\\apiAutoTest\\tools\\data_clearing.py\", line 77, in files_action\n    self.ftp_client.get(remotepath=remote_path, localpath=file_path)\n  File \"D:\\PythonCode\\apiAutoTest\\lib\\site-packages\\paramiko\\sftp_client.py\", line 801, in get\n    with open(localpath, \"wb\") as fl:\n"}, "start": 1641450239143, "stop": 1641450240438}, {"name": "data_clearing", "status": "broken", "statusDetails": {"message": "FileNotFoundError: [Errno 2] No such file or directory: '/home/chenlei/backup_sqls/apiautotest_2022-01-06T14_21_46.sql'\n", "trace": "  File \"D:\\PythonCode\\apiAutoTest\\lib\\site-packages\\pluggy\\callers.py\", line 187, in _multicall\n    res = hook_impl.function(*args)\n  File \"D:\\PythonCode\\apiAutoTest\\lib\\site-packages\\_pytest\\fixtures.py\", line 1117, in pytest_fixture_setup\n    result = call_fixture_func(fixturefunc, request, kwargs)\n  File \"D:\\PythonCode\\apiAutoTest\\lib\\site-packages\\_pytest\\fixtures.py\", line 915, in call_fixture_func\n    fixture_result = next(generator)\n  File \"F:\\CODE\\python-test\\apiAutoTest\\test\\conftest.py\", line 24, in data_clearing\n    DataClearing.backup_mysql()\n  File \"F:\\CODE\\python-test\\apiAutoTest\\tools\\data_clearing.py\", line 119, in backup_mysql\n    cls.server.files_action(0,\n  File \"F:\\CODE\\python-test\\apiAutoTest\\tools\\data_clearing.py\", line 77, in files_action\n    self.ftp_client.get(remotepath=remote_path, localpath=file_path)\n  File \"D:\\PythonCode\\apiAutoTest\\lib\\site-packages\\paramiko\\sftp_client.py\", line 801, in get\n    with open(localpath, \"wb\") as fl:\n"}, "start": 1641450241471, "stop": 1641450242636}, {"name": "data_clearing", "status": "broken", "statusDetails": {"message": "FileNotFoundError: [Errno 2] No such file or directory: '/home/chenlei/backup_sqls/apiautotest_2022-01-06T14_21_46.sql'\n", "trace": "  File \"D:\\PythonCode\\apiAutoTest\\lib\\site-packages\\pluggy\\callers.py\", line 187, in _multicall\n    res = hook_impl.function(*args)\n  File \"D:\\PythonCode\\apiAutoTest\\lib\\site-packages\\_pytest\\fixtures.py\", line 1117, in pytest_fixture_setup\n    result = call_fixture_func(fixturefunc, request, kwargs)\n  File \"D:\\PythonCode\\apiAutoTest\\lib\\site-packages\\_pytest\\fixtures.py\", line 915, in call_fixture_func\n    fixture_result = next(generator)\n  File \"F:\\CODE\\python-test\\apiAutoTest\\test\\conftest.py\", line 24, in data_clearing\n    DataClearing.backup_mysql()\n  File \"F:\\CODE\\python-test\\apiAutoTest\\tools\\data_clearing.py\", line 119, in backup_mysql\n    cls.server.files_action(0,\n  File \"F:\\CODE\\python-test\\apiAutoTest\\tools\\data_clearing.py\", line 77, in files_action\n    self.ftp_client.get(remotepath=remote_path, localpath=file_path)\n  File \"D:\\PythonCode\\apiAutoTest\\lib\\site-packages\\paramiko\\sftp_client.py\", line 801, in get\n    with open(localpath, \"wb\") as fl:\n"}, "start": 1641450243680, "stop": 1641450244665}, {"name": "data_clearing", "status": "broken", "statusDetails": {"message": "FileNotFoundError: [Errno 2] No such file or directory: '/home/chenlei/backup_sqls/apiautotest_2022-01-06T14_21_46.sql'\n", "trace": "  File \"D:\\PythonCode\\apiAutoTest\\lib\\site-packages\\pluggy\\callers.py\", line 187, in _multicall\n    res = hook_impl.function(*args)\n  File \"D:\\PythonCode\\apiAutoTest\\lib\\site-packages\\_pytest\\fixtures.py\", line 1117, in pytest_fixture_setup\n    result = call_fixture_func(fixturefunc, request, kwargs)\n  File \"D:\\PythonCode\\apiAutoTest\\lib\\site-packages\\_pytest\\fixtures.py\", line 915, in call_fixture_func\n    fixture_result = next(generator)\n  File \"F:\\CODE\\python-test\\apiAutoTest\\test\\conftest.py\", line 24, in data_clearing\n    DataClearing.backup_mysql()\n  File \"F:\\CODE\\python-test\\apiAutoTest\\tools\\data_clearing.py\", line 119, in backup_mysql\n    cls.server.files_action(0,\n  File \"F:\\CODE\\python-test\\apiAutoTest\\tools\\data_clearing.py\", line 77, in files_action\n    self.ftp_client.get(remotepath=remote_path, localpath=file_path)\n  File \"D:\\PythonCode\\apiAutoTest\\lib\\site-packages\\paramiko\\sftp_client.py\", line 801, in get\n    with open(localpath, \"wb\") as fl:\n"}, "start": 1641450245696, "stop": 1641450246803}, {"name": "data_clearing", "status": "broken", "statusDetails": {"message": "FileNotFoundError: [Errno 2] No such file or directory: '/home/chenlei/backup_sqls/apiautotest_2022-01-06T14_21_46.sql'\n", "trace": "  File \"D:\\PythonCode\\apiAutoTest\\lib\\site-packages\\pluggy\\callers.py\", line 187, in _multicall\n    res = hook_impl.function(*args)\n  File \"D:\\PythonCode\\apiAutoTest\\lib\\site-packages\\_pytest\\fixtures.py\", line 1117, in pytest_fixture_setup\n    result = call_fixture_func(fixturefunc, request, kwargs)\n  File \"D:\\PythonCode\\apiAutoTest\\lib\\site-packages\\_pytest\\fixtures.py\", line 915, in call_fixture_func\n    fixture_result = next(generator)\n  File \"F:\\CODE\\python-test\\apiAutoTest\\test\\conftest.py\", line 24, in data_clearing\n    DataClearing.backup_mysql()\n  File \"F:\\CODE\\python-test\\apiAutoTest\\tools\\data_clearing.py\", line 119, in backup_mysql\n    cls.server.files_action(0,\n  File \"F:\\CODE\\python-test\\apiAutoTest\\tools\\data_clearing.py\", line 77, in files_action\n    self.ftp_client.get(remotepath=remote_path, localpath=file_path)\n  File \"D:\\PythonCode\\apiAutoTest\\lib\\site-packages\\paramiko\\sftp_client.py\", line 801, in get\n    with open(localpath, \"wb\") as fl:\n"}, "start": 1641450247843, "stop": 1641450248872}, {"name": "data_clearing", "status": "broken", "statusDetails": {"message": "FileNotFoundError: [Errno 2] No such file or directory: '/home/chenlei/backup_sqls/apiautotest_2022-01-06T14_21_46.sql'\n", "trace": "  File \"D:\\PythonCode\\apiAutoTest\\lib\\site-packages\\pluggy\\callers.py\", line 187, in _multicall\n    res = hook_impl.function(*args)\n  File \"D:\\PythonCode\\apiAutoTest\\lib\\site-packages\\_pytest\\fixtures.py\", line 1117, in pytest_fixture_setup\n    result = call_fixture_func(fixturefunc, request, kwargs)\n  File \"D:\\PythonCode\\apiAutoTest\\lib\\site-packages\\_pytest\\fixtures.py\", line 915, in call_fixture_func\n    fixture_result = next(generator)\n  File \"F:\\CODE\\python-test\\apiAutoTest\\test\\conftest.py\", line 24, in data_clearing\n    DataClearing.backup_mysql()\n  File \"F:\\CODE\\python-test\\apiAutoTest\\tools\\data_clearing.py\", line 119, in backup_mysql\n    cls.server.files_action(0,\n  File \"F:\\CODE\\python-test\\apiAutoTest\\tools\\data_clearing.py\", line 77, in files_action\n    self.ftp_client.get(remotepath=remote_path, localpath=file_path)\n  File \"D:\\PythonCode\\apiAutoTest\\lib\\site-packages\\paramiko\\sftp_client.py\", line 801, in get\n    with open(localpath, \"wb\") as fl:\n"}, "start": 1641450249889, "stop": 1641450251109}, {"name": "data_clearing", "status": "broken", "statusDetails": {"message": "FileNotFoundError: [Errno 2] No such file or directory: '/home/chenlei/backup_sqls/apiautotest_2022-01-06T14_21_46.sql'\n", "trace": "  File \"D:\\PythonCode\\apiAutoTest\\lib\\site-packages\\pluggy\\callers.py\", line 187, in _multicall\n    res = hook_impl.function(*args)\n  File \"D:\\PythonCode\\apiAutoTest\\lib\\site-packages\\_pytest\\fixtures.py\", line 1117, in pytest_fixture_setup\n    result = call_fixture_func(fixturefunc, request, kwargs)\n  File \"D:\\PythonCode\\apiAutoTest\\lib\\site-packages\\_pytest\\fixtures.py\", line 915, in call_fixture_func\n    fixture_result = next(generator)\n  File \"F:\\CODE\\python-test\\apiAutoTest\\test\\conftest.py\", line 24, in data_clearing\n    DataClearing.backup_mysql()\n  File \"F:\\CODE\\python-test\\apiAutoTest\\tools\\data_clearing.py\", line 119, in backup_mysql\n    cls.server.files_action(0,\n  File \"F:\\CODE\\python-test\\apiAutoTest\\tools\\data_clearing.py\", line 77, in files_action\n    self.ftp_client.get(remotepath=remote_path, localpath=file_path)\n  File \"D:\\PythonCode\\apiAutoTest\\lib\\site-packages\\paramiko\\sftp_client.py\", line 801, in get\n    with open(localpath, \"wb\") as fl:\n"}, "start": 1641450252151, "stop": 1641450253407}, {"name": "data_clearing", "status": "broken", "statusDetails": {"message": "FileNotFoundError: [Errno 2] No such file or directory: '/home/chenlei/backup_sqls/apiautotest_2022-01-06T14_21_46.sql'\n", "trace": "  File \"D:\\PythonCode\\apiAutoTest\\lib\\site-packages\\pluggy\\callers.py\", line 187, in _multicall\n    res = hook_impl.function(*args)\n  File \"D:\\PythonCode\\apiAutoTest\\lib\\site-packages\\_pytest\\fixtures.py\", line 1117, in pytest_fixture_setup\n    result = call_fixture_func(fixturefunc, request, kwargs)\n  File \"D:\\PythonCode\\apiAutoTest\\lib\\site-packages\\_pytest\\fixtures.py\", line 915, in call_fixture_func\n    fixture_result = next(generator)\n  File \"F:\\CODE\\python-test\\apiAutoTest\\test\\conftest.py\", line 24, in data_clearing\n    DataClearing.backup_mysql()\n  File \"F:\\CODE\\python-test\\apiAutoTest\\tools\\data_clearing.py\", line 119, in backup_mysql\n    cls.server.files_action(0,\n  File \"F:\\CODE\\python-test\\apiAutoTest\\tools\\data_clearing.py\", line 77, in files_action\n    self.ftp_client.get(remotepath=remote_path, localpath=file_path)\n  File \"D:\\PythonCode\\apiAutoTest\\lib\\site-packages\\paramiko\\sftp_client.py\", line 801, in get\n    with open(localpath, \"wb\") as fl:\n"}, "start": 1641450254426, "stop": 1641450255863}, {"name": "data_clearing", "status": "broken", "statusDetails": {"message": "FileNotFoundError: [Errno 2] No such file or directory: '/home/chenlei/backup_sqls/apiautotest_2022-01-06T14_21_46.sql'\n", "trace": "  File \"D:\\PythonCode\\apiAutoTest\\lib\\site-packages\\pluggy\\callers.py\", line 187, in _multicall\n    res = hook_impl.function(*args)\n  File \"D:\\PythonCode\\apiAutoTest\\lib\\site-packages\\_pytest\\fixtures.py\", line 1117, in pytest_fixture_setup\n    result = call_fixture_func(fixturefunc, request, kwargs)\n  File \"D:\\PythonCode\\apiAutoTest\\lib\\site-packages\\_pytest\\fixtures.py\", line 915, in call_fixture_func\n    fixture_result = next(generator)\n  File \"F:\\CODE\\python-test\\apiAutoTest\\test\\conftest.py\", line 24, in data_clearing\n    DataClearing.backup_mysql()\n  File \"F:\\CODE\\python-test\\apiAutoTest\\tools\\data_clearing.py\", line 119, in backup_mysql\n    cls.server.files_action(0,\n  File \"F:\\CODE\\python-test\\apiAutoTest\\tools\\data_clearing.py\", line 77, in files_action\n    self.ftp_client.get(remotepath=remote_path, localpath=file_path)\n  File \"D:\\PythonCode\\apiAutoTest\\lib\\site-packages\\paramiko\\sftp_client.py\", line 801, in get\n    with open(localpath, \"wb\") as fl:\n"}, "start": 1641450256907, "stop": 1641450258050}, {"name": "data_clearing", "status": "broken", "statusDetails": {"message": "FileNotFoundError: [Errno 2] No such file or directory: '/home/chenlei/backup_sqls/apiautotest_2022-01-06T14_21_46.sql'\n", "trace": "  File \"D:\\PythonCode\\apiAutoTest\\lib\\site-packages\\pluggy\\callers.py\", line 187, in _multicall\n    res = hook_impl.function(*args)\n  File \"D:\\PythonCode\\apiAutoTest\\lib\\site-packages\\_pytest\\fixtures.py\", line 1117, in pytest_fixture_setup\n    result = call_fixture_func(fixturefunc, request, kwargs)\n  File \"D:\\PythonCode\\apiAutoTest\\lib\\site-packages\\_pytest\\fixtures.py\", line 915, in call_fixture_func\n    fixture_result = next(generator)\n  File \"F:\\CODE\\python-test\\apiAutoTest\\test\\conftest.py\", line 24, in data_clearing\n    DataClearing.backup_mysql()\n  File \"F:\\CODE\\python-test\\apiAutoTest\\tools\\data_clearing.py\", line 119, in backup_mysql\n    cls.server.files_action(0,\n  File \"F:\\CODE\\python-test\\apiAutoTest\\tools\\data_clearing.py\", line 77, in files_action\n    self.ftp_client.get(remotepath=remote_path, localpath=file_path)\n  File \"D:\\PythonCode\\apiAutoTest\\lib\\site-packages\\paramiko\\sftp_client.py\", line 801, in get\n    with open(localpath, \"wb\") as fl:\n"}, "start": 1641450259074, "stop": 1641450260399}, {"name": "data_clearing", "status": "broken", "statusDetails": {"message": "FileNotFoundError: [Errno 2] No such file or directory: '/home/chenlei/backup_sqls/apiautotest_2022-01-06T14_21_46.sql'\n", "trace": "  File \"D:\\PythonCode\\apiAutoTest\\lib\\site-packages\\pluggy\\callers.py\", line 187, in _multicall\n    res = hook_impl.function(*args)\n  File \"D:\\PythonCode\\apiAutoTest\\lib\\site-packages\\_pytest\\fixtures.py\", line 1117, in pytest_fixture_setup\n    result = call_fixture_func(fixturefunc, request, kwargs)\n  File \"D:\\PythonCode\\apiAutoTest\\lib\\site-packages\\_pytest\\fixtures.py\", line 915, in call_fixture_func\n    fixture_result = next(generator)\n  File \"F:\\CODE\\python-test\\apiAutoTest\\test\\conftest.py\", line 24, in data_clearing\n    DataClearing.backup_mysql()\n  File \"F:\\CODE\\python-test\\apiAutoTest\\tools\\data_clearing.py\", line 119, in backup_mysql\n    cls.server.files_action(0,\n  File \"F:\\CODE\\python-test\\apiAutoTest\\tools\\data_clearing.py\", line 77, in files_action\n    self.ftp_client.get(remotepath=remote_path, localpath=file_path)\n  File \"D:\\PythonCode\\apiAutoTest\\lib\\site-packages\\paramiko\\sftp_client.py\", line 801, in get\n    with open(localpath, \"wb\") as fl:\n"}, "start": 1641450261456, "stop": 1641450262441}, {"name": "data_clearing", "status": "broken", "statusDetails": {"message": "FileNotFoundError: [Errno 2] No such file or directory: '/home/chenlei/backup_sqls/apiautotest_2022-01-06T14_21_46.sql'\n", "trace": "  File \"D:\\PythonCode\\apiAutoTest\\lib\\site-packages\\pluggy\\callers.py\", line 187, in _multicall\n    res = hook_impl.function(*args)\n  File \"D:\\PythonCode\\apiAutoTest\\lib\\site-packages\\_pytest\\fixtures.py\", line 1117, in pytest_fixture_setup\n    result = call_fixture_func(fixturefunc, request, kwargs)\n  File \"D:\\PythonCode\\apiAutoTest\\lib\\site-packages\\_pytest\\fixtures.py\", line 915, in call_fixture_func\n    fixture_result = next(generator)\n  File \"F:\\CODE\\python-test\\apiAutoTest\\test\\conftest.py\", line 24, in data_clearing\n    DataClearing.backup_mysql()\n  File \"F:\\CODE\\python-test\\apiAutoTest\\tools\\data_clearing.py\", line 119, in backup_mysql\n    cls.server.files_action(0,\n  File \"F:\\CODE\\python-test\\apiAutoTest\\tools\\data_clearing.py\", line 77, in files_action\n    self.ftp_client.get(remotepath=remote_path, localpath=file_path)\n  File \"D:\\PythonCode\\apiAutoTest\\lib\\site-packages\\paramiko\\sftp_client.py\", line 801, in get\n    with open(localpath, \"wb\") as fl:\n"}, "start": 1641450263470, "stop": 1641450264778}, {"name": "data_clearing", "status": "broken", "statusDetails": {"message": "FileNotFoundError: [Errno 2] No such file or directory: '/home/chenlei/backup_sqls/apiautotest_2022-01-06T14_21_46.sql'\n", "trace": "  File \"D:\\PythonCode\\apiAutoTest\\lib\\site-packages\\pluggy\\callers.py\", line 187, in _multicall\n    res = hook_impl.function(*args)\n  File \"D:\\PythonCode\\apiAutoTest\\lib\\site-packages\\_pytest\\fixtures.py\", line 1117, in pytest_fixture_setup\n    result = call_fixture_func(fixturefunc, request, kwargs)\n  File \"D:\\PythonCode\\apiAutoTest\\lib\\site-packages\\_pytest\\fixtures.py\", line 915, in call_fixture_func\n    fixture_result = next(generator)\n  File \"F:\\CODE\\python-test\\apiAutoTest\\test\\conftest.py\", line 24, in data_clearing\n    DataClearing.backup_mysql()\n  File \"F:\\CODE\\python-test\\apiAutoTest\\tools\\data_clearing.py\", line 119, in backup_mysql\n    cls.server.files_action(0,\n  File \"F:\\CODE\\python-test\\apiAutoTest\\tools\\data_clearing.py\", line 77, in files_action\n    self.ftp_client.get(remotepath=remote_path, localpath=file_path)\n  File \"D:\\PythonCode\\apiAutoTest\\lib\\site-packages\\paramiko\\sftp_client.py\", line 801, in get\n    with open(localpath, \"wb\") as fl:\n"}, "start": 1641450265821, "stop": 1641450266945}, {"name": "data_clearing", "status": "broken", "statusDetails": {"message": "FileNotFoundError: [Errno 2] No such file or directory: '/home/chenlei/backup_sqls/apiautotest_2022-01-06T14_21_46.sql'\n", "trace": "  File \"D:\\PythonCode\\apiAutoTest\\lib\\site-packages\\pluggy\\callers.py\", line 187, in _multicall\n    res = hook_impl.function(*args)\n  File \"D:\\PythonCode\\apiAutoTest\\lib\\site-packages\\_pytest\\fixtures.py\", line 1117, in pytest_fixture_setup\n    result = call_fixture_func(fixturefunc, request, kwargs)\n  File \"D:\\PythonCode\\apiAutoTest\\lib\\site-packages\\_pytest\\fixtures.py\", line 915, in call_fixture_func\n    fixture_result = next(generator)\n  File \"F:\\CODE\\python-test\\apiAutoTest\\test\\conftest.py\", line 24, in data_clearing\n    DataClearing.backup_mysql()\n  File \"F:\\CODE\\python-test\\apiAutoTest\\tools\\data_clearing.py\", line 119, in backup_mysql\n    cls.server.files_action(0,\n  File \"F:\\CODE\\python-test\\apiAutoTest\\tools\\data_clearing.py\", line 77, in files_action\n    self.ftp_client.get(remotepath=remote_path, localpath=file_path)\n  File \"D:\\PythonCode\\apiAutoTest\\lib\\site-packages\\paramiko\\sftp_client.py\", line 801, in get\n    with open(localpath, \"wb\") as fl:\n"}, "start": 1641450267975, "stop": 1641450269166}, {"name": "data_clearing", "status": "broken", "statusDetails": {"message": "FileNotFoundError: [Errno 2] No such file or directory: '/home/chenlei/backup_sqls/apiautotest_2022-01-06T14_21_46.sql'\n", "trace": "  File \"D:\\PythonCode\\apiAutoTest\\lib\\site-packages\\pluggy\\callers.py\", line 187, in _multicall\n    res = hook_impl.function(*args)\n  File \"D:\\PythonCode\\apiAutoTest\\lib\\site-packages\\_pytest\\fixtures.py\", line 1117, in pytest_fixture_setup\n    result = call_fixture_func(fixturefunc, request, kwargs)\n  File \"D:\\PythonCode\\apiAutoTest\\lib\\site-packages\\_pytest\\fixtures.py\", line 915, in call_fixture_func\n    fixture_result = next(generator)\n  File \"F:\\CODE\\python-test\\apiAutoTest\\test\\conftest.py\", line 24, in data_clearing\n    DataClearing.backup_mysql()\n  File \"F:\\CODE\\python-test\\apiAutoTest\\tools\\data_clearing.py\", line 119, in backup_mysql\n    cls.server.files_action(0,\n  File \"F:\\CODE\\python-test\\apiAutoTest\\tools\\data_clearing.py\", line 77, in files_action\n    self.ftp_client.get(remotepath=remote_path, localpath=file_path)\n  File \"D:\\PythonCode\\apiAutoTest\\lib\\site-packages\\paramiko\\sftp_client.py\", line 801, in get\n    with open(localpath, \"wb\") as fl:\n"}, "start": 1641450270200, "stop": 1641450271256}, {"name": "data_clearing", "status": "broken", "statusDetails": {"message": "FileNotFoundError: [Errno 2] No such file or directory: '/home/chenlei/backup_sqls/apiautotest_2022-01-06T14_21_46.sql'\n", "trace": "  File \"D:\\PythonCode\\apiAutoTest\\lib\\site-packages\\pluggy\\callers.py\", line 187, in _multicall\n    res = hook_impl.function(*args)\n  File \"D:\\PythonCode\\apiAutoTest\\lib\\site-packages\\_pytest\\fixtures.py\", line 1117, in pytest_fixture_setup\n    result = call_fixture_func(fixturefunc, request, kwargs)\n  File \"D:\\PythonCode\\apiAutoTest\\lib\\site-packages\\_pytest\\fixtures.py\", line 915, in call_fixture_func\n    fixture_result = next(generator)\n  File \"F:\\CODE\\python-test\\apiAutoTest\\test\\conftest.py\", line 24, in data_clearing\n    DataClearing.backup_mysql()\n  File \"F:\\CODE\\python-test\\apiAutoTest\\tools\\data_clearing.py\", line 119, in backup_mysql\n    cls.server.files_action(0,\n  File \"F:\\CODE\\python-test\\apiAutoTest\\tools\\data_clearing.py\", line 77, in files_action\n    self.ftp_client.get(remotepath=remote_path, localpath=file_path)\n  File \"D:\\PythonCode\\apiAutoTest\\lib\\site-packages\\paramiko\\sftp_client.py\", line 801, in get\n    with open(localpath, \"wb\") as fl:\n"}, "start": 1641450272277, "stop": 1641450273535}, {"name": "data_clearing", "status": "broken", "statusDetails": {"message": "FileNotFoundError: [Errno 2] No such file or directory: '/home/chenlei/backup_sqls/apiautotest_2022-01-06T14_21_46.sql'\n", "trace": "  File \"D:\\PythonCode\\apiAutoTest\\lib\\site-packages\\pluggy\\callers.py\", line 187, in _multicall\n    res = hook_impl.function(*args)\n  File \"D:\\PythonCode\\apiAutoTest\\lib\\site-packages\\_pytest\\fixtures.py\", line 1117, in pytest_fixture_setup\n    result = call_fixture_func(fixturefunc, request, kwargs)\n  File \"D:\\PythonCode\\apiAutoTest\\lib\\site-packages\\_pytest\\fixtures.py\", line 915, in call_fixture_func\n    fixture_result = next(generator)\n  File \"F:\\CODE\\python-test\\apiAutoTest\\test\\conftest.py\", line 24, in data_clearing\n    DataClearing.backup_mysql()\n  File \"F:\\CODE\\python-test\\apiAutoTest\\tools\\data_clearing.py\", line 119, in backup_mysql\n    cls.server.files_action(0,\n  File \"F:\\CODE\\python-test\\apiAutoTest\\tools\\data_clearing.py\", line 77, in files_action\n    self.ftp_client.get(remotepath=remote_path, localpath=file_path)\n  File \"D:\\PythonCode\\apiAutoTest\\lib\\site-packages\\paramiko\\sftp_client.py\", line 801, in get\n    with open(localpath, \"wb\") as fl:\n"}, "start": 1641450274580, "stop": 1641450275858}, {"name": "data_clearing", "status": "broken", "statusDetails": {"message": "FileNotFoundError: [Errno 2] No such file or directory: '/home/chenlei/backup_sqls/apiautotest_2022-01-06T14_21_46.sql'\n", "trace": "  File \"D:\\PythonCode\\apiAutoTest\\lib\\site-packages\\pluggy\\callers.py\", line 187, in _multicall\n    res = hook_impl.function(*args)\n  File \"D:\\PythonCode\\apiAutoTest\\lib\\site-packages\\_pytest\\fixtures.py\", line 1117, in pytest_fixture_setup\n    result = call_fixture_func(fixturefunc, request, kwargs)\n  File \"D:\\PythonCode\\apiAutoTest\\lib\\site-packages\\_pytest\\fixtures.py\", line 915, in call_fixture_func\n    fixture_result = next(generator)\n  File \"F:\\CODE\\python-test\\apiAutoTest\\test\\conftest.py\", line 24, in data_clearing\n    DataClearing.backup_mysql()\n  File \"F:\\CODE\\python-test\\apiAutoTest\\tools\\data_clearing.py\", line 119, in backup_mysql\n    cls.server.files_action(0,\n  File \"F:\\CODE\\python-test\\apiAutoTest\\tools\\data_clearing.py\", line 77, in files_action\n    self.ftp_client.get(remotepath=remote_path, localpath=file_path)\n  File \"D:\\PythonCode\\apiAutoTest\\lib\\site-packages\\paramiko\\sftp_client.py\", line 801, in get\n    with open(localpath, \"wb\") as fl:\n"}, "start": 1641450276884, "stop": 1641450278320}, {"name": "data_clearing", "status": "broken", "statusDetails": {"message": "FileNotFoundError: [Errno 2] No such file or directory: '/home/chenlei/backup_sqls/apiautotest_2022-01-06T14_21_46.sql'\n", "trace": "  File \"D:\\PythonCode\\apiAutoTest\\lib\\site-packages\\pluggy\\callers.py\", line 187, in _multicall\n    res = hook_impl.function(*args)\n  File \"D:\\PythonCode\\apiAutoTest\\lib\\site-packages\\_pytest\\fixtures.py\", line 1117, in pytest_fixture_setup\n    result = call_fixture_func(fixturefunc, request, kwargs)\n  File \"D:\\PythonCode\\apiAutoTest\\lib\\site-packages\\_pytest\\fixtures.py\", line 915, in call_fixture_func\n    fixture_result = next(generator)\n  File \"F:\\CODE\\python-test\\apiAutoTest\\test\\conftest.py\", line 24, in data_clearing\n    DataClearing.backup_mysql()\n  File \"F:\\CODE\\python-test\\apiAutoTest\\tools\\data_clearing.py\", line 119, in backup_mysql\n    cls.server.files_action(0,\n  File \"F:\\CODE\\python-test\\apiAutoTest\\tools\\data_clearing.py\", line 77, in files_action\n    self.ftp_client.get(remotepath=remote_path, localpath=file_path)\n  File \"D:\\PythonCode\\apiAutoTest\\lib\\site-packages\\paramiko\\sftp_client.py\", line 801, in get\n    with open(localpath, \"wb\") as fl:\n"}, "start": 1641450279364, "stop": 1641450280453}, {"name": "data_clearing", "status": "broken", "statusDetails": {"message": "FileNotFoundError: [Errno 2] No such file or directory: '/home/chenlei/backup_sqls/apiautotest_2022-01-06T14_21_46.sql'\n", "trace": "  File \"D:\\PythonCode\\apiAutoTest\\lib\\site-packages\\pluggy\\callers.py\", line 187, in _multicall\n    res = hook_impl.function(*args)\n  File \"D:\\PythonCode\\apiAutoTest\\lib\\site-packages\\_pytest\\fixtures.py\", line 1117, in pytest_fixture_setup\n    result = call_fixture_func(fixturefunc, request, kwargs)\n  File \"D:\\PythonCode\\apiAutoTest\\lib\\site-packages\\_pytest\\fixtures.py\", line 915, in call_fixture_func\n    fixture_result = next(generator)\n  File \"F:\\CODE\\python-test\\apiAutoTest\\test\\conftest.py\", line 24, in data_clearing\n    DataClearing.backup_mysql()\n  File \"F:\\CODE\\python-test\\apiAutoTest\\tools\\data_clearing.py\", line 119, in backup_mysql\n    cls.server.files_action(0,\n  File \"F:\\CODE\\python-test\\apiAutoTest\\tools\\data_clearing.py\", line 77, in files_action\n    self.ftp_client.get(remotepath=remote_path, localpath=file_path)\n  File \"D:\\PythonCode\\apiAutoTest\\lib\\site-packages\\paramiko\\sftp_client.py\", line 801, in get\n    with open(localpath, \"wb\") as fl:\n"}, "start": 1641450281484, "stop": 1641450282842}, {"name": "data_clearing", "status": "broken", "statusDetails": {"message": "FileNotFoundError: [Errno 2] No such file or directory: '/home/chenlei/backup_sqls/apiautotest_2022-01-06T14_21_46.sql'\n", "trace": "  File \"D:\\PythonCode\\apiAutoTest\\lib\\site-packages\\pluggy\\callers.py\", line 187, in _multicall\n    res = hook_impl.function(*args)\n  File \"D:\\PythonCode\\apiAutoTest\\lib\\site-packages\\_pytest\\fixtures.py\", line 1117, in pytest_fixture_setup\n    result = call_fixture_func(fixturefunc, request, kwargs)\n  File \"D:\\PythonCode\\apiAutoTest\\lib\\site-packages\\_pytest\\fixtures.py\", line 915, in call_fixture_func\n    fixture_result = next(generator)\n  File \"F:\\CODE\\python-test\\apiAutoTest\\test\\conftest.py\", line 24, in data_clearing\n    DataClearing.backup_mysql()\n  File \"F:\\CODE\\python-test\\apiAutoTest\\tools\\data_clearing.py\", line 119, in backup_mysql\n    cls.server.files_action(0,\n  File \"F:\\CODE\\python-test\\apiAutoTest\\tools\\data_clearing.py\", line 77, in files_action\n    self.ftp_client.get(remotepath=remote_path, localpath=file_path)\n  File \"D:\\PythonCode\\apiAutoTest\\lib\\site-packages\\paramiko\\sftp_client.py\", line 801, in get\n    with open(localpath, \"wb\") as fl:\n"}, "start": 1641450283894, "stop": 1641450285347}, {"name": "data_clearing", "status": "broken", "statusDetails": {"message": "FileNotFoundError: [Errno 2] No such file or directory: '/home/chenlei/backup_sqls/apiautotest_2022-01-06T14_21_46.sql'\n", "trace": "  File \"D:\\PythonCode\\apiAutoTest\\lib\\site-packages\\pluggy\\callers.py\", line 187, in _multicall\n    res = hook_impl.function(*args)\n  File \"D:\\PythonCode\\apiAutoTest\\lib\\site-packages\\_pytest\\fixtures.py\", line 1117, in pytest_fixture_setup\n    result = call_fixture_func(fixturefunc, request, kwargs)\n  File \"D:\\PythonCode\\apiAutoTest\\lib\\site-packages\\_pytest\\fixtures.py\", line 915, in call_fixture_func\n    fixture_result = next(generator)\n  File \"F:\\CODE\\python-test\\apiAutoTest\\test\\conftest.py\", line 24, in data_clearing\n    DataClearing.backup_mysql()\n  File \"F:\\CODE\\python-test\\apiAutoTest\\tools\\data_clearing.py\", line 119, in backup_mysql\n    cls.server.files_action(0,\n  File \"F:\\CODE\\python-test\\apiAutoTest\\tools\\data_clearing.py\", line 77, in files_action\n    self.ftp_client.get(remotepath=remote_path, localpath=file_path)\n  File \"D:\\PythonCode\\apiAutoTest\\lib\\site-packages\\paramiko\\sftp_client.py\", line 801, in get\n    with open(localpath, \"wb\") as fl:\n"}, "start": 1641450286376, "stop": 1641450287482}, {"name": "data_clearing", "status": "broken", "statusDetails": {"message": "FileNotFoundError: [Errno 2] No such file or directory: '/home/chenlei/backup_sqls/apiautotest_2022-01-06T14_21_46.sql'\n", "trace": "  File \"D:\\PythonCode\\apiAutoTest\\lib\\site-packages\\pluggy\\callers.py\", line 187, in _multicall\n    res = hook_impl.function(*args)\n  File \"D:\\PythonCode\\apiAutoTest\\lib\\site-packages\\_pytest\\fixtures.py\", line 1117, in pytest_fixture_setup\n    result = call_fixture_func(fixturefunc, request, kwargs)\n  File \"D:\\PythonCode\\apiAutoTest\\lib\\site-packages\\_pytest\\fixtures.py\", line 915, in call_fixture_func\n    fixture_result = next(generator)\n  File \"F:\\CODE\\python-test\\apiAutoTest\\test\\conftest.py\", line 24, in data_clearing\n    DataClearing.backup_mysql()\n  File \"F:\\CODE\\python-test\\apiAutoTest\\tools\\data_clearing.py\", line 119, in backup_mysql\n    cls.server.files_action(0,\n  File \"F:\\CODE\\python-test\\apiAutoTest\\tools\\data_clearing.py\", line 77, in files_action\n    self.ftp_client.get(remotepath=remote_path, localpath=file_path)\n  File \"D:\\PythonCode\\apiAutoTest\\lib\\site-packages\\paramiko\\sftp_client.py\", line 801, in get\n    with open(localpath, \"wb\") as fl:\n"}, "start": 1641450288527, "stop": 1641450289991}, {"name": "data_clearing", "status": "broken", "statusDetails": {"message": "FileNotFoundError: [Errno 2] No such file or directory: '/home/chenlei/backup_sqls/apiautotest_2022-01-06T14_21_46.sql'\n", "trace": "  File \"D:\\PythonCode\\apiAutoTest\\lib\\site-packages\\pluggy\\callers.py\", line 187, in _multicall\n    res = hook_impl.function(*args)\n  File \"D:\\PythonCode\\apiAutoTest\\lib\\site-packages\\_pytest\\fixtures.py\", line 1117, in pytest_fixture_setup\n    result = call_fixture_func(fixturefunc, request, kwargs)\n  File \"D:\\PythonCode\\apiAutoTest\\lib\\site-packages\\_pytest\\fixtures.py\", line 915, in call_fixture_func\n    fixture_result = next(generator)\n  File \"F:\\CODE\\python-test\\apiAutoTest\\test\\conftest.py\", line 24, in data_clearing\n    DataClearing.backup_mysql()\n  File \"F:\\CODE\\python-test\\apiAutoTest\\tools\\data_clearing.py\", line 119, in backup_mysql\n    cls.server.files_action(0,\n  File \"F:\\CODE\\python-test\\apiAutoTest\\tools\\data_clearing.py\", line 77, in files_action\n    self.ftp_client.get(remotepath=remote_path, localpath=file_path)\n  File \"D:\\PythonCode\\apiAutoTest\\lib\\site-packages\\paramiko\\sftp_client.py\", line 801, in get\n    with open(localpath, \"wb\") as fl:\n"}, "start": 1641450291014, "stop": 1641450292744}, {"name": "data_clearing", "status": "broken", "statusDetails": {"message": "FileNotFoundError: [Errno 2] No such file or directory: '/home/chenlei/backup_sqls/apiautotest_2022-01-06T14_21_46.sql'\n", "trace": "  File \"D:\\PythonCode\\apiAutoTest\\lib\\site-packages\\pluggy\\callers.py\", line 187, in _multicall\n    res = hook_impl.function(*args)\n  File \"D:\\PythonCode\\apiAutoTest\\lib\\site-packages\\_pytest\\fixtures.py\", line 1117, in pytest_fixture_setup\n    result = call_fixture_func(fixturefunc, request, kwargs)\n  File \"D:\\PythonCode\\apiAutoTest\\lib\\site-packages\\_pytest\\fixtures.py\", line 915, in call_fixture_func\n    fixture_result = next(generator)\n  File \"F:\\CODE\\python-test\\apiAutoTest\\test\\conftest.py\", line 24, in data_clearing\n    DataClearing.backup_mysql()\n  File \"F:\\CODE\\python-test\\apiAutoTest\\tools\\data_clearing.py\", line 119, in backup_mysql\n    cls.server.files_action(0,\n  File \"F:\\CODE\\python-test\\apiAutoTest\\tools\\data_clearing.py\", line 77, in files_action\n    self.ftp_client.get(remotepath=remote_path, localpath=file_path)\n  File \"D:\\PythonCode\\apiAutoTest\\lib\\site-packages\\paramiko\\sftp_client.py\", line 801, in get\n    with open(localpath, \"wb\") as fl:\n"}, "start": 1641450293778, "stop": 1641450294888}, {"name": "data_clearing", "status": "broken", "statusDetails": {"message": "FileNotFoundError: [Errno 2] No such file or directory: '/home/chenlei/backup_sqls/apiautotest_2022-01-06T14_21_46.sql'\n", "trace": "  File \"D:\\PythonCode\\apiAutoTest\\lib\\site-packages\\pluggy\\callers.py\", line 187, in _multicall\n    res = hook_impl.function(*args)\n  File \"D:\\PythonCode\\apiAutoTest\\lib\\site-packages\\_pytest\\fixtures.py\", line 1117, in pytest_fixture_setup\n    result = call_fixture_func(fixturefunc, request, kwargs)\n  File \"D:\\PythonCode\\apiAutoTest\\lib\\site-packages\\_pytest\\fixtures.py\", line 915, in call_fixture_func\n    fixture_result = next(generator)\n  File \"F:\\CODE\\python-test\\apiAutoTest\\test\\conftest.py\", line 24, in data_clearing\n    DataClearing.backup_mysql()\n  File \"F:\\CODE\\python-test\\apiAutoTest\\tools\\data_clearing.py\", line 119, in backup_mysql\n    cls.server.files_action(0,\n  File \"F:\\CODE\\python-test\\apiAutoTest\\tools\\data_clearing.py\", line 77, in files_action\n    self.ftp_client.get(remotepath=remote_path, localpath=file_path)\n  File \"D:\\PythonCode\\apiAutoTest\\lib\\site-packages\\paramiko\\sftp_client.py\", line 801, in get\n    with open(localpath, \"wb\") as fl:\n"}, "start": 1641450295906, "stop": 1641450297002}, {"name": "data_clearing", "status": "broken", "statusDetails": {"message": "FileNotFoundError: [Errno 2] No such file or directory: '/home/chenlei/backup_sqls/apiautotest_2022-01-06T14_21_46.sql'\n", "trace": "  File \"D:\\PythonCode\\apiAutoTest\\lib\\site-packages\\pluggy\\callers.py\", line 187, in _multicall\n    res = hook_impl.function(*args)\n  File \"D:\\PythonCode\\apiAutoTest\\lib\\site-packages\\_pytest\\fixtures.py\", line 1117, in pytest_fixture_setup\n    result = call_fixture_func(fixturefunc, request, kwargs)\n  File \"D:\\PythonCode\\apiAutoTest\\lib\\site-packages\\_pytest\\fixtures.py\", line 915, in call_fixture_func\n    fixture_result = next(generator)\n  File \"F:\\CODE\\python-test\\apiAutoTest\\test\\conftest.py\", line 24, in data_clearing\n    DataClearing.backup_mysql()\n  File \"F:\\CODE\\python-test\\apiAutoTest\\tools\\data_clearing.py\", line 119, in backup_mysql\n    cls.server.files_action(0,\n  File \"F:\\CODE\\python-test\\apiAutoTest\\tools\\data_clearing.py\", line 77, in files_action\n    self.ftp_client.get(remotepath=remote_path, localpath=file_path)\n  File \"D:\\PythonCode\\apiAutoTest\\lib\\site-packages\\paramiko\\sftp_client.py\", line 801, in get\n    with open(localpath, \"wb\") as fl:\n"}, "start": 1641450298041, "stop": 1641450299275}, {"name": "data_clearing", "status": "broken", "statusDetails": {"message": "FileNotFoundError: [Errno 2] No such file or directory: '/home/chenlei/backup_sqls/apiautotest_2022-01-06T14_21_46.sql'\n", "trace": "  File \"D:\\PythonCode\\apiAutoTest\\lib\\site-packages\\pluggy\\callers.py\", line 187, in _multicall\n    res = hook_impl.function(*args)\n  File \"D:\\PythonCode\\apiAutoTest\\lib\\site-packages\\_pytest\\fixtures.py\", line 1117, in pytest_fixture_setup\n    result = call_fixture_func(fixturefunc, request, kwargs)\n  File \"D:\\PythonCode\\apiAutoTest\\lib\\site-packages\\_pytest\\fixtures.py\", line 915, in call_fixture_func\n    fixture_result = next(generator)\n  File \"F:\\CODE\\python-test\\apiAutoTest\\test\\conftest.py\", line 24, in data_clearing\n    DataClearing.backup_mysql()\n  File \"F:\\CODE\\python-test\\apiAutoTest\\tools\\data_clearing.py\", line 119, in backup_mysql\n    cls.server.files_action(0,\n  File \"F:\\CODE\\python-test\\apiAutoTest\\tools\\data_clearing.py\", line 77, in files_action\n    self.ftp_client.get(remotepath=remote_path, localpath=file_path)\n  File \"D:\\PythonCode\\apiAutoTest\\lib\\site-packages\\paramiko\\sftp_client.py\", line 801, in get\n    with open(localpath, \"wb\") as fl:\n"}, "start": 1641450300299, "stop": 1641450301394}, {"name": "data_clearing", "status": "broken", "statusDetails": {"message": "FileNotFoundError: [Errno 2] No such file or directory: '/home/chenlei/backup_sqls/apiautotest_2022-01-06T14_21_46.sql'\n", "trace": "  File \"D:\\PythonCode\\apiAutoTest\\lib\\site-packages\\pluggy\\callers.py\", line 187, in _multicall\n    res = hook_impl.function(*args)\n  File \"D:\\PythonCode\\apiAutoTest\\lib\\site-packages\\_pytest\\fixtures.py\", line 1117, in pytest_fixture_setup\n    result = call_fixture_func(fixturefunc, request, kwargs)\n  File \"D:\\PythonCode\\apiAutoTest\\lib\\site-packages\\_pytest\\fixtures.py\", line 915, in call_fixture_func\n    fixture_result = next(generator)\n  File \"F:\\CODE\\python-test\\apiAutoTest\\test\\conftest.py\", line 24, in data_clearing\n    DataClearing.backup_mysql()\n  File \"F:\\CODE\\python-test\\apiAutoTest\\tools\\data_clearing.py\", line 119, in backup_mysql\n    cls.server.files_action(0,\n  File \"F:\\CODE\\python-test\\apiAutoTest\\tools\\data_clearing.py\", line 77, in files_action\n    self.ftp_client.get(remotepath=remote_path, localpath=file_path)\n  File \"D:\\PythonCode\\apiAutoTest\\lib\\site-packages\\paramiko\\sftp_client.py\", line 801, in get\n    with open(localpath, \"wb\") as fl:\n"}, "start": 1641450302431, "stop": 1641450303953}, {"name": "data_clearing", "status": "broken", "statusDetails": {"message": "FileNotFoundError: [Errno 2] No such file or directory: '/home/chenlei/backup_sqls/apiautotest_2022-01-06T14_21_46.sql'\n", "trace": "  File \"D:\\PythonCode\\apiAutoTest\\lib\\site-packages\\pluggy\\callers.py\", line 187, in _multicall\n    res = hook_impl.function(*args)\n  File \"D:\\PythonCode\\apiAutoTest\\lib\\site-packages\\_pytest\\fixtures.py\", line 1117, in pytest_fixture_setup\n    result = call_fixture_func(fixturefunc, request, kwargs)\n  File \"D:\\PythonCode\\apiAutoTest\\lib\\site-packages\\_pytest\\fixtures.py\", line 915, in call_fixture_func\n    fixture_result = next(generator)\n  File \"F:\\CODE\\python-test\\apiAutoTest\\test\\conftest.py\", line 24, in data_clearing\n    DataClearing.backup_mysql()\n  File \"F:\\CODE\\python-test\\apiAutoTest\\tools\\data_clearing.py\", line 119, in backup_mysql\n    cls.server.files_action(0,\n  File \"F:\\CODE\\python-test\\apiAutoTest\\tools\\data_clearing.py\", line 77, in files_action\n    self.ftp_client.get(remotepath=remote_path, localpath=file_path)\n  File \"D:\\PythonCode\\apiAutoTest\\lib\\site-packages\\paramiko\\sftp_client.py\", line 801, in get\n    with open(localpath, \"wb\") as fl:\n"}, "start": 1641450304979, "stop": 1641450306387}, {"name": "data_clearing", "status": "broken", "statusDetails": {"message": "FileNotFoundError: [Errno 2] No such file or directory: '/home/chenlei/backup_sqls/apiautotest_2022-01-06T14_21_46.sql'\n", "trace": "  File \"D:\\PythonCode\\apiAutoTest\\lib\\site-packages\\pluggy\\callers.py\", line 187, in _multicall\n    res = hook_impl.function(*args)\n  File \"D:\\PythonCode\\apiAutoTest\\lib\\site-packages\\_pytest\\fixtures.py\", line 1117, in pytest_fixture_setup\n    result = call_fixture_func(fixturefunc, request, kwargs)\n  File \"D:\\PythonCode\\apiAutoTest\\lib\\site-packages\\_pytest\\fixtures.py\", line 915, in call_fixture_func\n    fixture_result = next(generator)\n  File \"F:\\CODE\\python-test\\apiAutoTest\\test\\conftest.py\", line 24, in data_clearing\n    DataClearing.backup_mysql()\n  File \"F:\\CODE\\python-test\\apiAutoTest\\tools\\data_clearing.py\", line 119, in backup_mysql\n    cls.server.files_action(0,\n  File \"F:\\CODE\\python-test\\apiAutoTest\\tools\\data_clearing.py\", line 77, in files_action\n    self.ftp_client.get(remotepath=remote_path, localpath=file_path)\n  File \"D:\\PythonCode\\apiAutoTest\\lib\\site-packages\\paramiko\\sftp_client.py\", line 801, in get\n    with open(localpath, \"wb\") as fl:\n"}, "start": 1641450307452, "stop": 1641450308455}, {"name": "data_clearing", "status": "broken", "statusDetails": {"message": "FileNotFoundError: [Errno 2] No such file or directory: '/home/chenlei/backup_sqls/apiautotest_2022-01-06T14_21_46.sql'\n", "trace": "  File \"D:\\PythonCode\\apiAutoTest\\lib\\site-packages\\pluggy\\callers.py\", line 187, in _multicall\n    res = hook_impl.function(*args)\n  File \"D:\\PythonCode\\apiAutoTest\\lib\\site-packages\\_pytest\\fixtures.py\", line 1117, in pytest_fixture_setup\n    result = call_fixture_func(fixturefunc, request, kwargs)\n  File \"D:\\PythonCode\\apiAutoTest\\lib\\site-packages\\_pytest\\fixtures.py\", line 915, in call_fixture_func\n    fixture_result = next(generator)\n  File \"F:\\CODE\\python-test\\apiAutoTest\\test\\conftest.py\", line 24, in data_clearing\n    DataClearing.backup_mysql()\n  File \"F:\\CODE\\python-test\\apiAutoTest\\tools\\data_clearing.py\", line 119, in backup_mysql\n    cls.server.files_action(0,\n  File \"F:\\CODE\\python-test\\apiAutoTest\\tools\\data_clearing.py\", line 77, in files_action\n    self.ftp_client.get(remotepath=remote_path, localpath=file_path)\n  File \"D:\\PythonCode\\apiAutoTest\\lib\\site-packages\\paramiko\\sftp_client.py\", line 801, in get\n    with open(localpath, \"wb\") as fl:\n"}, "start": 1641450309481, "stop": 1641450310762}, {"name": "data_clearing", "status": "broken", "statusDetails": {"message": "FileNotFoundError: [Errno 2] No such file or directory: '/home/chenlei/backup_sqls/apiautotest_2022-01-06T14_21_46.sql'\n", "trace": "  File \"D:\\PythonCode\\apiAutoTest\\lib\\site-packages\\pluggy\\callers.py\", line 187, in _multicall\n    res = hook_impl.function(*args)\n  File \"D:\\PythonCode\\apiAutoTest\\lib\\site-packages\\_pytest\\fixtures.py\", line 1117, in pytest_fixture_setup\n    result = call_fixture_func(fixturefunc, request, kwargs)\n  File \"D:\\PythonCode\\apiAutoTest\\lib\\site-packages\\_pytest\\fixtures.py\", line 915, in call_fixture_func\n    fixture_result = next(generator)\n  File \"F:\\CODE\\python-test\\apiAutoTest\\test\\conftest.py\", line 24, in data_clearing\n    DataClearing.backup_mysql()\n  File \"F:\\CODE\\python-test\\apiAutoTest\\tools\\data_clearing.py\", line 119, in backup_mysql\n    cls.server.files_action(0,\n  File \"F:\\CODE\\python-test\\apiAutoTest\\tools\\data_clearing.py\", line 77, in files_action\n    self.ftp_client.get(remotepath=remote_path, localpath=file_path)\n  File \"D:\\PythonCode\\apiAutoTest\\lib\\site-packages\\paramiko\\sftp_client.py\", line 801, in get\n    with open(localpath, \"wb\") as fl:\n"}, "start": 1641450311799, "stop": 1641450313160}, {"name": "data_clearing", "status": "broken", "statusDetails": {"message": "FileNotFoundError: [Errno 2] No such file or directory: '/home/chenlei/backup_sqls/apiautotest_2022-01-06T14_21_46.sql'\n", "trace": "  File \"D:\\PythonCode\\apiAutoTest\\lib\\site-packages\\pluggy\\callers.py\", line 187, in _multicall\n    res = hook_impl.function(*args)\n  File \"D:\\PythonCode\\apiAutoTest\\lib\\site-packages\\_pytest\\fixtures.py\", line 1117, in pytest_fixture_setup\n    result = call_fixture_func(fixturefunc, request, kwargs)\n  File \"D:\\PythonCode\\apiAutoTest\\lib\\site-packages\\_pytest\\fixtures.py\", line 915, in call_fixture_func\n    fixture_result = next(generator)\n  File \"F:\\CODE\\python-test\\apiAutoTest\\test\\conftest.py\", line 24, in data_clearing\n    DataClearing.backup_mysql()\n  File \"F:\\CODE\\python-test\\apiAutoTest\\tools\\data_clearing.py\", line 119, in backup_mysql\n    cls.server.files_action(0,\n  File \"F:\\CODE\\python-test\\apiAutoTest\\tools\\data_clearing.py\", line 77, in files_action\n    self.ftp_client.get(remotepath=remote_path, localpath=file_path)\n  File \"D:\\PythonCode\\apiAutoTest\\lib\\site-packages\\paramiko\\sftp_client.py\", line 801, in get\n    with open(localpath, \"wb\") as fl:\n"}, "start": 1641450314177, "stop": 1641450315378}, {"name": "data_clearing", "status": "broken", "statusDetails": {"message": "FileNotFoundError: [Errno 2] No such file or directory: '/home/chenlei/backup_sqls/apiautotest_2022-01-06T14_21_46.sql'\n", "trace": "  File \"D:\\PythonCode\\apiAutoTest\\lib\\site-packages\\pluggy\\callers.py\", line 187, in _multicall\n    res = hook_impl.function(*args)\n  File \"D:\\PythonCode\\apiAutoTest\\lib\\site-packages\\_pytest\\fixtures.py\", line 1117, in pytest_fixture_setup\n    result = call_fixture_func(fixturefunc, request, kwargs)\n  File \"D:\\PythonCode\\apiAutoTest\\lib\\site-packages\\_pytest\\fixtures.py\", line 915, in call_fixture_func\n    fixture_result = next(generator)\n  File \"F:\\CODE\\python-test\\apiAutoTest\\test\\conftest.py\", line 24, in data_clearing\n    DataClearing.backup_mysql()\n  File \"F:\\CODE\\python-test\\apiAutoTest\\tools\\data_clearing.py\", line 119, in backup_mysql\n    cls.server.files_action(0,\n  File \"F:\\CODE\\python-test\\apiAutoTest\\tools\\data_clearing.py\", line 77, in files_action\n    self.ftp_client.get(remotepath=remote_path, localpath=file_path)\n  File \"D:\\PythonCode\\apiAutoTest\\lib\\site-packages\\paramiko\\sftp_client.py\", line 801, in get\n    with open(localpath, \"wb\") as fl:\n"}, "start": 1641450316421, "stop": 1641450317506}, {"name": "data_clearing", "status": "broken", "statusDetails": {"message": "FileNotFoundError: [Errno 2] No such file or directory: '/home/chenlei/backup_sqls/apiautotest_2022-01-06T14_21_46.sql'\n", "trace": "  File \"D:\\PythonCode\\apiAutoTest\\lib\\site-packages\\pluggy\\callers.py\", line 187, in _multicall\n    res = hook_impl.function(*args)\n  File \"D:\\PythonCode\\apiAutoTest\\lib\\site-packages\\_pytest\\fixtures.py\", line 1117, in pytest_fixture_setup\n    result = call_fixture_func(fixturefunc, request, kwargs)\n  File \"D:\\PythonCode\\apiAutoTest\\lib\\site-packages\\_pytest\\fixtures.py\", line 915, in call_fixture_func\n    fixture_result = next(generator)\n  File \"F:\\CODE\\python-test\\apiAutoTest\\test\\conftest.py\", line 24, in data_clearing\n    DataClearing.backup_mysql()\n  File \"F:\\CODE\\python-test\\apiAutoTest\\tools\\data_clearing.py\", line 119, in backup_mysql\n    cls.server.files_action(0,\n  File \"F:\\CODE\\python-test\\apiAutoTest\\tools\\data_clearing.py\", line 77, in files_action\n    self.ftp_client.get(remotepath=remote_path, localpath=file_path)\n  File \"D:\\PythonCode\\apiAutoTest\\lib\\site-packages\\paramiko\\sftp_client.py\", line 801, in get\n    with open(localpath, \"wb\") as fl:\n"}, "start": 1641450318527, "stop": 1641450319534}, {"name": "data_clearing", "status": "broken", "statusDetails": {"message": "FileNotFoundError: [Errno 2] No such file or directory: '/home/chenlei/backup_sqls/apiautotest_2022-01-06T14_21_46.sql'\n", "trace": "  File \"D:\\PythonCode\\apiAutoTest\\lib\\site-packages\\pluggy\\callers.py\", line 187, in _multicall\n    res = hook_impl.function(*args)\n  File \"D:\\PythonCode\\apiAutoTest\\lib\\site-packages\\_pytest\\fixtures.py\", line 1117, in pytest_fixture_setup\n    result = call_fixture_func(fixturefunc, request, kwargs)\n  File \"D:\\PythonCode\\apiAutoTest\\lib\\site-packages\\_pytest\\fixtures.py\", line 915, in call_fixture_func\n    fixture_result = next(generator)\n  File \"F:\\CODE\\python-test\\apiAutoTest\\test\\conftest.py\", line 24, in data_clearing\n    DataClearing.backup_mysql()\n  File \"F:\\CODE\\python-test\\apiAutoTest\\tools\\data_clearing.py\", line 119, in backup_mysql\n    cls.server.files_action(0,\n  File \"F:\\CODE\\python-test\\apiAutoTest\\tools\\data_clearing.py\", line 77, in files_action\n    self.ftp_client.get(remotepath=remote_path, localpath=file_path)\n  File \"D:\\PythonCode\\apiAutoTest\\lib\\site-packages\\paramiko\\sftp_client.py\", line 801, in get\n    with open(localpath, \"wb\") as fl:\n"}, "start": 1641450320575, "stop": 1641450321987}, {"name": "data_clearing", "status": "broken", "statusDetails": {"message": "FileNotFoundError: [Errno 2] No such file or directory: '/home/chenlei/backup_sqls/apiautotest_2022-01-06T14_21_46.sql'\n", "trace": "  File \"D:\\PythonCode\\apiAutoTest\\lib\\site-packages\\pluggy\\callers.py\", line 187, in _multicall\n    res = hook_impl.function(*args)\n  File \"D:\\PythonCode\\apiAutoTest\\lib\\site-packages\\_pytest\\fixtures.py\", line 1117, in pytest_fixture_setup\n    result = call_fixture_func(fixturefunc, request, kwargs)\n  File \"D:\\PythonCode\\apiAutoTest\\lib\\site-packages\\_pytest\\fixtures.py\", line 915, in call_fixture_func\n    fixture_result = next(generator)\n  File \"F:\\CODE\\python-test\\apiAutoTest\\test\\conftest.py\", line 24, in data_clearing\n    DataClearing.backup_mysql()\n  File \"F:\\CODE\\python-test\\apiAutoTest\\tools\\data_clearing.py\", line 119, in backup_mysql\n    cls.server.files_action(0,\n  File \"F:\\CODE\\python-test\\apiAutoTest\\tools\\data_clearing.py\", line 77, in files_action\n    self.ftp_client.get(remotepath=remote_path, localpath=file_path)\n  File \"D:\\PythonCode\\apiAutoTest\\lib\\site-packages\\paramiko\\sftp_client.py\", line 801, in get\n    with open(localpath, \"wb\") as fl:\n"}, "start": 1641450323014, "stop": 1641450324207}, {"name": "data_clearing", "status": "broken", "statusDetails": {"message": "FileNotFoundError: [Errno 2] No such file or directory: '/home/chenlei/backup_sqls/apiautotest_2022-01-06T14_21_46.sql'\n", "trace": "  File \"D:\\PythonCode\\apiAutoTest\\lib\\site-packages\\pluggy\\callers.py\", line 187, in _multicall\n    res = hook_impl.function(*args)\n  File \"D:\\PythonCode\\apiAutoTest\\lib\\site-packages\\_pytest\\fixtures.py\", line 1117, in pytest_fixture_setup\n    result = call_fixture_func(fixturefunc, request, kwargs)\n  File \"D:\\PythonCode\\apiAutoTest\\lib\\site-packages\\_pytest\\fixtures.py\", line 915, in call_fixture_func\n    fixture_result = next(generator)\n  File \"F:\\CODE\\python-test\\apiAutoTest\\test\\conftest.py\", line 24, in data_clearing\n    DataClearing.backup_mysql()\n  File \"F:\\CODE\\python-test\\apiAutoTest\\tools\\data_clearing.py\", line 119, in backup_mysql\n    cls.server.files_action(0,\n  File \"F:\\CODE\\python-test\\apiAutoTest\\tools\\data_clearing.py\", line 77, in files_action\n    self.ftp_client.get(remotepath=remote_path, localpath=file_path)\n  File \"D:\\PythonCode\\apiAutoTest\\lib\\site-packages\\paramiko\\sftp_client.py\", line 801, in get\n    with open(localpath, \"wb\") as fl:\n"}, "start": 1641450325245, "stop": 1641450326543}, {"name": "data_clearing", "status": "broken", "statusDetails": {"message": "FileNotFoundError: [Errno 2] No such file or directory: '/home/chenlei/backup_sqls/apiautotest_2022-01-06T14_21_46.sql'\n", "trace": "  File \"D:\\PythonCode\\apiAutoTest\\lib\\site-packages\\pluggy\\callers.py\", line 187, in _multicall\n    res = hook_impl.function(*args)\n  File \"D:\\PythonCode\\apiAutoTest\\lib\\site-packages\\_pytest\\fixtures.py\", line 1117, in pytest_fixture_setup\n    result = call_fixture_func(fixturefunc, request, kwargs)\n  File \"D:\\PythonCode\\apiAutoTest\\lib\\site-packages\\_pytest\\fixtures.py\", line 915, in call_fixture_func\n    fixture_result = next(generator)\n  File \"F:\\CODE\\python-test\\apiAutoTest\\test\\conftest.py\", line 24, in data_clearing\n    DataClearing.backup_mysql()\n  File \"F:\\CODE\\python-test\\apiAutoTest\\tools\\data_clearing.py\", line 119, in backup_mysql\n    cls.server.files_action(0,\n  File \"F:\\CODE\\python-test\\apiAutoTest\\tools\\data_clearing.py\", line 77, in files_action\n    self.ftp_client.get(remotepath=remote_path, localpath=file_path)\n  File \"D:\\PythonCode\\apiAutoTest\\lib\\site-packages\\paramiko\\sftp_client.py\", line 801, in get\n    with open(localpath, \"wb\") as fl:\n"}, "start": 1641450327570, "stop": 1641450328687}, {"name": "data_clearing", "status": "broken", "statusDetails": {"message": "FileNotFoundError: [Errno 2] No such file or directory: '/home/chenlei/backup_sqls/apiautotest_2022-01-06T14_21_46.sql'\n", "trace": "  File \"D:\\PythonCode\\apiAutoTest\\lib\\site-packages\\pluggy\\callers.py\", line 187, in _multicall\n    res = hook_impl.function(*args)\n  File \"D:\\PythonCode\\apiAutoTest\\lib\\site-packages\\_pytest\\fixtures.py\", line 1117, in pytest_fixture_setup\n    result = call_fixture_func(fixturefunc, request, kwargs)\n  File \"D:\\PythonCode\\apiAutoTest\\lib\\site-packages\\_pytest\\fixtures.py\", line 915, in call_fixture_func\n    fixture_result = next(generator)\n  File \"F:\\CODE\\python-test\\apiAutoTest\\test\\conftest.py\", line 24, in data_clearing\n    DataClearing.backup_mysql()\n  File \"F:\\CODE\\python-test\\apiAutoTest\\tools\\data_clearing.py\", line 119, in backup_mysql\n    cls.server.files_action(0,\n  File \"F:\\CODE\\python-test\\apiAutoTest\\tools\\data_clearing.py\", line 77, in files_action\n    self.ftp_client.get(remotepath=remote_path, localpath=file_path)\n  File \"D:\\PythonCode\\apiAutoTest\\lib\\site-packages\\paramiko\\sftp_client.py\", line 801, in get\n    with open(localpath, \"wb\") as fl:\n"}, "start": 1641450329753, "stop": 1641450331212}, {"name": "data_clearing", "status": "broken", "statusDetails": {"message": "FileNotFoundError: [Errno 2] No such file or directory: '/home/chenlei/backup_sqls/apiautotest_2022-01-06T14_21_46.sql'\n", "trace": "  File \"D:\\PythonCode\\apiAutoTest\\lib\\site-packages\\pluggy\\callers.py\", line 187, in _multicall\n    res = hook_impl.function(*args)\n  File \"D:\\PythonCode\\apiAutoTest\\lib\\site-packages\\_pytest\\fixtures.py\", line 1117, in pytest_fixture_setup\n    result = call_fixture_func(fixturefunc, request, kwargs)\n  File \"D:\\PythonCode\\apiAutoTest\\lib\\site-packages\\_pytest\\fixtures.py\", line 915, in call_fixture_func\n    fixture_result = next(generator)\n  File \"F:\\CODE\\python-test\\apiAutoTest\\test\\conftest.py\", line 24, in data_clearing\n    DataClearing.backup_mysql()\n  File \"F:\\CODE\\python-test\\apiAutoTest\\tools\\data_clearing.py\", line 119, in backup_mysql\n    cls.server.files_action(0,\n  File \"F:\\CODE\\python-test\\apiAutoTest\\tools\\data_clearing.py\", line 77, in files_action\n    self.ftp_client.get(remotepath=remote_path, localpath=file_path)\n  File \"D:\\PythonCode\\apiAutoTest\\lib\\site-packages\\paramiko\\sftp_client.py\", line 801, in get\n    with open(localpath, \"wb\") as fl:\n"}, "start": 1641450332230, "stop": 1641450333255}, {"name": "data_clearing", "status": "broken", "statusDetails": {"message": "FileNotFoundError: [Errno 2] No such file or directory: '/home/chenlei/backup_sqls/apiautotest_2022-01-06T14_21_46.sql'\n", "trace": "  File \"D:\\PythonCode\\apiAutoTest\\lib\\site-packages\\pluggy\\callers.py\", line 187, in _multicall\n    res = hook_impl.function(*args)\n  File \"D:\\PythonCode\\apiAutoTest\\lib\\site-packages\\_pytest\\fixtures.py\", line 1117, in pytest_fixture_setup\n    result = call_fixture_func(fixturefunc, request, kwargs)\n  File \"D:\\PythonCode\\apiAutoTest\\lib\\site-packages\\_pytest\\fixtures.py\", line 915, in call_fixture_func\n    fixture_result = next(generator)\n  File \"F:\\CODE\\python-test\\apiAutoTest\\test\\conftest.py\", line 24, in data_clearing\n    DataClearing.backup_mysql()\n  File \"F:\\CODE\\python-test\\apiAutoTest\\tools\\data_clearing.py\", line 119, in backup_mysql\n    cls.server.files_action(0,\n  File \"F:\\CODE\\python-test\\apiAutoTest\\tools\\data_clearing.py\", line 77, in files_action\n    self.ftp_client.get(remotepath=remote_path, localpath=file_path)\n  File \"D:\\PythonCode\\apiAutoTest\\lib\\site-packages\\paramiko\\sftp_client.py\", line 801, in get\n    with open(localpath, \"wb\") as fl:\n"}, "start": 1641450334288, "stop": 1641450335331}, {"name": "data_clearing", "status": "broken", "statusDetails": {"message": "FileNotFoundError: [Errno 2] No such file or directory: '/home/chenlei/backup_sqls/apiautotest_2022-01-06T14_21_46.sql'\n", "trace": "  File \"D:\\PythonCode\\apiAutoTest\\lib\\site-packages\\pluggy\\callers.py\", line 187, in _multicall\n    res = hook_impl.function(*args)\n  File \"D:\\PythonCode\\apiAutoTest\\lib\\site-packages\\_pytest\\fixtures.py\", line 1117, in pytest_fixture_setup\n    result = call_fixture_func(fixturefunc, request, kwargs)\n  File \"D:\\PythonCode\\apiAutoTest\\lib\\site-packages\\_pytest\\fixtures.py\", line 915, in call_fixture_func\n    fixture_result = next(generator)\n  File \"F:\\CODE\\python-test\\apiAutoTest\\test\\conftest.py\", line 24, in data_clearing\n    DataClearing.backup_mysql()\n  File \"F:\\CODE\\python-test\\apiAutoTest\\tools\\data_clearing.py\", line 119, in backup_mysql\n    cls.server.files_action(0,\n  File \"F:\\CODE\\python-test\\apiAutoTest\\tools\\data_clearing.py\", line 77, in files_action\n    self.ftp_client.get(remotepath=remote_path, localpath=file_path)\n  File \"D:\\PythonCode\\apiAutoTest\\lib\\site-packages\\paramiko\\sftp_client.py\", line 801, in get\n    with open(localpath, \"wb\") as fl:\n"}, "start": 1641450336349, "stop": 1641450337848}, {"name": "data_clearing", "status": "broken", "statusDetails": {"message": "FileNotFoundError: [Errno 2] No such file or directory: '/home/chenlei/backup_sqls/apiautotest_2022-01-06T14_21_46.sql'\n", "trace": "  File \"D:\\PythonCode\\apiAutoTest\\lib\\site-packages\\pluggy\\callers.py\", line 187, in _multicall\n    res = hook_impl.function(*args)\n  File \"D:\\PythonCode\\apiAutoTest\\lib\\site-packages\\_pytest\\fixtures.py\", line 1117, in pytest_fixture_setup\n    result = call_fixture_func(fixturefunc, request, kwargs)\n  File \"D:\\PythonCode\\apiAutoTest\\lib\\site-packages\\_pytest\\fixtures.py\", line 915, in call_fixture_func\n    fixture_result = next(generator)\n  File \"F:\\CODE\\python-test\\apiAutoTest\\test\\conftest.py\", line 24, in data_clearing\n    DataClearing.backup_mysql()\n  File \"F:\\CODE\\python-test\\apiAutoTest\\tools\\data_clearing.py\", line 119, in backup_mysql\n    cls.server.files_action(0,\n  File \"F:\\CODE\\python-test\\apiAutoTest\\tools\\data_clearing.py\", line 77, in files_action\n    self.ftp_client.get(remotepath=remote_path, localpath=file_path)\n  File \"D:\\PythonCode\\apiAutoTest\\lib\\site-packages\\paramiko\\sftp_client.py\", line 801, in get\n    with open(localpath, \"wb\") as fl:\n"}, "start": 1641450338878, "stop": 1641450340351}, {"name": "data_clearing", "status": "broken", "statusDetails": {"message": "FileNotFoundError: [Errno 2] No such file or directory: '/home/chenlei/backup_sqls/apiautotest_2022-01-06T14_21_46.sql'\n", "trace": "  File \"D:\\PythonCode\\apiAutoTest\\lib\\site-packages\\pluggy\\callers.py\", line 187, in _multicall\n    res = hook_impl.function(*args)\n  File \"D:\\PythonCode\\apiAutoTest\\lib\\site-packages\\_pytest\\fixtures.py\", line 1117, in pytest_fixture_setup\n    result = call_fixture_func(fixturefunc, request, kwargs)\n  File \"D:\\PythonCode\\apiAutoTest\\lib\\site-packages\\_pytest\\fixtures.py\", line 915, in call_fixture_func\n    fixture_result = next(generator)\n  File \"F:\\CODE\\python-test\\apiAutoTest\\test\\conftest.py\", line 24, in data_clearing\n    DataClearing.backup_mysql()\n  File \"F:\\CODE\\python-test\\apiAutoTest\\tools\\data_clearing.py\", line 119, in backup_mysql\n    cls.server.files_action(0,\n  File \"F:\\CODE\\python-test\\apiAutoTest\\tools\\data_clearing.py\", line 77, in files_action\n    self.ftp_client.get(remotepath=remote_path, localpath=file_path)\n  File \"D:\\PythonCode\\apiAutoTest\\lib\\site-packages\\paramiko\\sftp_client.py\", line 801, in get\n    with open(localpath, \"wb\") as fl:\n"}, "start": 1641450341375, "stop": 1641450342779}, {"name": "data_clearing", "status": "broken", "statusDetails": {"message": "FileNotFoundError: [Errno 2] No such file or directory: '/home/chenlei/backup_sqls/apiautotest_2022-01-06T14_21_46.sql'\n", "trace": "  File \"D:\\PythonCode\\apiAutoTest\\lib\\site-packages\\pluggy\\callers.py\", line 187, in _multicall\n    res = hook_impl.function(*args)\n  File \"D:\\PythonCode\\apiAutoTest\\lib\\site-packages\\_pytest\\fixtures.py\", line 1117, in pytest_fixture_setup\n    result = call_fixture_func(fixturefunc, request, kwargs)\n  File \"D:\\PythonCode\\apiAutoTest\\lib\\site-packages\\_pytest\\fixtures.py\", line 915, in call_fixture_func\n    fixture_result = next(generator)\n  File \"F:\\CODE\\python-test\\apiAutoTest\\test\\conftest.py\", line 24, in data_clearing\n    DataClearing.backup_mysql()\n  File \"F:\\CODE\\python-test\\apiAutoTest\\tools\\data_clearing.py\", line 119, in backup_mysql\n    cls.server.files_action(0,\n  File \"F:\\CODE\\python-test\\apiAutoTest\\tools\\data_clearing.py\", line 77, in files_action\n    self.ftp_client.get(remotepath=remote_path, localpath=file_path)\n  File \"D:\\PythonCode\\apiAutoTest\\lib\\site-packages\\paramiko\\sftp_client.py\", line 801, in get\n    with open(localpath, \"wb\") as fl:\n"}, "start": 1641450343813, "stop": 1641450344924}, {"name": "data_clearing", "status": "broken", "statusDetails": {"message": "FileNotFoundError: [Errno 2] No such file or directory: '/home/chenlei/backup_sqls/apiautotest_2022-01-06T14_21_46.sql'\n", "trace": "  File \"D:\\PythonCode\\apiAutoTest\\lib\\site-packages\\pluggy\\callers.py\", line 187, in _multicall\n    res = hook_impl.function(*args)\n  File \"D:\\PythonCode\\apiAutoTest\\lib\\site-packages\\_pytest\\fixtures.py\", line 1117, in pytest_fixture_setup\n    result = call_fixture_func(fixturefunc, request, kwargs)\n  File \"D:\\PythonCode\\apiAutoTest\\lib\\site-packages\\_pytest\\fixtures.py\", line 915, in call_fixture_func\n    fixture_result = next(generator)\n  File \"F:\\CODE\\python-test\\apiAutoTest\\test\\conftest.py\", line 24, in data_clearing\n    DataClearing.backup_mysql()\n  File \"F:\\CODE\\python-test\\apiAutoTest\\tools\\data_clearing.py\", line 119, in backup_mysql\n    cls.server.files_action(0,\n  File \"F:\\CODE\\python-test\\apiAutoTest\\tools\\data_clearing.py\", line 77, in files_action\n    self.ftp_client.get(remotepath=remote_path, localpath=file_path)\n  File \"D:\\PythonCode\\apiAutoTest\\lib\\site-packages\\paramiko\\sftp_client.py\", line 801, in get\n    with open(localpath, \"wb\") as fl:\n"}, "start": 1641450345942, "stop": 1641450347310}, {"name": "data_clearing", "status": "broken", "statusDetails": {"message": "FileNotFoundError: [Errno 2] No such file or directory: '/home/chenlei/backup_sqls/apiautotest_2022-01-06T14_21_46.sql'\n", "trace": "  File \"D:\\PythonCode\\apiAutoTest\\lib\\site-packages\\pluggy\\callers.py\", line 187, in _multicall\n    res = hook_impl.function(*args)\n  File \"D:\\PythonCode\\apiAutoTest\\lib\\site-packages\\_pytest\\fixtures.py\", line 1117, in pytest_fixture_setup\n    result = call_fixture_func(fixturefunc, request, kwargs)\n  File \"D:\\PythonCode\\apiAutoTest\\lib\\site-packages\\_pytest\\fixtures.py\", line 915, in call_fixture_func\n    fixture_result = next(generator)\n  File \"F:\\CODE\\python-test\\apiAutoTest\\test\\conftest.py\", line 24, in data_clearing\n    DataClearing.backup_mysql()\n  File \"F:\\CODE\\python-test\\apiAutoTest\\tools\\data_clearing.py\", line 119, in backup_mysql\n    cls.server.files_action(0,\n  File \"F:\\CODE\\python-test\\apiAutoTest\\tools\\data_clearing.py\", line 77, in files_action\n    self.ftp_client.get(remotepath=remote_path, localpath=file_path)\n  File \"D:\\PythonCode\\apiAutoTest\\lib\\site-packages\\paramiko\\sftp_client.py\", line 801, in get\n    with open(localpath, \"wb\") as fl:\n"}, "start": 1641450348352, "stop": 1641450349879}, {"name": "data_clearing", "status": "broken", "statusDetails": {"message": "FileNotFoundError: [Errno 2] No such file or directory: '/home/chenlei/backup_sqls/apiautotest_2022-01-06T14_21_46.sql'\n", "trace": "  File \"D:\\PythonCode\\apiAutoTest\\lib\\site-packages\\pluggy\\callers.py\", line 187, in _multicall\n    res = hook_impl.function(*args)\n  File \"D:\\PythonCode\\apiAutoTest\\lib\\site-packages\\_pytest\\fixtures.py\", line 1117, in pytest_fixture_setup\n    result = call_fixture_func(fixturefunc, request, kwargs)\n  File \"D:\\PythonCode\\apiAutoTest\\lib\\site-packages\\_pytest\\fixtures.py\", line 915, in call_fixture_func\n    fixture_result = next(generator)\n  File \"F:\\CODE\\python-test\\apiAutoTest\\test\\conftest.py\", line 24, in data_clearing\n    DataClearing.backup_mysql()\n  File \"F:\\CODE\\python-test\\apiAutoTest\\tools\\data_clearing.py\", line 119, in backup_mysql\n    cls.server.files_action(0,\n  File \"F:\\CODE\\python-test\\apiAutoTest\\tools\\data_clearing.py\", line 77, in files_action\n    self.ftp_client.get(remotepath=remote_path, localpath=file_path)\n  File \"D:\\PythonCode\\apiAutoTest\\lib\\site-packages\\paramiko\\sftp_client.py\", line 801, in get\n    with open(localpath, \"wb\") as fl:\n"}, "start": 1641450350896, "stop": 1641450352638}], "start": 1641450350896, "stop": 1641450352690}